nohup: ignoring input
[19/Dec/2018 09:19:25] "GET /list HTTP/1.1" 200 1350
[19/Dec/2018 09:19:25] "GET /static/css/list.css HTTP/1.1" 304 0
[19/Dec/2018 09:19:25] "GET /static/js/list.js HTTP/1.1" 304 0
[19/Dec/2018 09:19:25] "GET /static/css/general.css HTTP/1.1" 304 0
Not Found: /logo_upc.png
[19/Dec/2018 09:19:25] "GET /logo_upc.png HTTP/1.1" 404 2589
[19/Dec/2018 09:26:23] "GET /list HTTP/1.1" 200 1350
[19/Dec/2018 09:26:23] "GET /static/css/list.css HTTP/1.1" 200 0
[19/Dec/2018 09:26:23] "GET /static/js/list.js HTTP/1.1" 200 606
[19/Dec/2018 09:26:23] "GET /static/css/general.css HTTP/1.1" 200 1547
Not Found: /logo_upc.png
[19/Dec/2018 09:26:23] "GET /logo_upc.png HTTP/1.1" 404 2589
[19/Dec/2018 09:27:10] "GET /list HTTP/1.1" 200 1350
[19/Dec/2018 09:27:10] "GET /static/css/list.css HTTP/1.1" 200 0
[19/Dec/2018 09:27:10] "GET /static/js/list.js HTTP/1.1" 200 606
[19/Dec/2018 09:27:10] "GET /static/css/general.css HTTP/1.1" 200 1545
Not Found: /logo_upc.png
[19/Dec/2018 09:27:10] "GET /logo_upc.png HTTP/1.1" 404 2589
[19/Dec/2018 09:28:08] "GET /list HTTP/1.1" 200 1350
[19/Dec/2018 09:28:08] "GET /static/css/list.css HTTP/1.1" 200 0
[19/Dec/2018 09:28:08] "GET /static/js/list.js HTTP/1.1" 200 606
[19/Dec/2018 09:28:08] "GET /static/css/general.css HTTP/1.1" 200 1562
Not Found: /logo_upc.png
[19/Dec/2018 09:28:08] "GET /logo_upc.png HTTP/1.1" 404 2589
[19/Dec/2018 09:28:22] "GET /static/css/list.css HTTP/1.1" 200 0
[19/Dec/2018 09:31:21] "GET /list HTTP/1.1" 200 1350
[19/Dec/2018 09:31:22] "GET /static/css/list.css HTTP/1.1" 200 0
[19/Dec/2018 09:31:22] "GET /static/js/list.js HTTP/1.1" 200 606
[19/Dec/2018 09:31:22] "GET /static/css/general.css HTTP/1.1" 200 1570
Not Found: /logo_upc.png
[19/Dec/2018 09:31:22] "GET /logo_upc.png HTTP/1.1" 404 2589
[19/Dec/2018 09:41:31] "GET /list HTTP/1.1" 200 1350
[19/Dec/2018 09:41:32] "GET /static/css/list.css HTTP/1.1" 200 0
[19/Dec/2018 09:41:32] "GET /static/js/list.js HTTP/1.1" 200 606
[19/Dec/2018 09:41:32] "GET /static/css/general.css HTTP/1.1" 200 1635
Not Found: /logo_upc.png
[19/Dec/2018 09:41:32] "GET /logo_upc.png HTTP/1.1" 404 2589
[19/Dec/2018 09:49:20] "GET /list HTTP/1.1" 200 1350
[19/Dec/2018 09:49:21] "GET /static/css/list.css HTTP/1.1" 200 112
[19/Dec/2018 09:49:21] "GET /static/js/list.js HTTP/1.1" 200 606
[19/Dec/2018 09:49:21] "GET /static/css/general.css HTTP/1.1" 200 1635
Not Found: /logo_upc.png
[19/Dec/2018 09:49:21] "GET /logo_upc.png HTTP/1.1" 404 2589
[19/Dec/2018 09:50:48] "GET /list HTTP/1.1" 200 1350
[19/Dec/2018 09:50:48] "GET /static/css/list.css HTTP/1.1" 200 125
[19/Dec/2018 09:50:48] "GET /static/js/list.js HTTP/1.1" 200 606
[19/Dec/2018 09:50:48] "GET /static/css/general.css HTTP/1.1" 200 1635
Not Found: /logo_upc.png
[19/Dec/2018 09:50:48] "GET /logo_upc.png HTTP/1.1" 404 2589
[19/Dec/2018 09:51:00] "GET /list HTTP/1.1" 200 1350
[19/Dec/2018 09:51:01] "GET /static/css/list.css HTTP/1.1" 200 124
[19/Dec/2018 09:51:01] "GET /static/js/list.js HTTP/1.1" 200 606
[19/Dec/2018 09:51:01] "GET /static/css/general.css HTTP/1.1" 200 1635
Not Found: /logo_upc.png
[19/Dec/2018 09:51:01] "GET /logo_upc.png HTTP/1.1" 404 2589
[19/Dec/2018 09:51:33] "GET /list HTTP/1.1" 200 1350
[19/Dec/2018 09:51:33] "GET /static/css/list.css HTTP/1.1" 200 159
[19/Dec/2018 09:51:33] "GET /static/js/list.js HTTP/1.1" 200 606
[19/Dec/2018 09:51:33] "GET /static/css/general.css HTTP/1.1" 200 1635
Not Found: /logo_upc.png
[19/Dec/2018 09:51:33] "GET /logo_upc.png HTTP/1.1" 404 2589
[19/Dec/2018 09:51:52] "GET /list HTTP/1.1" 200 1350
[19/Dec/2018 09:51:52] "GET /static/css/list.css HTTP/1.1" 200 160
[19/Dec/2018 09:51:52] "GET /static/js/list.js HTTP/1.1" 200 606
[19/Dec/2018 09:51:52] "GET /static/css/general.css HTTP/1.1" 200 1635
Not Found: /logo_upc.png
[19/Dec/2018 09:51:52] "GET /logo_upc.png HTTP/1.1" 404 2589
[19/Dec/2018 09:52:36] "GET /list HTTP/1.1" 200 1350
[19/Dec/2018 09:52:36] "GET /static/js/list.js HTTP/1.1" 200 606
[19/Dec/2018 09:52:36] "GET /static/css/list.css HTTP/1.1" 200 159
[19/Dec/2018 09:52:37] "GET /static/css/general.css HTTP/1.1" 200 1635
Not Found: /logo_upc.png
[19/Dec/2018 09:52:37] "GET /logo_upc.png HTTP/1.1" 404 2589
[19/Dec/2018 10:00:47] "GET /list HTTP/1.1" 200 1360
[19/Dec/2018 10:00:47] "GET /static/css/list.css HTTP/1.1" 200 190
[19/Dec/2018 10:00:48] "GET /static/js/list.js HTTP/1.1" 200 606
[19/Dec/2018 10:00:48] "GET /static/css/general.css HTTP/1.1" 200 1635
Not Found: /logo_upc.png
[19/Dec/2018 10:00:48] "GET /logo_upc.png HTTP/1.1" 404 2589
[19/Dec/2018 10:00:56] "GET /list HTTP/1.1" 200 1360
[19/Dec/2018 10:00:56] "GET /static/css/list.css HTTP/1.1" 200 190
[19/Dec/2018 10:00:56] "GET /static/js/list.js HTTP/1.1" 200 606
[19/Dec/2018 10:00:56] "GET /static/css/general.css HTTP/1.1" 200 1635
Not Found: /logo_upc.png
[19/Dec/2018 10:00:56] "GET /logo_upc.png HTTP/1.1" 404 2589
[19/Dec/2018 10:04:23] "GET /list HTTP/1.1" 200 1360
[19/Dec/2018 10:04:24] "GET /static/css/list.css HTTP/1.1" 200 201
[19/Dec/2018 10:04:24] "GET /static/js/list.js HTTP/1.1" 200 606
[19/Dec/2018 10:04:24] "GET /static/css/general.css HTTP/1.1" 200 1635
Not Found: /logo_upc.png
[19/Dec/2018 10:04:24] "GET /logo_upc.png HTTP/1.1" 404 2589
Not Found: /create
[19/Dec/2018 10:53:22] "GET /create HTTP/1.1" 404 2571
[19/Dec/2018 10:59:02] "GET /list HTTP/1.1" 200 1356
[19/Dec/2018 10:59:02] "GET /static/css/list.css HTTP/1.1" 200 201
[19/Dec/2018 10:59:02] "GET /static/js/list.js HTTP/1.1" 200 606
[19/Dec/2018 10:59:02] "GET /static/css/general.css HTTP/1.1" 200 1635
Not Found: /logo_upc.png
[19/Dec/2018 10:59:02] "GET /logo_upc.png HTTP/1.1" 404 2589
[19/Dec/2018 11:04:28] "GET /list HTTP/1.1" 200 1356
[19/Dec/2018 11:04:29] "GET /static/js/list.js HTTP/1.1" 200 606
[19/Dec/2018 11:04:29] "GET /static/css/list.css HTTP/1.1" 200 223
[19/Dec/2018 11:04:29] "GET /static/css/general.css HTTP/1.1" 200 1635
Not Found: /logo_upc.png
[19/Dec/2018 11:04:29] "GET /logo_upc.png HTTP/1.1" 404 2589
[19/Dec/2018 11:04:52] "GET /list HTTP/1.1" 200 1356
[19/Dec/2018 11:04:52] "GET /static/css/list.css HTTP/1.1" 200 203
[19/Dec/2018 11:04:52] "GET /static/js/list.js HTTP/1.1" 200 606
[19/Dec/2018 11:04:52] "GET /static/css/general.css HTTP/1.1" 200 1635
Not Found: /logo_upc.png
[19/Dec/2018 11:04:52] "GET /logo_upc.png HTTP/1.1" 404 2589
[19/Dec/2018 11:07:09] "GET /list HTTP/1.1" 200 1356
[19/Dec/2018 11:07:09] "GET /static/css/list.css HTTP/1.1" 200 287
[19/Dec/2018 11:07:09] "GET /static/js/list.js HTTP/1.1" 200 606
[19/Dec/2018 11:07:09] "GET /static/css/general.css HTTP/1.1" 200 1635
Not Found: /logo_upc.png
[19/Dec/2018 11:07:09] "GET /logo_upc.png HTTP/1.1" 404 2589
[19/Dec/2018 11:07:19] "GET /list HTTP/1.1" 200 1356
[19/Dec/2018 11:07:19] "GET /static/css/list.css HTTP/1.1" 200 287
[19/Dec/2018 11:07:19] "GET /static/js/list.js HTTP/1.1" 200 606
[19/Dec/2018 11:07:19] "GET /static/css/general.css HTTP/1.1" 200 1635
Not Found: /logo_upc.png
[19/Dec/2018 11:07:19] "GET /logo_upc.png HTTP/1.1" 404 2589
[19/Dec/2018 11:07:48] "GET /list HTTP/1.1" 200 1356
[19/Dec/2018 11:07:48] "GET /static/css/list.css HTTP/1.1" 200 281
[19/Dec/2018 11:07:48] "GET /static/js/list.js HTTP/1.1" 200 606
[19/Dec/2018 11:07:48] "GET /static/css/general.css HTTP/1.1" 200 1635
Not Found: /logo_upc.png
[19/Dec/2018 11:07:48] "GET /logo_upc.png HTTP/1.1" 404 2589
[19/Dec/2018 11:08:24] "GET /list HTTP/1.1" 200 1356
[19/Dec/2018 11:08:24] "GET /static/js/list.js HTTP/1.1" 200 606
[19/Dec/2018 11:08:24] "GET /static/css/list.css HTTP/1.1" 200 305
[19/Dec/2018 11:08:24] "GET /static/css/general.css HTTP/1.1" 200 1635
Not Found: /logo_upc.png
[19/Dec/2018 11:08:24] "GET /logo_upc.png HTTP/1.1" 404 2589
[19/Dec/2018 11:08:36] "GET /list HTTP/1.1" 200 1356
[19/Dec/2018 11:08:36] "GET /static/css/list.css HTTP/1.1" 200 319
[19/Dec/2018 11:08:36] "GET /static/js/list.js HTTP/1.1" 200 606
[19/Dec/2018 11:08:36] "GET /static/css/general.css HTTP/1.1" 200 1635
Not Found: /logo_upc.png
[19/Dec/2018 11:08:37] "GET /logo_upc.png HTTP/1.1" 404 2589
[19/Dec/2018 11:09:02] "GET /list HTTP/1.1" 200 1356
[19/Dec/2018 11:09:02] "GET /static/css/list.css HTTP/1.1" 200 339
[19/Dec/2018 11:09:02] "GET /static/js/list.js HTTP/1.1" 200 606
[19/Dec/2018 11:09:02] "GET /static/css/general.css HTTP/1.1" 200 1635
Not Found: /logo_upc.png
[19/Dec/2018 11:09:02] "GET /logo_upc.png HTTP/1.1" 404 2589
[19/Dec/2018 11:15:57] "GET /list HTTP/1.1" 200 1361
[19/Dec/2018 11:15:57] "GET /static/css/list.css HTTP/1.1" 200 498
[19/Dec/2018 11:15:57] "GET /static/js/list.js HTTP/1.1" 200 606
[19/Dec/2018 11:15:57] "GET /static/css/general.css HTTP/1.1" 200 1635
Not Found: /logo_upc.png
[19/Dec/2018 11:15:57] "GET /logo_upc.png HTTP/1.1" 404 2589
[19/Dec/2018 11:18:10] "GET /list HTTP/1.1" 200 1412
[19/Dec/2018 11:18:11] "GET /static/css/list.css HTTP/1.1" 200 501
[19/Dec/2018 11:18:11] "GET /static/js/list.js HTTP/1.1" 200 606
[19/Dec/2018 11:18:11] "GET /static/css/general.css HTTP/1.1" 200 1635
Not Found: /logo_upc.png
[19/Dec/2018 11:18:11] "GET /logo_upc.png HTTP/1.1" 404 2589
[19/Dec/2018 11:19:07] "GET /list HTTP/1.1" 200 1412
[19/Dec/2018 11:19:07] "GET /static/css/list.css HTTP/1.1" 200 501
[19/Dec/2018 11:19:07] "GET /static/js/list.js HTTP/1.1" 200 606
[19/Dec/2018 11:19:07] "GET /static/css/general.css HTTP/1.1" 200 1635
Not Found: /logo_upc.png
[19/Dec/2018 11:19:07] "GET /logo_upc.png HTTP/1.1" 404 2589
[19/Dec/2018 11:19:37] "GET /list HTTP/1.1" 200 1412
[19/Dec/2018 11:19:37] "GET /static/css/list.css HTTP/1.1" 200 490
[19/Dec/2018 11:19:37] "GET /static/js/list.js HTTP/1.1" 200 606
[19/Dec/2018 11:19:37] "GET /static/css/general.css HTTP/1.1" 200 1635
Not Found: /logo_upc.png
[19/Dec/2018 11:19:38] "GET /logo_upc.png HTTP/1.1" 404 2589
[19/Dec/2018 11:20:06] "GET /list HTTP/1.1" 200 1412
[19/Dec/2018 11:20:06] "GET /static/js/list.js HTTP/1.1" 200 606
[19/Dec/2018 11:20:06] "GET /static/css/list.css HTTP/1.1" 200 507
[19/Dec/2018 11:20:06] "GET /static/css/general.css HTTP/1.1" 200 1635
Not Found: /logo_upc.png
[19/Dec/2018 11:20:06] "GET /logo_upc.png HTTP/1.1" 404 2589
[19/Dec/2018 11:20:36] "GET /list HTTP/1.1" 200 1412
[19/Dec/2018 11:20:36] "GET /static/css/list.css HTTP/1.1" 200 547
[19/Dec/2018 11:20:36] "GET /static/js/list.js HTTP/1.1" 200 606
[19/Dec/2018 11:20:36] "GET /static/css/general.css HTTP/1.1" 200 1635
Not Found: /logo_upc.png
[19/Dec/2018 11:20:36] "GET /logo_upc.png HTTP/1.1" 404 2589
[19/Dec/2018 11:20:45] "GET /list HTTP/1.1" 200 1412
[19/Dec/2018 11:20:45] "GET /static/css/list.css HTTP/1.1" 200 547
[19/Dec/2018 11:20:45] "GET /static/js/list.js HTTP/1.1" 200 606
[19/Dec/2018 11:20:45] "GET /static/css/general.css HTTP/1.1" 200 1635
Not Found: /logo_upc.png
[19/Dec/2018 11:20:45] "GET /logo_upc.png HTTP/1.1" 404 2589
[19/Dec/2018 11:21:35] "GET /list HTTP/1.1" 200 1412
[19/Dec/2018 11:21:35] "GET /static/js/list.js HTTP/1.1" 200 606
[19/Dec/2018 11:21:35] "GET /static/css/list.css HTTP/1.1" 200 586
[19/Dec/2018 11:21:35] "GET /static/css/general.css HTTP/1.1" 200 1635
Not Found: /logo_upc.png
[19/Dec/2018 11:21:35] "GET /logo_upc.png HTTP/1.1" 404 2589
[19/Dec/2018 11:48:59] "GET /list HTTP/1.1" 200 1434
[19/Dec/2018 11:48:59] "GET /static/css/list.css HTTP/1.1" 200 573
[19/Dec/2018 11:48:59] "GET /static/js/list.js HTTP/1.1" 200 606
[19/Dec/2018 11:48:59] "GET /static/css/general.css HTTP/1.1" 200 1635
Not Found: /logo_upc.png
[19/Dec/2018 11:48:59] "GET /logo_upc.png HTTP/1.1" 404 2589
[19/Dec/2018 11:50:48] "GET /list HTTP/1.1" 200 1434
[19/Dec/2018 11:50:48] "GET /static/css/list.css HTTP/1.1" 200 560
[19/Dec/2018 11:50:48] "GET /static/js/list.js HTTP/1.1" 200 606
[19/Dec/2018 11:50:48] "GET /static/css/general.css HTTP/1.1" 200 1635
Not Found: /logo_upc.png
[19/Dec/2018 11:50:49] "GET /logo_upc.png HTTP/1.1" 404 2589
[19/Dec/2018 11:55:29] "GET /list HTTP/1.1" 200 1434
[19/Dec/2018 11:55:30] "GET /static/css/list.css HTTP/1.1" 200 590
[19/Dec/2018 11:55:30] "GET /static/js/list.js HTTP/1.1" 200 606
[19/Dec/2018 11:55:30] "GET /static/css/general.css HTTP/1.1" 200 1635
Not Found: /logo_upc.png
[19/Dec/2018 11:55:30] "GET /logo_upc.png HTTP/1.1" 404 2589
[19/Dec/2018 12:04:51] "GET /list HTTP/1.1" 200 1434
[19/Dec/2018 12:04:51] "GET /static/css/list.css HTTP/1.1" 200 590
[19/Dec/2018 12:04:51] "GET /static/js/list.js HTTP/1.1" 200 606
[19/Dec/2018 12:04:51] "GET /static/css/general.css HTTP/1.1" 200 1635
Not Found: /logo_upc.png
[19/Dec/2018 12:04:51] "GET /logo_upc.png HTTP/1.1" 404 2589
[19/Dec/2018 12:06:51] "GET /list HTTP/1.1" 200 1417
[19/Dec/2018 12:06:51] "GET /static/css/list.css HTTP/1.1" 200 590
[19/Dec/2018 12:06:51] "GET /static/js/list.js HTTP/1.1" 200 606
[19/Dec/2018 12:06:51] "GET /static/css/general.css HTTP/1.1" 200 1635
Not Found: /logo_upc.png
[19/Dec/2018 12:06:52] "GET /logo_upc.png HTTP/1.1" 404 2589
[19/Dec/2018 12:07:33] "GET /list HTTP/1.1" 200 1417
[19/Dec/2018 12:07:33] "GET /static/css/list.css HTTP/1.1" 200 668
[19/Dec/2018 12:07:33] "GET /static/js/list.js HTTP/1.1" 200 606
[19/Dec/2018 12:07:33] "GET /static/css/general.css HTTP/1.1" 200 1635
Not Found: /logo_upc.png
[19/Dec/2018 12:07:33] "GET /logo_upc.png HTTP/1.1" 404 2589
[19/Dec/2018 12:07:46] "GET /list HTTP/1.1" 200 1417
[19/Dec/2018 12:07:46] "GET /static/js/list.js HTTP/1.1" 200 606
[19/Dec/2018 12:07:46] "GET /static/css/list.css HTTP/1.1" 200 672
[19/Dec/2018 12:07:46] "GET /static/css/general.css HTTP/1.1" 200 1635
Not Found: /logo_upc.png
[19/Dec/2018 12:07:46] "GET /logo_upc.png HTTP/1.1" 404 2589
[19/Dec/2018 12:07:55] "GET /list HTTP/1.1" 200 1417
[19/Dec/2018 12:07:56] "GET /static/css/list.css HTTP/1.1" 200 676
[19/Dec/2018 12:07:56] "GET /static/js/list.js HTTP/1.1" 200 606
[19/Dec/2018 12:07:56] "GET /static/css/general.css HTTP/1.1" 200 1635
Not Found: /logo_upc.png
[19/Dec/2018 12:07:56] "GET /logo_upc.png HTTP/1.1" 404 2589
[19/Dec/2018 12:08:05] "GET /list HTTP/1.1" 200 1417
[19/Dec/2018 12:08:05] "GET /static/js/list.js HTTP/1.1" 200 606
[19/Dec/2018 12:08:05] "GET /static/css/list.css HTTP/1.1" 200 688
[19/Dec/2018 12:08:06] "GET /static/css/general.css HTTP/1.1" 200 1635
Not Found: /logo_upc.png
[19/Dec/2018 12:08:06] "GET /logo_upc.png HTTP/1.1" 404 2589
[19/Dec/2018 12:43:06] "GET /list HTTP/1.1" 200 1417
[19/Dec/2018 12:43:06] "GET /static/js/list.js HTTP/1.1" 200 606
[19/Dec/2018 12:43:06] "GET /static/css/list.css HTTP/1.1" 200 688
[19/Dec/2018 12:43:06] "GET /static/css/general.css HTTP/1.1" 200 1635
Not Found: /logo_upc.png
[19/Dec/2018 12:43:06] "GET /logo_upc.png HTTP/1.1" 404 2589
[19/Dec/2018 12:46:25] "GET /list HTTP/1.1" 200 1417
[19/Dec/2018 12:46:25] "GET /static/css/list.css HTTP/1.1" 200 713
[19/Dec/2018 12:46:25] "GET /static/js/list.js HTTP/1.1" 200 606
[19/Dec/2018 12:46:26] "GET /static/css/general.css HTTP/1.1" 200 1635
Not Found: /logo_upc.png
[19/Dec/2018 12:46:26] "GET /logo_upc.png HTTP/1.1" 404 2589
[19/Dec/2018 12:55:21] "GET /list HTTP/1.1" 200 1417
[19/Dec/2018 12:55:22] "GET /static/css/list.css HTTP/1.1" 200 713
[19/Dec/2018 12:55:22] "GET /static/js/list.js HTTP/1.1" 200 606
[19/Dec/2018 12:55:22] "GET /static/css/general.css HTTP/1.1" 200 1635
Not Found: /logo_upc.png
[19/Dec/2018 12:55:22] "GET /logo_upc.png HTTP/1.1" 404 2589
[19/Dec/2018 12:56:24] "GET /list HTTP/1.1" 200 1417
[19/Dec/2018 12:56:24] "GET /static/css/list.css HTTP/1.1" 200 732
[19/Dec/2018 12:56:24] "GET /static/js/list.js HTTP/1.1" 200 606
[19/Dec/2018 12:56:24] "GET /static/css/general.css HTTP/1.1" 200 1635
Not Found: /logo_upc.png
[19/Dec/2018 12:56:24] "GET /logo_upc.png HTTP/1.1" 404 2589
[19/Dec/2018 12:57:09] "GET /list HTTP/1.1" 200 1417
[19/Dec/2018 12:57:10] "GET /static/js/list.js HTTP/1.1" 200 606
[19/Dec/2018 12:57:10] "GET /static/css/list.css HTTP/1.1" 200 734
[19/Dec/2018 12:57:10] "GET /static/css/general.css HTTP/1.1" 200 1635
Not Found: /logo_upc.png
[19/Dec/2018 12:57:10] "GET /logo_upc.png HTTP/1.1" 404 2589
[19/Dec/2018 12:57:26] "GET /list HTTP/1.1" 200 1417
[19/Dec/2018 12:57:26] "GET /static/css/list.css HTTP/1.1" 200 746
[19/Dec/2018 12:57:26] "GET /static/js/list.js HTTP/1.1" 200 606
[19/Dec/2018 12:57:26] "GET /static/css/general.css HTTP/1.1" 200 1635
Not Found: /logo_upc.png
[19/Dec/2018 12:57:26] "GET /logo_upc.png HTTP/1.1" 404 2589
[19/Dec/2018 12:59:38] "GET /list HTTP/1.1" 200 1417
[19/Dec/2018 12:59:38] "GET /static/js/list.js HTTP/1.1" 200 606
[19/Dec/2018 12:59:38] "GET /static/css/list.css HTTP/1.1" 200 748
[19/Dec/2018 12:59:38] "GET /static/css/general.css HTTP/1.1" 200 1635
Not Found: /logo_upc.png
[19/Dec/2018 12:59:38] "GET /logo_upc.png HTTP/1.1" 404 2589
[19/Dec/2018 12:59:44] "GET /list HTTP/1.1" 200 1417
[19/Dec/2018 12:59:44] "GET /static/css/list.css HTTP/1.1" 200 749
[19/Dec/2018 12:59:44] "GET /static/js/list.js HTTP/1.1" 200 606
[19/Dec/2018 12:59:44] "GET /static/css/general.css HTTP/1.1" 200 1635
Not Found: /logo_upc.png
[19/Dec/2018 12:59:44] "GET /logo_upc.png HTTP/1.1" 404 2589
[19/Dec/2018 12:59:52] "GET /list HTTP/1.1" 200 1417
[19/Dec/2018 12:59:52] "GET /static/css/list.css HTTP/1.1" 200 749
[19/Dec/2018 12:59:52] "GET /static/js/list.js HTTP/1.1" 200 606
[19/Dec/2018 12:59:53] "GET /static/css/general.css HTTP/1.1" 200 1635
Not Found: /logo_upc.png
[19/Dec/2018 12:59:53] "GET /logo_upc.png HTTP/1.1" 404 2589
[19/Dec/2018 13:00:37] "GET /list HTTP/1.1" 200 1417
[19/Dec/2018 13:00:37] "GET /static/css/list.css HTTP/1.1" 200 769
[19/Dec/2018 13:00:37] "GET /static/js/list.js HTTP/1.1" 200 606
[19/Dec/2018 13:00:37] "GET /static/css/general.css HTTP/1.1" 200 1635
Not Found: /logo_upc.png
[19/Dec/2018 13:00:37] "GET /logo_upc.png HTTP/1.1" 404 2589
[19/Dec/2018 13:00:43] "GET /list HTTP/1.1" 200 1417
[19/Dec/2018 13:00:43] "GET /static/css/list.css HTTP/1.1" 200 769
[19/Dec/2018 13:00:43] "GET /static/js/list.js HTTP/1.1" 200 606
[19/Dec/2018 13:00:43] "GET /static/css/general.css HTTP/1.1" 200 1635
Not Found: /logo_upc.png
[19/Dec/2018 13:00:43] "GET /logo_upc.png HTTP/1.1" 404 2589
[19/Dec/2018 13:00:49] "GET /list HTTP/1.1" 200 1417
[19/Dec/2018 13:00:49] "GET /static/css/list.css HTTP/1.1" 200 768
[19/Dec/2018 13:00:49] "GET /static/js/list.js HTTP/1.1" 200 606
[19/Dec/2018 13:00:49] "GET /static/css/general.css HTTP/1.1" 200 1635
Not Found: /logo_upc.png
[19/Dec/2018 13:00:49] "GET /logo_upc.png HTTP/1.1" 404 2589
[19/Dec/2018 13:00:54] "GET /list HTTP/1.1" 200 1417
[19/Dec/2018 13:00:55] "GET /static/css/list.css HTTP/1.1" 200 768
[19/Dec/2018 13:00:55] "GET /static/js/list.js HTTP/1.1" 200 606
[19/Dec/2018 13:00:55] "GET /static/css/general.css HTTP/1.1" 200 1635
Not Found: /logo_upc.png
[19/Dec/2018 13:00:55] "GET /logo_upc.png HTTP/1.1" 404 2589
[19/Dec/2018 13:01:15] "GET /list HTTP/1.1" 200 1417
[19/Dec/2018 13:01:15] "GET /static/js/list.js HTTP/1.1" 200 606
[19/Dec/2018 13:01:15] "GET /static/css/list.css HTTP/1.1" 200 753
[19/Dec/2018 13:01:15] "GET /static/css/general.css HTTP/1.1" 200 1635
Not Found: /logo_upc.png
[19/Dec/2018 13:01:16] "GET /logo_upc.png HTTP/1.1" 404 2589
[19/Dec/2018 13:01:27] "GET /list HTTP/1.1" 200 1417
[19/Dec/2018 13:01:28] "GET /static/js/list.js HTTP/1.1" 200 606
[19/Dec/2018 13:01:28] "GET /static/css/list.css HTTP/1.1" 200 767
[19/Dec/2018 13:01:28] "GET /static/css/general.css HTTP/1.1" 200 1635
Not Found: /logo_upc.png
[19/Dec/2018 13:01:28] "GET /logo_upc.png HTTP/1.1" 404 2589
[19/Dec/2018 13:01:58] "GET /list HTTP/1.1" 200 1417
[19/Dec/2018 13:01:59] "GET /static/css/list.css HTTP/1.1" 200 768
[19/Dec/2018 13:01:59] "GET /static/js/list.js HTTP/1.1" 200 606
[19/Dec/2018 13:01:59] "GET /static/css/general.css HTTP/1.1" 200 1635
Not Found: /logo_upc.png
[19/Dec/2018 13:01:59] "GET /logo_upc.png HTTP/1.1" 404 2589
[19/Dec/2018 13:07:11] "GET /list HTTP/1.1" 200 1417
[19/Dec/2018 13:07:11] "GET /static/css/list.css HTTP/1.1" 200 767
[19/Dec/2018 13:07:11] "GET /static/js/list.js HTTP/1.1" 200 606
[19/Dec/2018 13:07:11] "GET /static/css/general.css HTTP/1.1" 200 1635
Not Found: /logo_upc.png
[19/Dec/2018 13:07:12] "GET /logo_upc.png HTTP/1.1" 404 2589
[19/Dec/2018 13:07:24] "GET /list HTTP/1.1" 200 1417
[19/Dec/2018 13:07:24] "GET /static/js/list.js HTTP/1.1" 200 606
[19/Dec/2018 13:07:24] "GET /static/css/list.css HTTP/1.1" 200 767
[19/Dec/2018 13:07:25] "GET /static/css/general.css HTTP/1.1" 200 1635
Not Found: /logo_upc.png
[19/Dec/2018 13:07:25] "GET /logo_upc.png HTTP/1.1" 404 2589
[19/Dec/2018 13:11:10] "GET /list HTTP/1.1" 200 1417
[19/Dec/2018 13:11:10] "GET /static/css/list.css HTTP/1.1" 200 816
[19/Dec/2018 13:11:10] "GET /static/js/list.js HTTP/1.1" 200 606
[19/Dec/2018 13:11:11] "GET /static/css/general.css HTTP/1.1" 200 1635
Not Found: /logo_upc.png
[19/Dec/2018 13:11:11] "GET /logo_upc.png HTTP/1.1" 404 2589
[19/Dec/2018 13:11:29] "GET /list HTTP/1.1" 200 1417
[19/Dec/2018 13:11:29] "GET /static/js/list.js HTTP/1.1" 200 606
[19/Dec/2018 13:11:29] "GET /static/css/list.css HTTP/1.1" 200 816
[19/Dec/2018 13:11:29] "GET /static/css/general.css HTTP/1.1" 200 1635
Not Found: /logo_upc.png
[19/Dec/2018 13:11:29] "GET /logo_upc.png HTTP/1.1" 404 2589
[19/Dec/2018 13:15:59] "GET /list HTTP/1.1" 200 1417
[19/Dec/2018 13:15:59] "GET /static/js/list.js HTTP/1.1" 200 606
[19/Dec/2018 13:15:59] "GET /static/css/general.css HTTP/1.1" 200 1635
[19/Dec/2018 13:15:59] "GET /static/css/list.css HTTP/1.1" 200 796
Not Found: /logo_upc.png
[19/Dec/2018 13:16:00] "GET /logo_upc.png HTTP/1.1" 404 2589
[19/Dec/2018 13:19:09] "GET /list HTTP/1.1" 200 1417
[19/Dec/2018 13:19:10] "GET /static/js/list.js HTTP/1.1" 200 606
[19/Dec/2018 13:19:10] "GET /static/css/list.css HTTP/1.1" 200 838
[19/Dec/2018 13:19:10] "GET /static/css/general.css HTTP/1.1" 200 1635
Not Found: /logo_upc.png
[19/Dec/2018 13:19:10] "GET /logo_upc.png HTTP/1.1" 404 2589
[19/Dec/2018 13:21:54] "GET /list HTTP/1.1" 200 1417
[19/Dec/2018 13:21:54] "GET /static/js/list.js HTTP/1.1" 200 606
[19/Dec/2018 13:21:54] "GET /static/css/list.css HTTP/1.1" 200 907
[19/Dec/2018 13:21:54] "GET /static/css/general.css HTTP/1.1" 200 1635
Not Found: /logo_upc.png
[19/Dec/2018 13:21:55] "GET /logo_upc.png HTTP/1.1" 404 2589
[19/Dec/2018 13:24:01] "GET /list HTTP/1.1" 200 1417
[19/Dec/2018 13:24:02] "GET /static/css/list.css HTTP/1.1" 200 881
[19/Dec/2018 13:24:02] "GET /static/js/list.js HTTP/1.1" 200 606
[19/Dec/2018 13:24:02] "GET /static/css/general.css HTTP/1.1" 200 1635
Not Found: /logo_upc.png
[19/Dec/2018 13:24:02] "GET /logo_upc.png HTTP/1.1" 404 2589
[19/Dec/2018 13:37:40] "GET /list HTTP/1.1" 200 1417
[19/Dec/2018 13:37:41] "GET /static/css/list.css HTTP/1.1" 200 886
[19/Dec/2018 13:37:41] "GET /static/js/list.js HTTP/1.1" 200 606
[19/Dec/2018 13:37:41] "GET /static/css/general.css HTTP/1.1" 200 1635
Not Found: /logo_upc.png
[19/Dec/2018 13:37:41] "GET /logo_upc.png HTTP/1.1" 404 2589
[19/Dec/2018 13:42:18] "GET /list HTTP/1.1" 200 1417
[19/Dec/2018 13:42:19] "GET /static/css/list.css HTTP/1.1" 200 899
[19/Dec/2018 13:42:19] "GET /static/js/list.js HTTP/1.1" 200 606
[19/Dec/2018 13:42:19] "GET /static/css/general.css HTTP/1.1" 200 1635
Not Found: /logo_upc.png
[19/Dec/2018 13:42:19] "GET /logo_upc.png HTTP/1.1" 404 2589
[19/Dec/2018 13:44:10] "GET /list HTTP/1.1" 200 1417
[19/Dec/2018 13:44:10] "GET /static/css/list.css HTTP/1.1" 200 920
[19/Dec/2018 13:44:10] "GET /static/js/list.js HTTP/1.1" 200 606
[19/Dec/2018 13:44:10] "GET /static/css/general.css HTTP/1.1" 200 1635
Not Found: /logo_upc.png
[19/Dec/2018 13:44:10] "GET /logo_upc.png HTTP/1.1" 404 2589
[19/Dec/2018 13:49:04] "GET /list HTTP/1.1" 200 1417
[19/Dec/2018 13:49:05] "GET /static/js/list.js HTTP/1.1" 200 606
[19/Dec/2018 13:49:05] "GET /static/css/list.css HTTP/1.1" 200 922
[19/Dec/2018 13:49:05] "GET /static/css/general.css HTTP/1.1" 200 1635
Not Found: /logo_upc.png
[19/Dec/2018 13:49:05] "GET /logo_upc.png HTTP/1.1" 404 2589
[2018-12-19 13:49:59,201 pyinotify ERROR] The pathname '/home/pi/tfg/django/tornejos/project/application/views.py' of this watch <Watch wd=27 path=/home/pi/tfg/django/tornejos/project/application/views.py mask=4038 proc_fun=None auto_add=False exclude_filter=<function WatchManager.<lambda> at 0xb65d06a8> dir=False > has probably changed and couldn't be updated, so it cannot be trusted anymore. To fix this error move directories/files only between watched parents directories, in this case e.g. put a watch on '/home/pi/tfg/django/tornejos/project/application'.
Performing system checks...

System check identified no issues (0 silenced).
December 19, 2018 - 09:19:23
Django version 2.1.3, using settings 'project.settings'
Starting development server at http://127.0.0.1:8000/
Quit the server with CONTROL-C.
[19/Dec/2018 13:50:17] "GET /list HTTP/1.1" 200 1700
[19/Dec/2018 13:50:17] "GET /static/css/list.css HTTP/1.1" 200 922
[19/Dec/2018 13:50:17] "GET /static/js/list.js HTTP/1.1" 200 606
[19/Dec/2018 13:50:17] "GET /static/css/general.css HTTP/1.1" 200 1635
Not Found: /logo_upc.png
[19/Dec/2018 13:50:18] "GET /logo_upc.png HTTP/1.1" 404 2589
[19/Dec/2018 13:56:23] "GET /list HTTP/1.1" 200 1700
[19/Dec/2018 13:56:23] "GET /static/css/list.css HTTP/1.1" 200 944
[19/Dec/2018 13:56:23] "GET /static/js/list.js HTTP/1.1" 200 565
[19/Dec/2018 13:56:23] "GET /static/css/general.css HTTP/1.1" 200 1635
Not Found: /logo_upc.png
[19/Dec/2018 13:56:23] "GET /logo_upc.png HTTP/1.1" 404 2589
[19/Dec/2018 13:59:02] "GET /list HTTP/1.1" 200 1700
[19/Dec/2018 13:59:02] "GET /static/js/list.js HTTP/1.1" 200 581
[19/Dec/2018 13:59:02] "GET /static/css/list.css HTTP/1.1" 200 944
[19/Dec/2018 13:59:02] "GET /static/css/general.css HTTP/1.1" 200 1635
Not Found: /logo_upc.png
[19/Dec/2018 13:59:02] "GET /logo_upc.png HTTP/1.1" 404 2589
[19/Dec/2018 13:59:48] "GET /list HTTP/1.1" 200 1700
[19/Dec/2018 13:59:48] "GET /static/css/list.css HTTP/1.1" 200 944
[19/Dec/2018 13:59:48] "GET /static/js/list.js HTTP/1.1" 200 591
[19/Dec/2018 13:59:48] "GET /static/css/general.css HTTP/1.1" 200 1635
Not Found: /logo_upc.png
[19/Dec/2018 13:59:48] "GET /logo_upc.png HTTP/1.1" 404 2589
[19/Dec/2018 14:00:46] "GET /list HTTP/1.1" 200 1700
[19/Dec/2018 14:00:46] "GET /static/css/list.css HTTP/1.1" 200 944
[19/Dec/2018 14:00:46] "GET /static/js/list.js HTTP/1.1" 200 591
[19/Dec/2018 14:00:46] "GET /static/css/general.css HTTP/1.1" 200 1635
Not Found: /logo_upc.png
[19/Dec/2018 14:00:46] "GET /logo_upc.png HTTP/1.1" 404 2589
[19/Dec/2018 14:01:08] "GET /list HTTP/1.1" 200 1700
[19/Dec/2018 14:01:08] "GET /static/js/list.js HTTP/1.1" 200 607
[19/Dec/2018 14:01:08] "GET /static/css/list.css HTTP/1.1" 200 944
[19/Dec/2018 14:01:08] "GET /static/css/general.css HTTP/1.1" 200 1635
Not Found: /logo_upc.png
[19/Dec/2018 14:01:09] "GET /logo_upc.png HTTP/1.1" 404 2589
[19/Dec/2018 14:07:18] "GET /list HTTP/1.1" 200 1700
[19/Dec/2018 14:07:18] "GET /static/css/list.css HTTP/1.1" 200 944
[19/Dec/2018 14:07:18] "GET /static/js/list.js HTTP/1.1" 200 611
[19/Dec/2018 14:07:18] "GET /static/css/general.css HTTP/1.1" 200 1635
Not Found: /logo_upc.png
[19/Dec/2018 14:07:18] "GET /logo_upc.png HTTP/1.1" 404 2589
[19/Dec/2018 14:07:43] "GET /list HTTP/1.1" 200 1700
[19/Dec/2018 14:07:44] "GET /static/js/list.js HTTP/1.1" 200 630
[19/Dec/2018 14:07:44] "GET /static/css/list.css HTTP/1.1" 200 944
[19/Dec/2018 14:07:44] "GET /static/css/general.css HTTP/1.1" 200 1635
Not Found: /logo_upc.png
[19/Dec/2018 14:07:44] "GET /logo_upc.png HTTP/1.1" 404 2589
[19/Dec/2018 14:07:54] "GET /list HTTP/1.1" 200 1700
[19/Dec/2018 14:07:54] "GET /static/css/list.css HTTP/1.1" 200 944
[19/Dec/2018 14:07:54] "GET /static/js/list.js HTTP/1.1" 200 637
[19/Dec/2018 14:07:54] "GET /static/css/general.css HTTP/1.1" 200 1635
Not Found: /logo_upc.png
[19/Dec/2018 14:07:55] "GET /logo_upc.png HTTP/1.1" 404 2589
[19/Dec/2018 14:08:11] "GET /list HTTP/1.1" 200 1700
[19/Dec/2018 14:08:12] "GET /static/css/list.css HTTP/1.1" 200 944
[19/Dec/2018 14:08:12] "GET /static/js/list.js HTTP/1.1" 200 621
[19/Dec/2018 14:08:12] "GET /static/css/general.css HTTP/1.1" 200 1635
Not Found: /logo_upc.png
[19/Dec/2018 14:08:12] "GET /logo_upc.png HTTP/1.1" 404 2589
[19/Dec/2018 14:09:38] "GET /list HTTP/1.1" 200 1700
[19/Dec/2018 14:09:38] "GET /static/css/list.css HTTP/1.1" 200 944
[19/Dec/2018 14:09:38] "GET /static/js/list.js HTTP/1.1" 200 602
[19/Dec/2018 14:09:38] "GET /static/css/general.css HTTP/1.1" 200 1635
Not Found: /logo_upc.png
[19/Dec/2018 14:09:38] "GET /logo_upc.png HTTP/1.1" 404 2589
[19/Dec/2018 14:10:26] "GET /list HTTP/1.1" 200 1700
[19/Dec/2018 14:10:26] "GET /static/css/list.css HTTP/1.1" 200 944
[19/Dec/2018 14:10:26] "GET /static/js/list.js HTTP/1.1" 200 583
[19/Dec/2018 14:10:27] "GET /static/css/general.css HTTP/1.1" 200 1635
Not Found: /logo_upc.png
[19/Dec/2018 14:10:27] "GET /logo_upc.png HTTP/1.1" 404 2589
[19/Dec/2018 14:10:55] "GET /list HTTP/1.1" 200 1700
[19/Dec/2018 14:10:55] "GET /static/js/list.js HTTP/1.1" 200 612
[19/Dec/2018 14:10:55] "GET /static/css/list.css HTTP/1.1" 200 944
[19/Dec/2018 14:10:56] "GET /static/css/general.css HTTP/1.1" 200 1635
Not Found: /logo_upc.png
[19/Dec/2018 14:10:56] "GET /logo_upc.png HTTP/1.1" 404 2589
[19/Dec/2018 14:13:57] "GET /list HTTP/1.1" 200 1700
[19/Dec/2018 14:13:57] "GET /static/css/list.css HTTP/1.1" 200 944
[19/Dec/2018 14:13:57] "GET /static/js/list.js HTTP/1.1" 200 614
[19/Dec/2018 14:13:57] "GET /static/css/general.css HTTP/1.1" 200 1635
Not Found: /logo_upc.png
[19/Dec/2018 14:13:57] "GET /logo_upc.png HTTP/1.1" 404 2589
[19/Dec/2018 14:15:09] "GET /list HTTP/1.1" 200 1700
[19/Dec/2018 14:15:09] "GET /static/css/list.css HTTP/1.1" 200 944
[19/Dec/2018 14:15:09] "GET /static/js/list.js HTTP/1.1" 200 617
[19/Dec/2018 14:15:09] "GET /static/css/general.css HTTP/1.1" 200 1635
Not Found: /logo_upc.png
[19/Dec/2018 14:15:09] "GET /logo_upc.png HTTP/1.1" 404 2589
[19/Dec/2018 14:15:44] "GET /list HTTP/1.1" 200 1700
[19/Dec/2018 14:15:44] "GET /static/css/list.css HTTP/1.1" 200 944
[19/Dec/2018 14:15:44] "GET /static/js/list.js HTTP/1.1" 200 614
[19/Dec/2018 14:15:44] "GET /static/css/general.css HTTP/1.1" 200 1635
Not Found: /logo_upc.png
[19/Dec/2018 14:15:44] "GET /logo_upc.png HTTP/1.1" 404 2589
[19/Dec/2018 14:16:03] "GET /list HTTP/1.1" 200 1700
[19/Dec/2018 14:16:03] "GET /static/css/list.css HTTP/1.1" 200 944
[19/Dec/2018 14:16:03] "GET /static/js/list.js HTTP/1.1" 200 616
[19/Dec/2018 14:16:03] "GET /static/css/general.css HTTP/1.1" 200 1635
Not Found: /logo_upc.png
[19/Dec/2018 14:16:03] "GET /logo_upc.png HTTP/1.1" 404 2589
[19/Dec/2018 14:16:27] "GET /list HTTP/1.1" 200 1700
[19/Dec/2018 14:16:28] "GET /static/js/list.js HTTP/1.1" 200 617
[19/Dec/2018 14:16:28] "GET /static/css/list.css HTTP/1.1" 200 944
[19/Dec/2018 14:16:28] "GET /static/css/general.css HTTP/1.1" 200 1635
Not Found: /logo_upc.png
[19/Dec/2018 14:16:28] "GET /logo_upc.png HTTP/1.1" 404 2589
[19/Dec/2018 14:16:58] "GET /list HTTP/1.1" 200 1700
[19/Dec/2018 14:16:58] "GET /static/css/list.css HTTP/1.1" 200 944
[19/Dec/2018 14:16:58] "GET /static/js/list.js HTTP/1.1" 200 619
[19/Dec/2018 14:16:58] "GET /static/css/general.css HTTP/1.1" 200 1635
Not Found: /logo_upc.png
[19/Dec/2018 14:16:59] "GET /logo_upc.png HTTP/1.1" 404 2589
[19/Dec/2018 14:18:14] "GET / HTTP/1.1" 200 686
[19/Dec/2018 14:18:18] "GET /test HTTP/1.1" 200 1417
[19/Dec/2018 14:18:18] "GET /static/js/list.js HTTP/1.1" 200 619
Not Found: /logo_upc.png
[19/Dec/2018 14:18:18] "GET /logo_upc.png HTTP/1.1" 404 2589
[19/Dec/2018 14:18:21] "GET /list HTTP/1.1" 200 1700
[19/Dec/2018 14:18:22] "GET /static/js/list.js HTTP/1.1" 304 0
Not Found: /logo_upc.png
[19/Dec/2018 14:18:22] "GET /logo_upc.png HTTP/1.1" 404 2589
[19/Dec/2018 14:18:36] "GET /blog/ HTTP/1.1" 200 3857
[19/Dec/2018 14:19:19] "GET /list HTTP/1.1" 200 1700
[19/Dec/2018 14:19:19] "GET /static/js/list.js HTTP/1.1" 304 0
Not Found: /logo_upc.png
[19/Dec/2018 14:19:19] "GET /logo_upc.png HTTP/1.1" 404 2589
[19/Dec/2018 14:26:52] "GET /list HTTP/1.1" 200 1700
[19/Dec/2018 14:26:52] "GET /static/js/list.js HTTP/1.1" 200 619
[19/Dec/2018 14:26:52] "GET /static/css/list.css HTTP/1.1" 200 944
[19/Dec/2018 14:26:52] "GET /static/css/general.css HTTP/1.1" 200 1635
Not Found: /logo_upc.png
[19/Dec/2018 14:26:52] "GET /logo_upc.png HTTP/1.1" 404 2589
[19/Dec/2018 14:28:19] "GET /list HTTP/1.1" 200 1700
[19/Dec/2018 14:28:19] "GET /static/css/list.css HTTP/1.1" 200 1024
[19/Dec/2018 14:28:19] "GET /static/js/list.js HTTP/1.1" 200 619
[19/Dec/2018 14:28:19] "GET /static/css/general.css HTTP/1.1" 200 1635
Not Found: /logo_upc.png
[19/Dec/2018 14:28:20] "GET /logo_upc.png HTTP/1.1" 404 2589
[19/Dec/2018 14:29:25] "GET /list HTTP/1.1" 200 1700
[19/Dec/2018 14:29:25] "GET /static/css/list.css HTTP/1.1" 200 1113
[19/Dec/2018 14:29:25] "GET /static/js/list.js HTTP/1.1" 200 619
[19/Dec/2018 14:29:25] "GET /static/css/general.css HTTP/1.1" 200 1635
Not Found: /logo_upc.png
[19/Dec/2018 14:29:25] "GET /logo_upc.png HTTP/1.1" 404 2589
[19/Dec/2018 14:30:36] "GET /list HTTP/1.1" 200 1700
[19/Dec/2018 14:30:36] "GET /static/js/list.js HTTP/1.1" 200 619
[19/Dec/2018 14:30:37] "GET /static/css/list.css HTTP/1.1" 200 1113
[19/Dec/2018 14:30:37] "GET /static/css/general.css HTTP/1.1" 200 1635
Not Found: /logo_upc.png
[19/Dec/2018 14:30:37] "GET /logo_upc.png HTTP/1.1" 404 2589
[19/Dec/2018 14:31:03] "GET /list HTTP/1.1" 200 1700
[19/Dec/2018 14:31:03] "GET /static/css/list.css HTTP/1.1" 200 1131
[19/Dec/2018 14:31:03] "GET /static/js/list.js HTTP/1.1" 200 619
[19/Dec/2018 14:31:04] "GET /static/css/general.css HTTP/1.1" 200 1635
Not Found: /logo_upc.png
[19/Dec/2018 14:31:04] "GET /logo_upc.png HTTP/1.1" 404 2589
[19/Dec/2018 14:36:10] "GET /list HTTP/1.1" 200 1700
[19/Dec/2018 14:36:10] "GET /static/js/list.js HTTP/1.1" 200 619
[19/Dec/2018 14:36:10] "GET /static/css/list.css HTTP/1.1" 200 1171
[19/Dec/2018 14:36:10] "GET /static/css/general.css HTTP/1.1" 200 1635
Not Found: /logo_upc.png
[19/Dec/2018 14:36:11] "GET /logo_upc.png HTTP/1.1" 404 2589
[19/Dec/2018 14:36:21] "GET /list HTTP/1.1" 200 1700
[19/Dec/2018 14:36:21] "GET /static/css/list.css HTTP/1.1" 200 1171
[19/Dec/2018 14:36:21] "GET /static/js/list.js HTTP/1.1" 200 619
[19/Dec/2018 14:36:21] "GET /static/css/general.css HTTP/1.1" 200 1635
Not Found: /logo_upc.png
[19/Dec/2018 14:36:21] "GET /logo_upc.png HTTP/1.1" 404 2589
[19/Dec/2018 14:36:30] "GET /list HTTP/1.1" 200 1700
[19/Dec/2018 14:36:31] "GET /static/js/list.js HTTP/1.1" 200 619
[19/Dec/2018 14:36:31] "GET /static/css/list.css HTTP/1.1" 200 1171
[19/Dec/2018 14:36:31] "GET /static/css/general.css HTTP/1.1" 200 1635
Not Found: /logo_upc.png
[19/Dec/2018 14:36:31] "GET /logo_upc.png HTTP/1.1" 404 2589
[19/Dec/2018 14:36:41] "GET /list HTTP/1.1" 200 1700
[19/Dec/2018 14:36:41] "GET /static/css/list.css HTTP/1.1" 200 1171
[19/Dec/2018 14:36:41] "GET /static/js/list.js HTTP/1.1" 200 619
[19/Dec/2018 14:36:41] "GET /static/css/general.css HTTP/1.1" 200 1635
Not Found: /logo_upc.png
[19/Dec/2018 14:36:41] "GET /logo_upc.png HTTP/1.1" 404 2589
[19/Dec/2018 14:36:52] "GET /list HTTP/1.1" 200 1700
[19/Dec/2018 14:36:52] "GET /static/css/list.css HTTP/1.1" 200 1171
[19/Dec/2018 14:36:52] "GET /static/js/list.js HTTP/1.1" 200 619
[19/Dec/2018 14:36:52] "GET /static/css/general.css HTTP/1.1" 200 1635
Not Found: /logo_upc.png
[19/Dec/2018 14:36:52] "GET /logo_upc.png HTTP/1.1" 404 2589
[19/Dec/2018 14:37:01] "GET /list HTTP/1.1" 200 1700
[19/Dec/2018 14:37:01] "GET /static/css/list.css HTTP/1.1" 200 1171
[19/Dec/2018 14:37:01] "GET /static/js/list.js HTTP/1.1" 200 619
[19/Dec/2018 14:37:01] "GET /static/css/general.css HTTP/1.1" 200 1635
Not Found: /logo_upc.png
[19/Dec/2018 14:37:01] "GET /logo_upc.png HTTP/1.1" 404 2589
[19/Dec/2018 14:40:46] "GET /test HTTP/1.1" 200 1417
[19/Dec/2018 14:40:46] "GET /static/js/list.js HTTP/1.1" 304 0
[19/Dec/2018 14:40:46] "GET /static/css/list.css HTTP/1.1" 304 0
Not Found: /logo_upc.png
[19/Dec/2018 14:40:46] "GET /logo_upc.png HTTP/1.1" 404 2589
[19/Dec/2018 14:40:52] "GET /list HTTP/1.1" 200 1700
Not Found: /logo_upc.png
[19/Dec/2018 14:40:53] "GET /logo_upc.png HTTP/1.1" 404 2589
[19/Dec/2018 14:46:54] "GET / HTTP/1.1" 200 686
[19/Dec/2018 14:47:02] "GET /blog/ HTTP/1.1" 200 3857
[19/Dec/2018 14:47:06] "GET / HTTP/1.1" 200 686
[19/Dec/2018 14:47:09] "GET /test HTTP/1.1" 200 1417
[19/Dec/2018 14:47:09] "GET /static/js/list.js HTTP/1.1" 304 0
[19/Dec/2018 14:47:09] "GET /static/css/list.css HTTP/1.1" 304 0
Not Found: /logo_upc.png
[19/Dec/2018 14:47:09] "GET /logo_upc.png HTTP/1.1" 404 2589
[19/Dec/2018 14:47:10] "GET /list HTTP/1.1" 200 1700
Not Found: /logo_upc.png
[19/Dec/2018 14:47:11] "GET /logo_upc.png HTTP/1.1" 404 2589
Not Found: /create
[19/Dec/2018 14:47:17] "GET /create HTTP/1.1" 404 2571
[19/Dec/2018 14:47:23] "GET /list HTTP/1.1" 200 1700
Not Found: /logo_upc.png
[19/Dec/2018 14:47:23] "GET /logo_upc.png HTTP/1.1" 404 2589
[19/Dec/2018 14:48:42] "GET /t/200 HTTP/1.1" 200 997
[19/Dec/2018 14:48:42] "GET /static/css/list.css HTTP/1.1" 304 0
Not Found: /t/logo_upc.png
[19/Dec/2018 14:48:42] "GET /t/logo_upc.png HTTP/1.1" 404 2595
Not Found: /create/
[19/Dec/2018 14:48:51] "GET /create/ HTTP/1.1" 404 2574
[19/Dec/2018 14:49:11] "GET /t/200 HTTP/1.1" 200 997
Not Found: /t/logo_upc.png
[19/Dec/2018 14:49:12] "GET /t/logo_upc.png HTTP/1.1" 404 2595
[2018-12-19 14:50:35,986 pyinotify ERROR] The pathname '/home/pi/tfg/django/tornejos/project/urls.py' of this watch <Watch wd=1126 path=/home/pi/tfg/django/tornejos/project/urls.py mask=4038 proc_fun=None auto_add=False exclude_filter=<function WatchManager.<lambda> at 0xb664c6a8> dir=False > has probably changed and couldn't be updated, so it cannot be trusted anymore. To fix this error move directories/files only between watched parents directories, in this case e.g. put a watch on '/home/pi/tfg/django/tornejos/project'.
Performing system checks...

System check identified no issues (0 silenced).
December 19, 2018 - 13:50:16
Django version 2.1.3, using settings 'project.settings'
Starting development server at http://127.0.0.1:8000/
Quit the server with CONTROL-C.
Not Found: /create/
[19/Dec/2018 14:51:08] "GET /create/ HTTP/1.1" 404 2706
Not Found: /create/
[19/Dec/2018 14:51:50] "GET /create/ HTTP/1.1" 404 2706
[19/Dec/2018 14:51:53] "GET /t/200 HTTP/1.1" 200 996
[19/Dec/2018 14:51:54] "GET /static/css/list.css HTTP/1.1" 200 1171
[19/Dec/2018 14:51:54] "GET /static/js/list.js HTTP/1.1" 200 619
[19/Dec/2018 14:51:54] "GET /static/css/general.css HTTP/1.1" 200 1635
Not Found: /t/logo_upc.png
[19/Dec/2018 14:51:54] "GET /t/logo_upc.png HTTP/1.1" 404 2727
Internal Server Error: /create
Traceback (most recent call last):
  File "/home/pi/.local/lib/python3.5/site-packages/django/core/handlers/exception.py", line 34, in inner
    response = get_response(request)
  File "/home/pi/.local/lib/python3.5/site-packages/django/core/handlers/base.py", line 137, in _get_response
    "returned None instead." % (callback.__module__, view_name)
ValueError: The view project.application.views.create_tournament didn't return an HttpResponse object. It returned None instead.
[19/Dec/2018 14:51:57] "GET /create HTTP/1.1" 500 56945
[2018-12-19 14:52:21,573 pyinotify ERROR] The pathname '/home/pi/tfg/django/tornejos/project/application/views.py' of this watch <Watch wd=1027 path=/home/pi/tfg/django/tornejos/project/application/views.py mask=4038 proc_fun=None auto_add=False exclude_filter=<function WatchManager.<lambda> at 0xb669c6a8> dir=False > has probably changed and couldn't be updated, so it cannot be trusted anymore. To fix this error move directories/files only between watched parents directories, in this case e.g. put a watch on '/home/pi/tfg/django/tornejos/project/application'.
Performing system checks...

System check identified no issues (0 silenced).
December 19, 2018 - 14:50:54
Django version 2.1.3, using settings 'project.settings'
Starting development server at http://127.0.0.1:8000/
Quit the server with CONTROL-C.
[19/Dec/2018 14:52:39] "GET /create HTTP/1.1" 200 1650
[19/Dec/2018 14:52:39] "GET /static/js/create.js HTTP/1.1" 200 1422
[19/Dec/2018 14:52:40] "GET /static/css/general.css HTTP/1.1" 200 1635
Not Found: /logo_upc.png
[19/Dec/2018 14:52:40] "GET /logo_upc.png HTTP/1.1" 404 2721
Not Found: /create/
[19/Dec/2018 14:53:05] "POST /create/ HTTP/1.1" 404 2707
Not Found: /create/
[19/Dec/2018 14:53:16] "POST /create/ HTTP/1.1" 404 2707
[19/Dec/2018 14:53:45] "GET /create HTTP/1.1" 200 1649
[19/Dec/2018 14:53:46] "GET /static/js/create.js HTTP/1.1" 200 1422
[19/Dec/2018 14:53:46] "GET /static/css/general.css HTTP/1.1" 200 1635
Not Found: /logo_upc.png
[19/Dec/2018 14:53:46] "GET /logo_upc.png HTTP/1.1" 404 2721
Forbidden (CSRF cookie not set.): /create
[19/Dec/2018 14:53:55] "POST /create HTTP/1.1" 403 2868
[19/Dec/2018 15:55:20] "GET / HTTP/1.1" 200 686
[19/Dec/2018 15:55:22] "GET /blog/ HTTP/1.1" 200 3857
[19/Dec/2018 16:10:27] "GET / HTTP/1.1" 200 686
Not Found: /favicon.ico
[19/Dec/2018 16:10:28] "GET /favicon.ico HTTP/1.1" 404 2718
[19/Dec/2018 16:21:49] "GET / HTTP/1.1" 200 685
[19/Dec/2018 16:21:56] "GET / HTTP/1.1" 200 685
[19/Dec/2018 16:21:56] "GET /static/css/index.css HTTP/1.1" 200 639
Not Found: /favicon.ico
[19/Dec/2018 16:21:57] "GET /favicon.ico HTTP/1.1" 404 2718
[19/Dec/2018 16:23:00] "GET / HTTP/1.1" 200 685
[19/Dec/2018 16:23:00] "GET /static/css/index.css HTTP/1.1" 200 594
Not Found: /favicon.ico
[19/Dec/2018 16:23:00] "GET /favicon.ico HTTP/1.1" 404 2718
[19/Dec/2018 16:23:30] "GET / HTTP/1.1" 200 685
[19/Dec/2018 16:23:30] "GET /static/css/index.css HTTP/1.1" 200 602
Not Found: /favicon.ico
[19/Dec/2018 16:23:30] "GET /favicon.ico HTTP/1.1" 404 2718
[19/Dec/2018 16:24:52] "GET / HTTP/1.1" 200 685
[19/Dec/2018 16:24:52] "GET /static/css/index.css HTTP/1.1" 200 645
Not Found: /favicon.ico
[19/Dec/2018 16:24:52] "GET /favicon.ico HTTP/1.1" 404 2718
[19/Dec/2018 16:25:27] "GET / HTTP/1.1" 200 685
[19/Dec/2018 16:25:27] "GET /static/css/index.css HTTP/1.1" 200 561
Not Found: /favicon.ico
[19/Dec/2018 16:25:27] "GET /favicon.ico HTTP/1.1" 404 2718
[19/Dec/2018 16:25:40] "GET /static/css/index.css HTTP/1.1" 304 0
[19/Dec/2018 16:26:16] "GET / HTTP/1.1" 200 685
[19/Dec/2018 16:26:16] "GET /static/css/index.css HTTP/1.1" 200 561
Not Found: /favicon.ico
[19/Dec/2018 16:26:16] "GET /favicon.ico HTTP/1.1" 404 2718
[19/Dec/2018 16:26:47] "GET / HTTP/1.1" 200 685
[19/Dec/2018 16:26:47] "GET /static/css/index.css HTTP/1.1" 200 577
Not Found: /favicon.ico
[19/Dec/2018 16:26:47] "GET /favicon.ico HTTP/1.1" 404 2718
[19/Dec/2018 16:27:29] "GET / HTTP/1.1" 200 685
[19/Dec/2018 16:27:30] "GET /static/css/index.css HTTP/1.1" 200 638
Not Found: /favicon.ico
[19/Dec/2018 16:27:30] "GET /favicon.ico HTTP/1.1" 404 2718
[19/Dec/2018 16:27:36] "GET /list HTTP/1.1" 200 1700
[19/Dec/2018 16:27:36] "GET /static/css/list.css HTTP/1.1" 200 1171
[19/Dec/2018 16:27:36] "GET /static/js/list.js HTTP/1.1" 200 619
Not Found: /logo_upc.png
[19/Dec/2018 16:27:37] "GET /logo_upc.png HTTP/1.1" 404 2721
[19/Dec/2018 16:27:37] "GET /static/css/general.css HTTP/1.1" 200 1635
[19/Dec/2018 16:30:09] "GET / HTTP/1.1" 200 685
[19/Dec/2018 16:30:09] "GET /static/css/index.css HTTP/1.1" 200 592
Not Found: /favicon.ico
[19/Dec/2018 16:30:09] "GET /favicon.ico HTTP/1.1" 404 2718
[19/Dec/2018 16:30:17] "GET / HTTP/1.1" 200 685
[19/Dec/2018 16:30:17] "GET /static/css/index.css HTTP/1.1" 200 592
Not Found: /favicon.ico
[19/Dec/2018 16:30:17] "GET /favicon.ico HTTP/1.1" 404 2718
[19/Dec/2018 16:30:29] "GET / HTTP/1.1" 200 685
[19/Dec/2018 16:30:29] "GET /static/css/index.css HTTP/1.1" 200 592
Not Found: /favicon.ico
[19/Dec/2018 16:30:29] "GET /favicon.ico HTTP/1.1" 404 2718
[19/Dec/2018 16:30:38] "GET / HTTP/1.1" 200 685
[19/Dec/2018 16:30:39] "GET /static/css/index.css HTTP/1.1" 200 592
Not Found: /favicon.ico
[19/Dec/2018 16:30:39] "GET /favicon.ico HTTP/1.1" 404 2718
[19/Dec/2018 16:30:51] "GET / HTTP/1.1" 200 685
[19/Dec/2018 16:30:51] "GET /static/css/index.css HTTP/1.1" 200 611
Not Found: /favicon.ico
[19/Dec/2018 16:30:52] "GET /favicon.ico HTTP/1.1" 404 2718
[19/Dec/2018 16:31:16] "GET / HTTP/1.1" 200 685
[19/Dec/2018 16:31:17] "GET /static/css/index.css HTTP/1.1" 200 625
Not Found: /favicon.ico
[19/Dec/2018 16:31:17] "GET /favicon.ico HTTP/1.1" 404 2718
[19/Dec/2018 16:31:28] "GET / HTTP/1.1" 200 685
[19/Dec/2018 16:31:29] "GET /static/css/index.css HTTP/1.1" 200 651
Not Found: /favicon.ico
[19/Dec/2018 16:31:29] "GET /favicon.ico HTTP/1.1" 404 2718
[19/Dec/2018 16:33:17] "GET / HTTP/1.1" 200 685
[19/Dec/2018 16:33:17] "GET /static/css/index.css HTTP/1.1" 200 689
Not Found: /favicon.ico
[19/Dec/2018 16:33:17] "GET /favicon.ico HTTP/1.1" 404 2718
[19/Dec/2018 16:34:14] "GET / HTTP/1.1" 200 685
[19/Dec/2018 16:34:15] "GET /static/css/index.css HTTP/1.1" 200 710
Not Found: /favicon.ico
[19/Dec/2018 16:34:15] "GET /favicon.ico HTTP/1.1" 404 2718
[19/Dec/2018 16:36:02] "GET / HTTP/1.1" 200 685
[19/Dec/2018 16:36:03] "GET /static/css/index.css HTTP/1.1" 200 731
Not Found: /favicon.ico
[19/Dec/2018 16:36:03] "GET /favicon.ico HTTP/1.1" 404 2718
[19/Dec/2018 16:36:16] "GET / HTTP/1.1" 200 685
[19/Dec/2018 16:36:16] "GET /static/css/index.css HTTP/1.1" 200 731
Not Found: /favicon.ico
[19/Dec/2018 16:36:17] "GET /favicon.ico HTTP/1.1" 404 2718
[19/Dec/2018 16:36:39] "GET / HTTP/1.1" 200 685
[19/Dec/2018 16:36:39] "GET /static/css/index.css HTTP/1.1" 200 752
Not Found: /favicon.ico
[19/Dec/2018 16:36:39] "GET /favicon.ico HTTP/1.1" 404 2718
[19/Dec/2018 16:37:42] "GET / HTTP/1.1" 200 685
[19/Dec/2018 16:37:43] "GET /static/css/index.css HTTP/1.1" 200 752
Not Found: /favicon.ico
[19/Dec/2018 16:37:43] "GET /favicon.ico HTTP/1.1" 404 2718
[19/Dec/2018 16:37:55] "GET / HTTP/1.1" 200 685
[19/Dec/2018 16:37:55] "GET /static/css/index.css HTTP/1.1" 200 751
Not Found: /favicon.ico
[19/Dec/2018 16:37:56] "GET /favicon.ico HTTP/1.1" 404 2718
[19/Dec/2018 16:38:25] "GET / HTTP/1.1" 200 685
[19/Dec/2018 16:38:25] "GET /static/css/index.css HTTP/1.1" 200 777
Not Found: /favicon.ico
[19/Dec/2018 16:38:26] "GET /favicon.ico HTTP/1.1" 404 2718
[19/Dec/2018 16:39:42] "GET / HTTP/1.1" 200 685
[19/Dec/2018 16:39:42] "GET /static/css/index.css HTTP/1.1" 200 779
Not Found: /favicon.ico
[19/Dec/2018 16:39:42] "GET /favicon.ico HTTP/1.1" 404 2718
[19/Dec/2018 16:42:01] "GET / HTTP/1.1" 200 685
[19/Dec/2018 16:42:01] "GET /static/css/index.css HTTP/1.1" 200 782
Not Found: /favicon.ico
[19/Dec/2018 16:42:02] "GET /favicon.ico HTTP/1.1" 404 2718
[19/Dec/2018 16:42:30] "GET / HTTP/1.1" 200 685
[19/Dec/2018 16:42:30] "GET /static/css/index.css HTTP/1.1" 200 758
Not Found: /favicon.ico
[19/Dec/2018 16:42:30] "GET /favicon.ico HTTP/1.1" 404 2718
[19/Dec/2018 16:42:51] "GET / HTTP/1.1" 200 685
[19/Dec/2018 16:42:51] "GET /static/css/index.css HTTP/1.1" 200 779
Not Found: /favicon.ico
[19/Dec/2018 16:42:52] "GET /favicon.ico HTTP/1.1" 404 2718
[19/Dec/2018 16:42:58] "GET / HTTP/1.1" 200 685
[19/Dec/2018 16:42:58] "GET /static/css/index.css HTTP/1.1" 200 748
Not Found: /favicon.ico
[19/Dec/2018 16:42:58] "GET /favicon.ico HTTP/1.1" 404 2718
[19/Dec/2018 16:44:03] "GET / HTTP/1.1" 200 685
[19/Dec/2018 16:44:03] "GET /static/css/index.css HTTP/1.1" 200 840
Not Found: /favicon.ico
[19/Dec/2018 16:44:04] "GET /favicon.ico HTTP/1.1" 404 2718
[19/Dec/2018 16:44:18] "GET / HTTP/1.1" 200 698
[19/Dec/2018 16:44:18] "GET /static/css/index.css HTTP/1.1" 200 840
Not Found: /favicon.ico
[19/Dec/2018 16:44:18] "GET /favicon.ico HTTP/1.1" 404 2718
[19/Dec/2018 16:44:31] "GET / HTTP/1.1" 200 698
[19/Dec/2018 16:44:31] "GET /static/css/index.css HTTP/1.1" 200 839
Not Found: /favicon.ico
[19/Dec/2018 16:44:31] "GET /favicon.ico HTTP/1.1" 404 2718
[19/Dec/2018 16:44:44] "GET / HTTP/1.1" 200 698
[19/Dec/2018 16:44:44] "GET /static/css/index.css HTTP/1.1" 200 838
Not Found: /favicon.ico
[19/Dec/2018 16:44:44] "GET /favicon.ico HTTP/1.1" 404 2718
[19/Dec/2018 16:47:02] "GET / HTTP/1.1" 200 698
[19/Dec/2018 16:47:02] "GET /static/css/index.css HTTP/1.1" 200 866
Not Found: /favicon.ico
[19/Dec/2018 16:47:02] "GET /favicon.ico HTTP/1.1" 404 2718
[19/Dec/2018 16:47:07] "GET / HTTP/1.1" 200 698
[19/Dec/2018 16:47:07] "GET /static/css/index.css HTTP/1.1" 200 865
Not Found: /favicon.ico
[19/Dec/2018 16:47:08] "GET /favicon.ico HTTP/1.1" 404 2718
[19/Dec/2018 16:47:12] "GET / HTTP/1.1" 200 698
[19/Dec/2018 16:47:12] "GET /static/css/index.css HTTP/1.1" 200 866
Not Found: /favicon.ico
[19/Dec/2018 16:47:12] "GET /favicon.ico HTTP/1.1" 404 2718
[19/Dec/2018 16:49:36] "GET / HTTP/1.1" 200 698
[19/Dec/2018 16:49:36] "GET /static/css/index.css HTTP/1.1" 200 838
Not Found: /favicon.ico
[19/Dec/2018 16:49:36] "GET /favicon.ico HTTP/1.1" 404 2718
[19/Dec/2018 16:49:47] "GET / HTTP/1.1" 200 698
[19/Dec/2018 16:49:47] "GET /static/css/index.css HTTP/1.1" 200 854
Not Found: /favicon.ico
[19/Dec/2018 16:49:47] "GET /favicon.ico HTTP/1.1" 404 2718
[19/Dec/2018 16:50:03] "GET / HTTP/1.1" 200 698
[19/Dec/2018 16:50:03] "GET /static/css/index.css HTTP/1.1" 200 856
Not Found: /favicon.ico
[19/Dec/2018 16:50:04] "GET /favicon.ico HTTP/1.1" 404 2718
[19/Dec/2018 16:50:10] "GET / HTTP/1.1" 200 698
[19/Dec/2018 16:50:10] "GET /static/css/index.css HTTP/1.1" 200 856
Not Found: /favicon.ico
[19/Dec/2018 16:50:10] "GET /favicon.ico HTTP/1.1" 404 2718
[19/Dec/2018 16:50:18] "GET / HTTP/1.1" 200 698
[19/Dec/2018 16:50:18] "GET /static/css/index.css HTTP/1.1" 200 856
Not Found: /favicon.ico
[19/Dec/2018 16:50:18] "GET /favicon.ico HTTP/1.1" 404 2718
[19/Dec/2018 16:50:31] "GET / HTTP/1.1" 200 698
[19/Dec/2018 16:50:31] "GET /static/css/index.css HTTP/1.1" 200 876
Not Found: /favicon.ico
[19/Dec/2018 16:50:31] "GET /favicon.ico HTTP/1.1" 404 2718
[19/Dec/2018 16:52:32] "GET / HTTP/1.1" 200 698
[19/Dec/2018 16:52:33] "GET /static/css/index.css HTTP/1.1" 200 892
Not Found: /favicon.ico
[19/Dec/2018 16:52:33] "GET /favicon.ico HTTP/1.1" 404 2718
[19/Dec/2018 16:53:19] "GET / HTTP/1.1" 200 698
[19/Dec/2018 16:53:19] "GET /static/css/index.css HTTP/1.1" 200 933
Not Found: /favicon.ico
[19/Dec/2018 16:53:19] "GET /favicon.ico HTTP/1.1" 404 2718
[19/Dec/2018 16:53:52] "GET / HTTP/1.1" 200 698
[19/Dec/2018 16:53:52] "GET /static/css/index.css HTTP/1.1" 200 892
Not Found: /favicon.ico
[19/Dec/2018 16:53:52] "GET /favicon.ico HTTP/1.1" 404 2718
[19/Dec/2018 16:55:23] "GET / HTTP/1.1" 200 698
[19/Dec/2018 16:55:23] "GET /static/css/index.css HTTP/1.1" 200 871
Not Found: /favicon.ico
[19/Dec/2018 16:55:23] "GET /favicon.ico HTTP/1.1" 404 2718
[19/Dec/2018 16:55:30] "GET /static/css/index.css HTTP/1.1" 304 0
[19/Dec/2018 16:56:14] "GET / HTTP/1.1" 200 698
[19/Dec/2018 16:56:15] "GET /static/css/index.css HTTP/1.1" 200 906
Not Found: /favicon.ico
[19/Dec/2018 16:56:15] "GET /favicon.ico HTTP/1.1" 404 2718
[19/Dec/2018 16:56:24] "GET / HTTP/1.1" 200 698
[19/Dec/2018 16:56:24] "GET /static/css/index.css HTTP/1.1" 200 941
Not Found: /favicon.ico
[19/Dec/2018 16:56:25] "GET /favicon.ico HTTP/1.1" 404 2718
[19/Dec/2018 16:56:44] "GET / HTTP/1.1" 200 698
[19/Dec/2018 16:56:44] "GET /static/css/index.css HTTP/1.1" 200 963
Not Found: /favicon.ico
[19/Dec/2018 16:56:44] "GET /favicon.ico HTTP/1.1" 404 2718
[19/Dec/2018 16:56:46] "GET / HTTP/1.1" 200 698
[19/Dec/2018 16:56:46] "GET /static/css/index.css HTTP/1.1" 200 963
Not Found: /favicon.ico
[19/Dec/2018 16:56:46] "GET /favicon.ico HTTP/1.1" 404 2718
[19/Dec/2018 16:56:47] "GET / HTTP/1.1" 200 698
[19/Dec/2018 16:56:47] "GET /static/css/index.css HTTP/1.1" 200 963
Not Found: /favicon.ico
[19/Dec/2018 16:56:47] "GET /favicon.ico HTTP/1.1" 404 2718
[19/Dec/2018 16:56:51] "GET / HTTP/1.1" 200 698
[19/Dec/2018 16:56:51] "GET /static/css/index.css HTTP/1.1" 304 0
[19/Dec/2018 16:56:55] "GET /blog/ HTTP/1.1" 200 3857
[19/Dec/2018 16:56:55] "GET /static/css/blog.css HTTP/1.1" 304 0
[19/Dec/2018 16:56:56] "GET / HTTP/1.1" 200 698
[19/Dec/2018 16:56:57] "GET /static/css/index.css HTTP/1.1" 304 0
[19/Dec/2018 16:57:07] "GET /static/css/index.css HTTP/1.1" 304 0
[19/Dec/2018 16:57:52] "GET / HTTP/1.1" 200 698
[19/Dec/2018 16:57:53] "GET /static/css/index.css HTTP/1.1" 200 995
Not Found: /favicon.ico
[19/Dec/2018 16:57:53] "GET /favicon.ico HTTP/1.1" 404 2718
[19/Dec/2018 16:58:04] "GET / HTTP/1.1" 200 698
[19/Dec/2018 16:58:04] "GET /static/css/index.css HTTP/1.1" 200 994
Not Found: /favicon.ico
[19/Dec/2018 16:58:04] "GET /favicon.ico HTTP/1.1" 404 2718
[19/Dec/2018 16:58:27] "GET / HTTP/1.1" 200 698
[19/Dec/2018 16:58:28] "GET /static/css/index.css HTTP/1.1" 200 995
Not Found: /favicon.ico
[19/Dec/2018 16:58:28] "GET /favicon.ico HTTP/1.1" 404 2718
[19/Dec/2018 16:58:30] "GET / HTTP/1.1" 200 698
[19/Dec/2018 16:58:30] "GET /static/css/index.css HTTP/1.1" 200 995
Not Found: /favicon.ico
[19/Dec/2018 16:58:30] "GET /favicon.ico HTTP/1.1" 404 2718
[19/Dec/2018 16:58:35] "GET / HTTP/1.1" 200 698
[19/Dec/2018 16:58:35] "GET /static/css/index.css HTTP/1.1" 200 995
Not Found: /favicon.ico
[19/Dec/2018 16:58:35] "GET /favicon.ico HTTP/1.1" 404 2718
[19/Dec/2018 16:58:37] "GET /static/css/index.css HTTP/1.1" 304 0
[19/Dec/2018 16:58:56] "GET / HTTP/1.1" 200 698
[19/Dec/2018 16:58:56] "GET /static/css/index.css HTTP/1.1" 200 974
Not Found: /favicon.ico
[19/Dec/2018 16:58:57] "GET /favicon.ico HTTP/1.1" 404 2718
[19/Dec/2018 16:59:44] "GET / HTTP/1.1" 200 698
[19/Dec/2018 16:59:44] "GET /static/css/index.css HTTP/1.1" 200 970
Not Found: /favicon.ico
[19/Dec/2018 16:59:44] "GET /favicon.ico HTTP/1.1" 404 2718
[19/Dec/2018 17:00:01] "GET /list HTTP/1.1" 200 1700
[19/Dec/2018 17:00:01] "GET /static/js/list.js HTTP/1.1" 304 0
Not Found: /logo_upc.png
[19/Dec/2018 17:00:01] "GET /logo_upc.png HTTP/1.1" 404 2721
[19/Dec/2018 17:00:01] "GET /static/css/list.css HTTP/1.1" 304 0
[19/Dec/2018 17:00:18] "GET /list HTTP/1.1" 200 1700
[19/Dec/2018 17:00:18] "GET /static/css/list.css HTTP/1.1" 200 1171
[19/Dec/2018 17:00:18] "GET /static/js/list.js HTTP/1.1" 200 619
Not Found: /logo_upc.png
[19/Dec/2018 17:00:18] "GET /logo_upc.png HTTP/1.1" 404 2721
[19/Dec/2018 17:00:19] "GET /static/css/general.css HTTP/1.1" 200 1635
Not Found: /favicon.ico
[19/Dec/2018 17:00:19] "GET /favicon.ico HTTP/1.1" 404 2718
[19/Dec/2018 17:00:41] "GET / HTTP/1.1" 200 698
[19/Dec/2018 17:00:42] "GET /static/css/index.css HTTP/1.1" 304 0
[19/Dec/2018 17:01:26] "GET / HTTP/1.1" 200 698
[19/Dec/2018 17:01:27] "GET /static/css/index.css HTTP/1.1" 200 943
Not Found: /favicon.ico
[19/Dec/2018 17:01:27] "GET /favicon.ico HTTP/1.1" 404 2718
[19/Dec/2018 17:01:39] "GET / HTTP/1.1" 200 698
[19/Dec/2018 17:01:39] "GET /static/css/index.css HTTP/1.1" 200 971
Not Found: /favicon.ico
[19/Dec/2018 17:01:39] "GET /favicon.ico HTTP/1.1" 404 2718
[19/Dec/2018 17:02:00] "GET / HTTP/1.1" 200 698
[19/Dec/2018 17:02:01] "GET /static/css/index.css HTTP/1.1" 200 971
Not Found: /favicon.ico
[19/Dec/2018 17:02:01] "GET /favicon.ico HTTP/1.1" 404 2718
[19/Dec/2018 17:02:35] "GET /static/css/index.css HTTP/1.1" 200 874
[19/Dec/2018 17:03:40] "GET / HTTP/1.1" 200 698
[19/Dec/2018 17:03:40] "GET /static/css/index.css HTTP/1.1" 200 875
Not Found: /favicon.ico
[19/Dec/2018 17:03:41] "GET /favicon.ico HTTP/1.1" 404 2718
[19/Dec/2018 17:03:46] "GET / HTTP/1.1" 200 698
[19/Dec/2018 17:03:46] "GET /static/css/index.css HTTP/1.1" 200 875
Not Found: /favicon.ico
[19/Dec/2018 17:03:46] "GET /favicon.ico HTTP/1.1" 404 2718
[19/Dec/2018 17:03:53] "GET / HTTP/1.1" 200 698
[19/Dec/2018 17:03:53] "GET /static/css/index.css HTTP/1.1" 200 874
Not Found: /favicon.ico
[19/Dec/2018 17:03:53] "GET /favicon.ico HTTP/1.1" 404 2718
[19/Dec/2018 17:04:03] "GET / HTTP/1.1" 200 698
[19/Dec/2018 17:04:03] "GET /static/css/index.css HTTP/1.1" 200 853
Not Found: /favicon.ico
[19/Dec/2018 17:04:03] "GET /favicon.ico HTTP/1.1" 404 2718
[19/Dec/2018 17:04:05] "GET / HTTP/1.1" 200 698
[19/Dec/2018 17:04:05] "GET /static/css/index.css HTTP/1.1" 200 853
Not Found: /favicon.ico
[19/Dec/2018 17:04:05] "GET /favicon.ico HTTP/1.1" 404 2718
[19/Dec/2018 17:06:00] "GET / HTTP/1.1" 200 698
[19/Dec/2018 17:06:00] "GET /static/css/index.css HTTP/1.1" 200 894
Not Found: /favicon.ico
[19/Dec/2018 17:06:00] "GET /favicon.ico HTTP/1.1" 404 2718
[19/Dec/2018 17:06:05] "GET /static/css/index.css HTTP/1.1" 304 0
[19/Dec/2018 17:06:55] "GET / HTTP/1.1" 200 698
[19/Dec/2018 17:06:55] "GET /static/css/index.css HTTP/1.1" 200 920
Not Found: /favicon.ico
[19/Dec/2018 17:06:55] "GET /favicon.ico HTTP/1.1" 404 2718
[19/Dec/2018 17:07:07] "GET / HTTP/1.1" 200 698
[19/Dec/2018 17:07:07] "GET /static/css/index.css HTTP/1.1" 200 919
Not Found: /favicon.ico
[19/Dec/2018 17:07:08] "GET /favicon.ico HTTP/1.1" 404 2718
[19/Dec/2018 17:07:12] "GET / HTTP/1.1" 200 698
[19/Dec/2018 17:07:12] "GET /static/css/index.css HTTP/1.1" 200 920
Not Found: /favicon.ico
[19/Dec/2018 17:07:13] "GET /favicon.ico HTTP/1.1" 404 2718
[19/Dec/2018 17:07:22] "GET /static/css/index.css HTTP/1.1" 304 0
[19/Dec/2018 17:07:57] "GET / HTTP/1.1" 200 698
[19/Dec/2018 17:07:57] "GET /static/css/index.css HTTP/1.1" 200 939
Not Found: /favicon.ico
[19/Dec/2018 17:07:57] "GET /favicon.ico HTTP/1.1" 404 2718
[19/Dec/2018 17:08:14] "GET / HTTP/1.1" 200 698
[19/Dec/2018 17:08:14] "GET /static/css/index.css HTTP/1.1" 200 960
Not Found: /favicon.ico
[19/Dec/2018 17:08:14] "GET /favicon.ico HTTP/1.1" 404 2718
[19/Dec/2018 17:08:23] "GET / HTTP/1.1" 200 698
[19/Dec/2018 17:08:23] "GET /static/css/index.css HTTP/1.1" 200 978
Not Found: /favicon.ico
[19/Dec/2018 17:08:23] "GET /favicon.ico HTTP/1.1" 404 2718
[19/Dec/2018 17:10:57] "GET / HTTP/1.1" 200 698
[19/Dec/2018 17:10:57] "GET /static/css/index.css HTTP/1.1" 200 979
Not Found: /favicon.ico
[19/Dec/2018 17:10:57] "GET /favicon.ico HTTP/1.1" 404 2718
[19/Dec/2018 17:11:19] "GET / HTTP/1.1" 200 699
[19/Dec/2018 17:11:20] "GET /static/css/index.css HTTP/1.1" 200 979
Not Found: /favicon.ico
[19/Dec/2018 17:11:20] "GET /favicon.ico HTTP/1.1" 404 2718
[19/Dec/2018 17:18:19] "GET / HTTP/1.1" 200 699
[19/Dec/2018 17:18:20] "GET /static/css/index.css HTTP/1.1" 200 979
Not Found: /favicon.ico
[19/Dec/2018 17:18:20] "GET /favicon.ico HTTP/1.1" 404 2718
[19/Dec/2018 17:21:55] "GET / HTTP/1.1" 200 743
[19/Dec/2018 17:21:55] "GET /static/css/index.css HTTP/1.1" 200 979
Not Found: /favicon.ico
[19/Dec/2018 17:21:55] "GET /favicon.ico HTTP/1.1" 404 2718
[19/Dec/2018 17:22:18] "GET / HTTP/1.1" 200 743
[19/Dec/2018 17:22:18] "GET /static/css/index.css HTTP/1.1" 200 979
Not Found: /favicon.ico
[19/Dec/2018 17:22:18] "GET /favicon.ico HTTP/1.1" 404 2718
[19/Dec/2018 17:23:58] "GET / HTTP/1.1" 200 783
[19/Dec/2018 17:23:58] "GET /static/css/index.css HTTP/1.1" 200 979
Not Found: /favicon.ico
[19/Dec/2018 17:23:58] "GET /favicon.ico HTTP/1.1" 404 2718
[19/Dec/2018 17:24:21] "GET / HTTP/1.1" 200 783
[19/Dec/2018 17:24:21] "GET /static/css/index.css HTTP/1.1" 200 979
Not Found: /favicon.ico
[19/Dec/2018 17:24:21] "GET /favicon.ico HTTP/1.1" 404 2718
[19/Dec/2018 17:24:23] "GET /list HTTP/1.1" 200 1700
[19/Dec/2018 17:24:23] "GET /static/js/list.js HTTP/1.1" 304 0
Not Found: /logo_upc.png
[19/Dec/2018 17:24:23] "GET /logo_upc.png HTTP/1.1" 404 2721
[19/Dec/2018 17:24:23] "GET /static/css/list.css HTTP/1.1" 304 0
[19/Dec/2018 17:31:08] "GET / HTTP/1.1" 200 783
[19/Dec/2018 17:31:08] "GET /static/css/index.css HTTP/1.1" 200 978
Not Found: /favicon.ico
[19/Dec/2018 17:31:09] "GET /favicon.ico HTTP/1.1" 404 2718
[19/Dec/2018 17:31:18] "GET /static/css/index.css HTTP/1.1" 304 0
[19/Dec/2018 17:31:39] "GET / HTTP/1.1" 200 783
[19/Dec/2018 17:31:39] "GET /static/css/index.css HTTP/1.1" 200 939
Not Found: /favicon.ico
[19/Dec/2018 17:31:39] "GET /favicon.ico HTTP/1.1" 404 2718
[19/Dec/2018 17:31:59] "GET / HTTP/1.1" 200 783
[19/Dec/2018 17:31:59] "GET /static/css/index.css HTTP/1.1" 200 944
Not Found: /favicon.ico
[19/Dec/2018 17:31:59] "GET /favicon.ico HTTP/1.1" 404 2718
[19/Dec/2018 17:32:12] "GET / HTTP/1.1" 200 783
[19/Dec/2018 17:32:12] "GET /static/css/index.css HTTP/1.1" 200 965
Not Found: /favicon.ico
[19/Dec/2018 17:32:13] "GET /favicon.ico HTTP/1.1" 404 2718
[19/Dec/2018 17:32:22] "GET / HTTP/1.1" 200 783
[19/Dec/2018 17:32:22] "GET /static/css/index.css HTTP/1.1" 200 966
Not Found: /favicon.ico
[19/Dec/2018 17:32:23] "GET /favicon.ico HTTP/1.1" 404 2718
[19/Dec/2018 17:32:30] "GET / HTTP/1.1" 200 783
[19/Dec/2018 17:32:30] "GET /static/css/index.css HTTP/1.1" 200 985
Not Found: /favicon.ico
[19/Dec/2018 17:32:30] "GET /favicon.ico HTTP/1.1" 404 2718
[19/Dec/2018 17:33:01] "GET / HTTP/1.1" 200 783
[19/Dec/2018 17:33:01] "GET /static/css/index.css HTTP/1.1" 200 964
Not Found: /favicon.ico
[19/Dec/2018 17:33:01] "GET /favicon.ico HTTP/1.1" 404 2718
[19/Dec/2018 17:33:56] "GET / HTTP/1.1" 200 783
[19/Dec/2018 17:33:56] "GET /static/css/index.css HTTP/1.1" 200 965
Not Found: /favicon.ico
[19/Dec/2018 17:33:56] "GET /favicon.ico HTTP/1.1" 404 2718
[19/Dec/2018 17:34:12] "GET / HTTP/1.1" 200 783
[19/Dec/2018 17:34:12] "GET /static/css/index.css HTTP/1.1" 200 962
Not Found: /favicon.ico
[19/Dec/2018 17:34:12] "GET /favicon.ico HTTP/1.1" 404 2718
[19/Dec/2018 17:34:22] "GET / HTTP/1.1" 200 783
[19/Dec/2018 17:34:23] "GET /static/css/index.css HTTP/1.1" 200 964
Not Found: /favicon.ico
[19/Dec/2018 17:34:23] "GET /favicon.ico HTTP/1.1" 404 2718
[19/Dec/2018 17:34:52] "GET / HTTP/1.1" 200 783
[19/Dec/2018 17:34:53] "GET /static/css/index.css HTTP/1.1" 200 965
Not Found: /favicon.ico
[19/Dec/2018 17:34:53] "GET /favicon.ico HTTP/1.1" 404 2718
[19/Dec/2018 17:35:26] "GET / HTTP/1.1" 200 783
[19/Dec/2018 17:35:27] "GET /static/css/index.css HTTP/1.1" 200 965
Not Found: /favicon.ico
[19/Dec/2018 17:35:27] "GET /favicon.ico HTTP/1.1" 404 2718
[19/Dec/2018 17:37:23] "GET / HTTP/1.1" 200 986
[19/Dec/2018 17:37:23] "GET /static/css/index.css HTTP/1.1" 200 965
Not Found: /favicon.ico
[19/Dec/2018 17:37:23] "GET /favicon.ico HTTP/1.1" 404 2718
[19/Dec/2018 17:39:00] "GET / HTTP/1.1" 200 1099
[19/Dec/2018 17:39:00] "GET /static/css/index.css HTTP/1.1" 200 965
Not Found: /favicon.ico
[19/Dec/2018 17:39:01] "GET /favicon.ico HTTP/1.1" 404 2718
[19/Dec/2018 17:39:13] "GET / HTTP/1.1" 200 1094
[19/Dec/2018 17:39:13] "GET /static/css/index.css HTTP/1.1" 200 965
Not Found: /favicon.ico
[19/Dec/2018 17:39:14] "GET /favicon.ico HTTP/1.1" 404 2718
[19/Dec/2018 17:39:22] "GET / HTTP/1.1" 200 1099
[19/Dec/2018 17:39:22] "GET /static/css/index.css HTTP/1.1" 200 965
Not Found: /favicon.ico
[19/Dec/2018 17:39:22] "GET /favicon.ico HTTP/1.1" 404 2718
[19/Dec/2018 17:39:28] "GET / HTTP/1.1" 200 1103
[19/Dec/2018 17:39:28] "GET /static/css/index.css HTTP/1.1" 200 965
Not Found: /favicon.ico
[19/Dec/2018 17:39:28] "GET /favicon.ico HTTP/1.1" 404 2718
[19/Dec/2018 17:39:47] "GET / HTTP/1.1" 200 1115
[19/Dec/2018 17:39:47] "GET /static/css/index.css HTTP/1.1" 200 965
Not Found: /favicon.ico
[19/Dec/2018 17:39:47] "GET /favicon.ico HTTP/1.1" 404 2718
[19/Dec/2018 17:39:55] "GET / HTTP/1.1" 200 1119
[19/Dec/2018 17:39:56] "GET /static/css/index.css HTTP/1.1" 200 965
Not Found: /favicon.ico
[19/Dec/2018 17:39:56] "GET /favicon.ico HTTP/1.1" 404 2718
[19/Dec/2018 17:40:05] "GET / HTTP/1.1" 200 1132
[19/Dec/2018 17:40:05] "GET /static/css/index.css HTTP/1.1" 200 965
Not Found: /favicon.ico
[19/Dec/2018 17:40:05] "GET /favicon.ico HTTP/1.1" 404 2718
[19/Dec/2018 17:40:10] "GET / HTTP/1.1" 200 1119
[19/Dec/2018 17:40:10] "GET /static/css/index.css HTTP/1.1" 200 965
Not Found: /favicon.ico
[19/Dec/2018 17:40:10] "GET /favicon.ico HTTP/1.1" 404 2718
[19/Dec/2018 17:40:24] "GET / HTTP/1.1" 200 1145
[19/Dec/2018 17:40:24] "GET /static/css/index.css HTTP/1.1" 200 965
Not Found: /favicon.ico
[19/Dec/2018 17:40:24] "GET /favicon.ico HTTP/1.1" 404 2718
[19/Dec/2018 17:42:29] "GET / HTTP/1.1" 200 1134
[19/Dec/2018 17:42:29] "GET /static/css/index.css HTTP/1.1" 200 965
Not Found: /favicon.ico
[19/Dec/2018 17:42:29] "GET /favicon.ico HTTP/1.1" 404 2718
[19/Dec/2018 17:43:56] "GET / HTTP/1.1" 200 1172
[19/Dec/2018 17:43:56] "GET /static/css/index.css HTTP/1.1" 200 965
Not Found: /favicon.ico
[19/Dec/2018 17:43:56] "GET /favicon.ico HTTP/1.1" 404 2718
[19/Dec/2018 17:48:04] "GET / HTTP/1.1" 200 1264
[19/Dec/2018 17:48:04] "GET /static/css/index.css HTTP/1.1" 200 965
Not Found: /favicon.ico
[19/Dec/2018 17:48:05] "GET /favicon.ico HTTP/1.1" 404 2718
[19/Dec/2018 17:49:21] "GET / HTTP/1.1" 200 1266
[19/Dec/2018 17:49:21] "GET /static/css/index.css HTTP/1.1" 200 965
Not Found: /favicon.ico
[19/Dec/2018 17:49:21] "GET /favicon.ico HTTP/1.1" 404 2718
[19/Dec/2018 17:50:34] "GET / HTTP/1.1" 200 1266
[19/Dec/2018 17:50:34] "GET /static/css/index.css HTTP/1.1" 200 986
Not Found: /favicon.ico
[19/Dec/2018 17:50:34] "GET /favicon.ico HTTP/1.1" 404 2718
[19/Dec/2018 17:53:01] "GET / HTTP/1.1" 200 1524
[19/Dec/2018 17:53:01] "GET /static/css/index.css HTTP/1.1" 200 986
Not Found: /favicon.ico
[19/Dec/2018 17:53:01] "GET /favicon.ico HTTP/1.1" 404 2718
[19/Dec/2018 17:53:30] "GET / HTTP/1.1" 200 1524
[19/Dec/2018 17:53:31] "GET /static/css/index.css HTTP/1.1" 200 1015
Not Found: /favicon.ico
[19/Dec/2018 17:53:31] "GET /favicon.ico HTTP/1.1" 404 2718
[19/Dec/2018 17:56:25] "GET / HTTP/1.1" 200 1524
[19/Dec/2018 17:56:25] "GET /static/css/index.css HTTP/1.1" 200 1071
Not Found: /favicon.ico
[19/Dec/2018 17:56:25] "GET /favicon.ico HTTP/1.1" 404 2718
[19/Dec/2018 17:56:43] "GET / HTTP/1.1" 200 1524
[19/Dec/2018 17:56:44] "GET /static/css/index.css HTTP/1.1" 200 1108
Not Found: /favicon.ico
[19/Dec/2018 17:56:44] "GET /favicon.ico HTTP/1.1" 404 2718
[19/Dec/2018 17:56:46] "GET / HTTP/1.1" 200 1524
[19/Dec/2018 17:56:46] "GET / HTTP/1.1" 200 1524
[19/Dec/2018 17:56:46] "GET / HTTP/1.1" 200 1524
[19/Dec/2018 17:56:46] "GET /static/css/index.css HTTP/1.1" 200 1108
Not Found: /favicon.ico
[19/Dec/2018 17:56:46] "GET /favicon.ico HTTP/1.1" 404 2718
[19/Dec/2018 17:56:51] "GET / HTTP/1.1" 200 1524
[19/Dec/2018 17:56:51] "GET /static/css/index.css HTTP/1.1" 200 1108
Not Found: /favicon.ico
[19/Dec/2018 17:56:51] "GET /favicon.ico HTTP/1.1" 404 2718
[19/Dec/2018 17:57:12] "GET / HTTP/1.1" 200 1524
[19/Dec/2018 17:57:12] "GET /static/css/index.css HTTP/1.1" 200 1110
Not Found: /favicon.ico
[19/Dec/2018 17:57:12] "GET /favicon.ico HTTP/1.1" 404 2718
[19/Dec/2018 17:57:22] "GET / HTTP/1.1" 200 1524
[19/Dec/2018 17:57:22] "GET /static/css/index.css HTTP/1.1" 200 1110
Not Found: /favicon.ico
[19/Dec/2018 17:57:22] "GET /favicon.ico HTTP/1.1" 404 2718
[19/Dec/2018 17:57:36] "GET / HTTP/1.1" 200 1524
[19/Dec/2018 17:57:36] "GET /static/css/index.css HTTP/1.1" 200 1129
Not Found: /favicon.ico
[19/Dec/2018 17:57:36] "GET /favicon.ico HTTP/1.1" 404 2718
[19/Dec/2018 17:57:38] "GET / HTTP/1.1" 200 1524
[19/Dec/2018 17:57:38] "GET /static/css/index.css HTTP/1.1" 200 1129
Not Found: /favicon.ico
[19/Dec/2018 17:57:38] "GET /favicon.ico HTTP/1.1" 404 2718
[19/Dec/2018 17:57:45] "GET / HTTP/1.1" 200 1524
[19/Dec/2018 17:57:46] "GET /static/css/index.css HTTP/1.1" 200 1129
Not Found: /favicon.ico
[19/Dec/2018 17:57:46] "GET /favicon.ico HTTP/1.1" 404 2718
[19/Dec/2018 17:58:04] "GET / HTTP/1.1" 200 1524
[19/Dec/2018 17:58:04] "GET /static/css/index.css HTTP/1.1" 200 1107
Not Found: /favicon.ico
[19/Dec/2018 17:58:04] "GET /favicon.ico HTTP/1.1" 404 2718
[19/Dec/2018 17:58:06] "GET / HTTP/1.1" 200 1524
[19/Dec/2018 17:58:06] "GET /static/css/index.css HTTP/1.1" 200 1107
Not Found: /favicon.ico
[19/Dec/2018 17:58:06] "GET /favicon.ico HTTP/1.1" 404 2718
[19/Dec/2018 17:58:11] "GET / HTTP/1.1" 200 1524
[19/Dec/2018 17:58:12] "GET /static/css/index.css HTTP/1.1" 200 1107
Not Found: /favicon.ico
[19/Dec/2018 17:58:12] "GET /favicon.ico HTTP/1.1" 404 2718
[19/Dec/2018 17:58:15] "GET /static/css/index.css HTTP/1.1" 304 0
[19/Dec/2018 17:58:40] "GET / HTTP/1.1" 200 1524
[19/Dec/2018 17:58:40] "GET /static/css/index.css HTTP/1.1" 200 1108
Not Found: /favicon.ico
[19/Dec/2018 17:58:40] "GET /favicon.ico HTTP/1.1" 404 2718
[19/Dec/2018 17:58:51] "GET / HTTP/1.1" 200 1524
[19/Dec/2018 17:58:51] "GET /static/css/index.css HTTP/1.1" 200 1108
Not Found: /favicon.ico
[19/Dec/2018 17:58:52] "GET /favicon.ico HTTP/1.1" 404 2718
[19/Dec/2018 17:59:15] "GET / HTTP/1.1" 200 1524
[19/Dec/2018 17:59:16] "GET /static/css/index.css HTTP/1.1" 200 1109
Not Found: /favicon.ico
[19/Dec/2018 17:59:16] "GET /favicon.ico HTTP/1.1" 404 2718
[19/Dec/2018 17:59:47] "GET / HTTP/1.1" 200 1524
[19/Dec/2018 17:59:47] "GET /static/css/index.css HTTP/1.1" 200 1131
Not Found: /favicon.ico
[19/Dec/2018 17:59:47] "GET /favicon.ico HTTP/1.1" 404 2718
[19/Dec/2018 18:01:38] "GET / HTTP/1.1" 200 1524
[19/Dec/2018 18:01:38] "GET /static/css/index.css HTTP/1.1" 200 1135
Not Found: /favicon.ico
[19/Dec/2018 18:01:38] "GET /favicon.ico HTTP/1.1" 404 2718
[19/Dec/2018 18:01:45] "GET /static/css/index.css HTTP/1.1" 304 0
[19/Dec/2018 18:02:24] "GET / HTTP/1.1" 200 1524
[19/Dec/2018 18:02:25] "GET /static/css/index.css HTTP/1.1" 200 1126
Not Found: /favicon.ico
[19/Dec/2018 18:02:25] "GET /favicon.ico HTTP/1.1" 404 2718
[19/Dec/2018 18:02:45] "GET / HTTP/1.1" 200 1524
[19/Dec/2018 18:02:45] "GET /static/css/index.css HTTP/1.1" 200 1147
Not Found: /favicon.ico
[19/Dec/2018 18:02:45] "GET /favicon.ico HTTP/1.1" 404 2718
[19/Dec/2018 18:10:56] "GET / HTTP/1.1" 200 1838
[19/Dec/2018 18:10:56] "GET /static/css/index.css HTTP/1.1" 200 1147
Not Found: /favicon.ico
[19/Dec/2018 18:10:56] "GET /favicon.ico HTTP/1.1" 404 2718
[19/Dec/2018 18:11:29] "GET / HTTP/1.1" 200 1838
[19/Dec/2018 18:11:29] "GET /static/css/index.css HTTP/1.1" 200 1113
Not Found: /favicon.ico
[19/Dec/2018 18:11:29] "GET /favicon.ico HTTP/1.1" 404 2718
[19/Dec/2018 18:11:40] "GET / HTTP/1.1" 200 1838
[19/Dec/2018 18:11:41] "GET /static/css/index.css HTTP/1.1" 200 1133
Not Found: /favicon.ico
[19/Dec/2018 18:11:41] "GET /favicon.ico HTTP/1.1" 404 2718
[19/Dec/2018 18:11:46] "GET / HTTP/1.1" 200 1838
[19/Dec/2018 18:11:46] "GET /static/css/index.css HTTP/1.1" 200 1133
Not Found: /favicon.ico
[19/Dec/2018 18:11:46] "GET /favicon.ico HTTP/1.1" 404 2718
[19/Dec/2018 18:11:52] "GET / HTTP/1.1" 200 1838
[19/Dec/2018 18:11:52] "GET /static/css/index.css HTTP/1.1" 200 1133
Not Found: /favicon.ico
[19/Dec/2018 18:11:53] "GET /favicon.ico HTTP/1.1" 404 2718
[19/Dec/2018 18:12:26] "GET /static/css/index.css HTTP/1.1" 304 0
[19/Dec/2018 18:13:16] "GET / HTTP/1.1" 200 1838
[19/Dec/2018 18:13:17] "GET /static/css/index.css HTTP/1.1" 200 1154
Not Found: /favicon.ico
[19/Dec/2018 18:13:17] "GET /favicon.ico HTTP/1.1" 404 2718
[19/Dec/2018 18:13:58] "GET /static/css/index.css HTTP/1.1" 304 0
[19/Dec/2018 18:15:51] "GET / HTTP/1.1" 200 1838
[19/Dec/2018 18:15:51] "GET /static/css/index.css HTTP/1.1" 200 1154
Not Found: /favicon.ico
[19/Dec/2018 18:15:51] "GET /favicon.ico HTTP/1.1" 404 2718
[19/Dec/2018 18:16:10] "GET /list HTTP/1.1" 200 1700
[19/Dec/2018 18:16:10] "GET /static/css/list.css HTTP/1.1" 304 0
[19/Dec/2018 18:16:10] "GET /static/js/list.js HTTP/1.1" 304 0
Not Found: /logo_upc.png
[19/Dec/2018 18:16:11] "GET /logo_upc.png HTTP/1.1" 404 2721
[19/Dec/2018 18:16:11] "GET /static/css/general.css HTTP/1.1" 304 0
[19/Dec/2018 18:17:48] "GET / HTTP/1.1" 200 1838
[19/Dec/2018 18:17:48] "GET /static/css/index.css HTTP/1.1" 304 0
[19/Dec/2018 18:18:19] "GET / HTTP/1.1" 200 1838
[19/Dec/2018 18:18:19] "GET /static/css/index.css HTTP/1.1" 200 1169
Not Found: /favicon.ico
[19/Dec/2018 18:18:19] "GET /favicon.ico HTTP/1.1" 404 2718
[19/Dec/2018 18:18:27] "GET /list HTTP/1.1" 200 1700
Not Found: /logo_upc.png
[19/Dec/2018 18:18:27] "GET /logo_upc.png HTTP/1.1" 404 2721
[19/Dec/2018 18:18:43] "GET / HTTP/1.1" 200 1838
[19/Dec/2018 18:18:43] "GET /static/css/index.css HTTP/1.1" 200 1182
Not Found: /favicon.ico
[19/Dec/2018 18:18:43] "GET /favicon.ico HTTP/1.1" 404 2718
[19/Dec/2018 18:18:44] "GET /create HTTP/1.1" 200 1649
Not Found: /logo_upc.png
[19/Dec/2018 18:18:45] "GET /logo_upc.png HTTP/1.1" 404 2721
[19/Dec/2018 18:18:45] "GET /static/js/create.js HTTP/1.1" 304 0
[19/Dec/2018 18:18:48] "GET / HTTP/1.1" 200 1838
[19/Dec/2018 18:18:48] "GET /static/css/index.css HTTP/1.1" 200 1182
Not Found: /favicon.ico
[19/Dec/2018 18:18:49] "GET /favicon.ico HTTP/1.1" 404 2718
[19/Dec/2018 18:19:17] "GET / HTTP/1.1" 200 1838
[19/Dec/2018 18:19:17] "GET /static/css/index.css HTTP/1.1" 200 1223
Not Found: /favicon.ico
[19/Dec/2018 18:19:17] "GET /favicon.ico HTTP/1.1" 404 2718
[19/Dec/2018 18:19:19] "GET / HTTP/1.1" 200 1838
[19/Dec/2018 18:19:19] "GET /static/css/index.css HTTP/1.1" 200 1223
Not Found: /favicon.ico
[19/Dec/2018 18:19:19] "GET /favicon.ico HTTP/1.1" 404 2718
[19/Dec/2018 18:19:36] "GET / HTTP/1.1" 200 1838
[19/Dec/2018 18:19:37] "GET /static/css/index.css HTTP/1.1" 200 1221
Not Found: /favicon.ico
[19/Dec/2018 18:19:37] "GET /favicon.ico HTTP/1.1" 404 2718
[19/Dec/2018 18:19:46] "GET / HTTP/1.1" 200 1838
[19/Dec/2018 18:19:46] "GET /static/css/index.css HTTP/1.1" 200 1223
Not Found: /favicon.ico
[19/Dec/2018 18:19:46] "GET /favicon.ico HTTP/1.1" 404 2718
[19/Dec/2018 18:19:54] "GET / HTTP/1.1" 200 1838
[19/Dec/2018 18:19:54] "GET /static/css/index.css HTTP/1.1" 200 1215
Not Found: /favicon.ico
[19/Dec/2018 18:19:54] "GET /favicon.ico HTTP/1.1" 404 2718
[19/Dec/2018 18:20:03] "GET / HTTP/1.1" 200 1838
[19/Dec/2018 18:20:03] "GET /static/css/index.css HTTP/1.1" 200 1195
Not Found: /favicon.ico
[19/Dec/2018 18:20:03] "GET /favicon.ico HTTP/1.1" 404 2718
[19/Dec/2018 18:20:15] "GET / HTTP/1.1" 200 1838
[19/Dec/2018 18:20:16] "GET /static/css/index.css HTTP/1.1" 200 1224
Not Found: /favicon.ico
[19/Dec/2018 18:20:16] "GET /favicon.ico HTTP/1.1" 404 2718
[19/Dec/2018 18:20:22] "GET / HTTP/1.1" 200 1838
[19/Dec/2018 18:20:23] "GET /static/css/index.css HTTP/1.1" 200 1223
Not Found: /favicon.ico
[19/Dec/2018 18:20:23] "GET /favicon.ico HTTP/1.1" 404 2718
[19/Dec/2018 18:20:38] "GET /list HTTP/1.1" 200 1700
Not Found: /logo_upc.png
[19/Dec/2018 18:20:38] "GET /logo_upc.png HTTP/1.1" 404 2721
[19/Dec/2018 18:21:19] "GET /t/200 HTTP/1.1" 200 996
Not Found: /t/logo_upc.png
[19/Dec/2018 18:21:20] "GET /t/logo_upc.png HTTP/1.1" 404 2727
[19/Dec/2018 18:21:21] "GET /create HTTP/1.1" 200 1649
Not Found: /logo_upc.png
[19/Dec/2018 18:21:22] "GET /logo_upc.png HTTP/1.1" 404 2721
Not Found: /t/logo_upc.png
[19/Dec/2018 18:21:25] "GET /t/logo_upc.png HTTP/1.1" 404 2727
Not Found: /logo_upc.png
[19/Dec/2018 18:21:27] "GET /logo_upc.png HTTP/1.1" 404 2721
[19/Dec/2018 18:24:40] "GET /list HTTP/1.1" 200 1700
[19/Dec/2018 18:24:41] "GET /static/css/list.css HTTP/1.1" 200 1184
[19/Dec/2018 18:24:41] "GET /static/js/list.js HTTP/1.1" 200 619
Not Found: /logo_upc.png
[19/Dec/2018 18:24:41] "GET /logo_upc.png HTTP/1.1" 404 2721
[19/Dec/2018 18:24:41] "GET /static/css/general.css HTTP/1.1" 200 1635
Not Found: /favicon.ico
[19/Dec/2018 18:24:41] "GET /favicon.ico HTTP/1.1" 404 2718
[19/Dec/2018 18:25:10] "GET /list HTTP/1.1" 200 1700
[19/Dec/2018 18:25:10] "GET /static/css/list.css HTTP/1.1" 200 1184
[19/Dec/2018 18:25:10] "GET /static/js/list.js HTTP/1.1" 200 619
Not Found: /logo_upc.png
[19/Dec/2018 18:25:10] "GET /logo_upc.png HTTP/1.1" 404 2721
[19/Dec/2018 18:25:10] "GET /static/css/general.css HTTP/1.1" 200 1635
Not Found: /favicon.ico
[19/Dec/2018 18:25:10] "GET /favicon.ico HTTP/1.1" 404 2718
[19/Dec/2018 18:25:18] "GET /list HTTP/1.1" 200 1700
[19/Dec/2018 18:25:18] "GET /static/js/list.js HTTP/1.1" 200 619
[19/Dec/2018 18:25:18] "GET /static/css/list.css HTTP/1.1" 200 1184
Not Found: /logo_upc.png
[19/Dec/2018 18:25:18] "GET /logo_upc.png HTTP/1.1" 404 2721
[19/Dec/2018 18:25:18] "GET /static/css/general.css HTTP/1.1" 200 1635
Not Found: /favicon.ico
[19/Dec/2018 18:25:19] "GET /favicon.ico HTTP/1.1" 404 2718
[19/Dec/2018 18:26:07] "GET /list HTTP/1.1" 200 1700
[19/Dec/2018 18:26:07] "GET /static/css/list.css HTTP/1.1" 200 1202
[19/Dec/2018 18:26:07] "GET /static/js/list.js HTTP/1.1" 200 619
Not Found: /logo_upc.png
[19/Dec/2018 18:26:07] "GET /logo_upc.png HTTP/1.1" 404 2721
[19/Dec/2018 18:26:07] "GET /static/css/general.css HTTP/1.1" 200 1635
Not Found: /favicon.ico
[19/Dec/2018 18:26:07] "GET /favicon.ico HTTP/1.1" 404 2718
[19/Dec/2018 18:26:24] "GET /list HTTP/1.1" 200 1700
[19/Dec/2018 18:26:24] "GET /static/css/list.css HTTP/1.1" 200 1220
[19/Dec/2018 18:26:24] "GET /static/js/list.js HTTP/1.1" 200 619
Not Found: /logo_upc.png
[19/Dec/2018 18:26:24] "GET /logo_upc.png HTTP/1.1" 404 2721
[19/Dec/2018 18:26:24] "GET /static/css/general.css HTTP/1.1" 200 1635
Not Found: /favicon.ico
[19/Dec/2018 18:26:24] "GET /favicon.ico HTTP/1.1" 404 2718
[19/Dec/2018 18:26:29] "GET /list HTTP/1.1" 200 1700
[19/Dec/2018 18:26:30] "GET /static/css/list.css HTTP/1.1" 200 1220
[19/Dec/2018 18:26:30] "GET /static/js/list.js HTTP/1.1" 200 619
Not Found: /logo_upc.png
[19/Dec/2018 18:26:30] "GET /logo_upc.png HTTP/1.1" 404 2721
[19/Dec/2018 18:26:30] "GET /static/css/general.css HTTP/1.1" 200 1635
Not Found: /favicon.ico
[19/Dec/2018 18:26:30] "GET /favicon.ico HTTP/1.1" 404 2718
[19/Dec/2018 18:26:39] "GET /list HTTP/1.1" 200 1700
[19/Dec/2018 18:26:39] "GET /static/css/list.css HTTP/1.1" 200 1220
[19/Dec/2018 18:26:39] "GET /static/js/list.js HTTP/1.1" 200 619
Not Found: /logo_upc.png
[19/Dec/2018 18:26:39] "GET /logo_upc.png HTTP/1.1" 404 2721
[19/Dec/2018 18:26:39] "GET /static/css/general.css HTTP/1.1" 200 1635
Not Found: /favicon.ico
[19/Dec/2018 18:26:40] "GET /favicon.ico HTTP/1.1" 404 2718
[19/Dec/2018 18:26:48] "GET /list HTTP/1.1" 200 1700
[19/Dec/2018 18:26:48] "GET /static/js/list.js HTTP/1.1" 200 619
[19/Dec/2018 18:26:48] "GET /static/css/list.css HTTP/1.1" 200 1220
Not Found: /logo_upc.png
[19/Dec/2018 18:26:48] "GET /logo_upc.png HTTP/1.1" 404 2721
[19/Dec/2018 18:26:48] "GET /static/css/general.css HTTP/1.1" 200 1635
Not Found: /favicon.ico
[19/Dec/2018 18:26:49] "GET /favicon.ico HTTP/1.1" 404 2718
[19/Dec/2018 18:26:56] "GET /list HTTP/1.1" 200 1700
[19/Dec/2018 18:26:56] "GET /static/js/list.js HTTP/1.1" 200 619
[19/Dec/2018 18:26:56] "GET /static/css/list.css HTTP/1.1" 200 1220
Not Found: /logo_upc.png
[19/Dec/2018 18:26:56] "GET /logo_upc.png HTTP/1.1" 404 2721
[19/Dec/2018 18:26:56] "GET /static/css/general.css HTTP/1.1" 200 1635
Not Found: /favicon.ico
[19/Dec/2018 18:26:56] "GET /favicon.ico HTTP/1.1" 404 2718
[19/Dec/2018 18:27:02] "GET /list HTTP/1.1" 200 1700
[19/Dec/2018 18:27:02] "GET /static/css/general.css HTTP/1.1" 200 1635
[19/Dec/2018 18:27:02] "GET /static/css/list.css HTTP/1.1" 200 1221
[19/Dec/2018 18:27:02] "GET /static/js/list.js HTTP/1.1" 200 619
Not Found: /logo_upc.png
[19/Dec/2018 18:27:02] "GET /logo_upc.png HTTP/1.1" 404 2721
Not Found: /favicon.ico
[19/Dec/2018 18:27:03] "GET /favicon.ico HTTP/1.1" 404 2718
[19/Dec/2018 18:27:12] "GET /list HTTP/1.1" 200 1700
[19/Dec/2018 18:27:13] "GET /static/css/general.css HTTP/1.1" 200 1635
[19/Dec/2018 18:27:13] "GET /static/css/list.css HTTP/1.1" 200 1221
[19/Dec/2018 18:27:13] "GET /static/js/list.js HTTP/1.1" 200 619
Not Found: /logo_upc.png
[19/Dec/2018 18:27:13] "GET /logo_upc.png HTTP/1.1" 404 2721
Not Found: /favicon.ico
[19/Dec/2018 18:27:13] "GET /favicon.ico HTTP/1.1" 404 2718
[19/Dec/2018 18:27:48] "GET /list HTTP/1.1" 200 1700
[19/Dec/2018 18:27:48] "GET /static/css/list.css HTTP/1.1" 200 1289
[19/Dec/2018 18:27:48] "GET /static/js/list.js HTTP/1.1" 200 619
Not Found: /logo_upc.png
[19/Dec/2018 18:27:48] "GET /logo_upc.png HTTP/1.1" 404 2721
[19/Dec/2018 18:27:49] "GET /static/css/general.css HTTP/1.1" 200 1635
Not Found: /favicon.ico
[19/Dec/2018 18:27:49] "GET /favicon.ico HTTP/1.1" 404 2718
[19/Dec/2018 18:38:30] "GET /list HTTP/1.1" 200 1712
[19/Dec/2018 18:38:30] "GET /static/css/list.css HTTP/1.1" 200 1289
[19/Dec/2018 18:38:30] "GET /static/js/list.js HTTP/1.1" 200 619
[19/Dec/2018 18:38:31] "GET /static/css/general.css HTTP/1.1" 200 1635
Not Found: /favicon.ico
[19/Dec/2018 18:38:31] "GET /favicon.ico HTTP/1.1" 404 2718
[19/Dec/2018 18:39:24] "GET /list HTTP/1.1" 200 1712
[19/Dec/2018 18:39:24] "GET /static/css/list.css HTTP/1.1" 200 1289
[19/Dec/2018 18:39:24] "GET /static/js/list.js HTTP/1.1" 200 619
[19/Dec/2018 18:39:24] "GET /static/css/general.css HTTP/1.1" 200 1637
Not Found: /favicon.ico
[19/Dec/2018 18:39:24] "GET /favicon.ico HTTP/1.1" 404 2718
[19/Dec/2018 18:40:22] "GET /list HTTP/1.1" 200 1807
[19/Dec/2018 18:40:23] "GET /static/css/list.css HTTP/1.1" 200 1289
[19/Dec/2018 18:40:23] "GET /static/css/general.css HTTP/1.1" 200 1637
[19/Dec/2018 18:40:23] "GET /static/js/list.js HTTP/1.1" 200 619
Not Found: /favicon.ico
[19/Dec/2018 18:40:23] "GET /favicon.ico HTTP/1.1" 404 2718
[19/Dec/2018 18:40:32] "GET /create HTTP/1.1" 200 1756
[19/Dec/2018 18:40:32] "GET /static/css/general.css HTTP/1.1" 304 0
[19/Dec/2018 18:40:39] "GET /list HTTP/1.1" 200 1800
[19/Dec/2018 18:40:39] "GET /static/js/list.js HTTP/1.1" 200 619
[19/Dec/2018 18:40:39] "GET /static/css/list.css HTTP/1.1" 200 1289
[19/Dec/2018 18:40:40] "GET /static/css/general.css HTTP/1.1" 200 1637
Not Found: /favicon.ico
[19/Dec/2018 18:40:40] "GET /favicon.ico HTTP/1.1" 404 2718
[19/Dec/2018 18:40:57] "GET /create HTTP/1.1" 200 1749
[19/Dec/2018 18:40:57] "GET /static/css/general.css HTTP/1.1" 304 0
[19/Dec/2018 18:40:59] "GET /list HTTP/1.1" 200 1800
[19/Dec/2018 18:41:01] "GET /blog/ HTTP/1.1" 200 3857
[19/Dec/2018 18:41:03] "GET / HTTP/1.1" 200 1838
[19/Dec/2018 18:41:04] "GET /static/css/index.css HTTP/1.1" 304 0
[19/Dec/2018 18:41:06] "GET /list HTTP/1.1" 200 1800
[19/Dec/2018 18:41:06] "GET /static/css/general.css HTTP/1.1" 304 0
[19/Dec/2018 18:41:16] "GET /create HTTP/1.1" 200 1749
[19/Dec/2018 18:41:16] "GET /static/css/general.css HTTP/1.1" 304 0
[19/Dec/2018 18:41:18] "GET /list HTTP/1.1" 200 1800
[19/Dec/2018 18:41:19] "GET / HTTP/1.1" 200 1838
[19/Dec/2018 18:41:22] "GET /blog/ HTTP/1.1" 200 3857
[19/Dec/2018 18:41:24] "GET / HTTP/1.1" 200 1838
[19/Dec/2018 18:41:26] "GET /list HTTP/1.1" 200 1800
[19/Dec/2018 18:41:26] "GET /static/css/general.css HTTP/1.1" 304 0
[19/Dec/2018 18:41:27] "GET /create HTTP/1.1" 200 1749
[20/Dec/2018 08:49:30] "GET / HTTP/1.1" 200 1838
[20/Dec/2018 08:49:30] "GET /static/css/index.css HTTP/1.1" 200 1223
Not Found: /favicon.ico
[20/Dec/2018 08:49:30] "GET /favicon.ico HTTP/1.1" 404 2718
Not Found: /favicon.ico
[20/Dec/2018 08:49:30] "GET /favicon.ico HTTP/1.1" 404 2718
[20/Dec/2018 08:49:58] "GET /create HTTP/1.1" 200 1749
[20/Dec/2018 08:49:58] "GET /static/js/create.js HTTP/1.1" 200 1422
[20/Dec/2018 08:49:58] "GET /static/css/general.css HTTP/1.1" 200 1637
Forbidden (CSRF cookie not set.): /create
[20/Dec/2018 08:50:32] "POST /create HTTP/1.1" 403 2868
[20/Dec/2018 08:50:43] "GET /list HTTP/1.1" 200 1800
[20/Dec/2018 08:50:43] "GET /static/js/list.js HTTP/1.1" 200 619
[20/Dec/2018 08:50:43] "GET /static/css/list.css HTTP/1.1" 200 1289
[20/Dec/2018 08:50:48] "GET /t/1 HTTP/1.1" 200 1096
[20/Dec/2018 08:50:50] "GET /create HTTP/1.1" 200 1749
[20/Dec/2018 08:50:52] "GET / HTTP/1.1" 200 1838
[20/Dec/2018 08:50:56] "GET /blog/ HTTP/1.1" 200 3857
[20/Dec/2018 08:50:56] "GET /static/css/blog.css HTTP/1.1" 200 1353
[20/Dec/2018 08:51:07] "GET /blog/2018/12/16/testing-daimoni-api-25h/ HTTP/1.1" 200 2794
[20/Dec/2018 08:51:49] "GET /list HTTP/1.1" 200 1800
[20/Dec/2018 08:51:50] "GET /t/200 HTTP/1.1" 200 1096
[20/Dec/2018 08:51:53] "GET / HTTP/1.1" 200 1838
[20/Dec/2018 08:51:57] "GET /create HTTP/1.1" 200 1749
[20/Dec/2018 08:51:59] "GET /list HTTP/1.1" 200 1800
[20/Dec/2018 08:52:02] "GET /create HTTP/1.1" 200 1749
[20/Dec/2018 08:52:07] "GET / HTTP/1.1" 200 1838
[20/Dec/2018 08:52:11] "GET /blog/ HTTP/1.1" 200 3857
[20/Dec/2018 08:52:26] "GET /blog/2018/12/05/api-acces-dades/ HTTP/1.1" 200 2758
[2018-12-20 09:46:28,947 pyinotify ERROR] The pathname '/home/pi/tfg/django/tornejos/project/application/views.py' of this watch <Watch wd=1085 path=/home/pi/tfg/django/tornejos/project/application/views.py mask=4038 proc_fun=None auto_add=False exclude_filter=<function WatchManager.<lambda> at 0xb65c96a8> dir=False > has probably changed and couldn't be updated, so it cannot be trusted anymore. To fix this error move directories/files only between watched parents directories, in this case e.g. put a watch on '/home/pi/tfg/django/tornejos/project/application'.
Performing system checks...

System check identified no issues (0 silenced).
December 19, 2018 - 14:52:38
Django version 2.1.3, using settings 'project.settings'
Starting development server at http://127.0.0.1:8000/
Quit the server with CONTROL-C.
Unhandled exception in thread started by <function check_errors.<locals>.wrapper at 0xb5ae6b70>
Traceback (most recent call last):
  File "/home/pi/.local/lib/python3.5/site-packages/django/utils/autoreload.py", line 225, in wrapper
    fn(*args, **kwargs)
  File "/home/pi/.local/lib/python3.5/site-packages/django/core/management/commands/runserver.py", line 117, in inner_run
    self.check(display_num_errors=True)
  File "/home/pi/.local/lib/python3.5/site-packages/django/core/management/base.py", line 379, in check
    include_deployment_checks=include_deployment_checks,
  File "/home/pi/.local/lib/python3.5/site-packages/django/core/management/base.py", line 366, in _run_checks
    return checks.run_checks(**kwargs)
  File "/home/pi/.local/lib/python3.5/site-packages/django/core/checks/registry.py", line 71, in run_checks
    new_errors = check(app_configs=app_configs)
  File "/home/pi/.local/lib/python3.5/site-packages/django/core/checks/urls.py", line 40, in check_url_namespaces_unique
    all_namespaces = _load_all_namespaces(resolver)
  File "/home/pi/.local/lib/python3.5/site-packages/django/core/checks/urls.py", line 57, in _load_all_namespaces
    url_patterns = getattr(resolver, 'url_patterns', [])
  File "/home/pi/.local/lib/python3.5/site-packages/django/utils/functional.py", line 37, in __get__
    res = instance.__dict__[self.name] = self.func(instance)
  File "/home/pi/.local/lib/python3.5/site-packages/django/urls/resolvers.py", line 533, in url_patterns
    patterns = getattr(self.urlconf_module, "urlpatterns", self.urlconf_module)
  File "/home/pi/.local/lib/python3.5/site-packages/django/utils/functional.py", line 37, in __get__
    res = instance.__dict__[self.name] = self.func(instance)
  File "/home/pi/.local/lib/python3.5/site-packages/django/urls/resolvers.py", line 526, in urlconf_module
    return import_module(self.urlconf_name)
  File "/usr/lib/python3.5/importlib/__init__.py", line 126, in import_module
    return _bootstrap._gcd_import(name[level:], package, level)
  File "<frozen importlib._bootstrap>", line 986, in _gcd_import
  File "<frozen importlib._bootstrap>", line 969, in _find_and_load
  File "<frozen importlib._bootstrap>", line 958, in _find_and_load_unlocked
  File "<frozen importlib._bootstrap>", line 673, in _load_unlocked
  File "<frozen importlib._bootstrap_external>", line 673, in exec_module
  File "<frozen importlib._bootstrap>", line 222, in _call_with_frames_removed
  File "/home/pi/tfg/django/tornejos/project/urls.py", line 20, in <module>
    from project.application.views import test, create_tournament, display_tournament, list_tournaments
  File "/home/pi/tfg/django/tornejos/project/application/views.py", line 29
    result_data = client.recv()
    ^
IndentationError: unexpected indent
[2018-12-20 09:56:45,669 pyinotify ERROR] The pathname '/home/pi/tfg/django/tornejos/project/application/views.py' of this watch <Watch wd=1013 path=/home/pi/tfg/django/tornejos/project/application/views.py mask=4038 proc_fun=None auto_add=False exclude_filter=<function WatchManager.<lambda> at 0xb669f6a8> dir=False > has probably changed and couldn't be updated, so it cannot be trusted anymore. To fix this error move directories/files only between watched parents directories, in this case e.g. put a watch on '/home/pi/tfg/django/tornejos/project/application'.
Performing system checks...

Unhandled exception in thread started by <function check_errors.<locals>.wrapper at 0xb5aa3b70>
Traceback (most recent call last):
  File "/home/pi/.local/lib/python3.5/site-packages/django/utils/autoreload.py", line 225, in wrapper
    fn(*args, **kwargs)
  File "/home/pi/.local/lib/python3.5/site-packages/django/core/management/commands/runserver.py", line 117, in inner_run
    self.check(display_num_errors=True)
  File "/home/pi/.local/lib/python3.5/site-packages/django/core/management/base.py", line 379, in check
    include_deployment_checks=include_deployment_checks,
  File "/home/pi/.local/lib/python3.5/site-packages/django/core/management/base.py", line 366, in _run_checks
    return checks.run_checks(**kwargs)
  File "/home/pi/.local/lib/python3.5/site-packages/django/core/checks/registry.py", line 71, in run_checks
    new_errors = check(app_configs=app_configs)
  File "/home/pi/.local/lib/python3.5/site-packages/django/core/checks/urls.py", line 40, in check_url_namespaces_unique
    all_namespaces = _load_all_namespaces(resolver)
  File "/home/pi/.local/lib/python3.5/site-packages/django/core/checks/urls.py", line 57, in _load_all_namespaces
    url_patterns = getattr(resolver, 'url_patterns', [])
  File "/home/pi/.local/lib/python3.5/site-packages/django/utils/functional.py", line 37, in __get__
    res = instance.__dict__[self.name] = self.func(instance)
  File "/home/pi/.local/lib/python3.5/site-packages/django/urls/resolvers.py", line 533, in url_patterns
    patterns = getattr(self.urlconf_module, "urlpatterns", self.urlconf_module)
  File "/home/pi/.local/lib/python3.5/site-packages/django/utils/functional.py", line 37, in __get__
    res = instance.__dict__[self.name] = self.func(instance)
  File "/home/pi/.local/lib/python3.5/site-packages/django/urls/resolvers.py", line 526, in urlconf_module
    return import_module(self.urlconf_name)
  File "/usr/lib/python3.5/importlib/__init__.py", line 126, in import_module
    return _bootstrap._gcd_import(name[level:], package, level)
  File "<frozen importlib._bootstrap>", line 986, in _gcd_import
  File "<frozen importlib._bootstrap>", line 969, in _find_and_load
  File "<frozen importlib._bootstrap>", line 958, in _find_and_load_unlocked
  File "<frozen importlib._bootstrap>", line 673, in _load_unlocked
  File "<frozen importlib._bootstrap_external>", line 673, in exec_module
  File "<frozen importlib._bootstrap>", line 222, in _call_with_frames_removed
  File "/home/pi/tfg/django/tornejos/project/urls.py", line 20, in <module>
    from project.application.views import test, create_tournament, display_tournament, list_tournaments
  File "/home/pi/tfg/django/tornejos/project/application/views.py", line 39
    result_data = client.recv()
    ^
IndentationError: unexpected indent
[2018-12-20 09:59:47,060 pyinotify ERROR] The pathname '/home/pi/tfg/django/tornejos/project/settings.py' of this watch <Watch wd=121 path=/home/pi/tfg/django/tornejos/project/settings.py mask=4038 proc_fun=None auto_add=False exclude_filter=<function WatchManager.<lambda> at 0xb665c6a8> dir=False > has probably changed and couldn't be updated, so it cannot be trusted anymore. To fix this error move directories/files only between watched parents directories, in this case e.g. put a watch on '/home/pi/tfg/django/tornejos/project'.
Performing system checks...

Unhandled exception in thread started by <function check_errors.<locals>.wrapper at 0xb5abfbb8>
Traceback (most recent call last):
  File "/home/pi/.local/lib/python3.5/site-packages/django/utils/autoreload.py", line 225, in wrapper
    fn(*args, **kwargs)
  File "/home/pi/.local/lib/python3.5/site-packages/django/core/management/commands/runserver.py", line 117, in inner_run
    self.check(display_num_errors=True)
  File "/home/pi/.local/lib/python3.5/site-packages/django/core/management/base.py", line 379, in check
    include_deployment_checks=include_deployment_checks,
  File "/home/pi/.local/lib/python3.5/site-packages/django/core/management/base.py", line 366, in _run_checks
    return checks.run_checks(**kwargs)
  File "/home/pi/.local/lib/python3.5/site-packages/django/core/checks/registry.py", line 71, in run_checks
    new_errors = check(app_configs=app_configs)
  File "/home/pi/.local/lib/python3.5/site-packages/django/core/checks/urls.py", line 40, in check_url_namespaces_unique
    all_namespaces = _load_all_namespaces(resolver)
  File "/home/pi/.local/lib/python3.5/site-packages/django/core/checks/urls.py", line 57, in _load_all_namespaces
    url_patterns = getattr(resolver, 'url_patterns', [])
  File "/home/pi/.local/lib/python3.5/site-packages/django/utils/functional.py", line 37, in __get__
    res = instance.__dict__[self.name] = self.func(instance)
  File "/home/pi/.local/lib/python3.5/site-packages/django/urls/resolvers.py", line 533, in url_patterns
    patterns = getattr(self.urlconf_module, "urlpatterns", self.urlconf_module)
  File "/home/pi/.local/lib/python3.5/site-packages/django/utils/functional.py", line 37, in __get__
    res = instance.__dict__[self.name] = self.func(instance)
  File "/home/pi/.local/lib/python3.5/site-packages/django/urls/resolvers.py", line 526, in urlconf_module
    return import_module(self.urlconf_name)
  File "/usr/lib/python3.5/importlib/__init__.py", line 126, in import_module
    return _bootstrap._gcd_import(name[level:], package, level)
  File "<frozen importlib._bootstrap>", line 986, in _gcd_import
  File "<frozen importlib._bootstrap>", line 969, in _find_and_load
  File "<frozen importlib._bootstrap>", line 958, in _find_and_load_unlocked
  File "<frozen importlib._bootstrap>", line 673, in _load_unlocked
  File "<frozen importlib._bootstrap_external>", line 673, in exec_module
  File "<frozen importlib._bootstrap>", line 222, in _call_with_frames_removed
  File "/home/pi/tfg/django/tornejos/project/urls.py", line 20, in <module>
    from project.application.views import test, create_tournament, display_tournament, list_tournaments
  File "/home/pi/tfg/django/tornejos/project/application/views.py", line 39
    result_data = client.recv()
    ^
IndentationError: unexpected indent
[2018-12-20 10:41:01,056 pyinotify ERROR] The pathname '/home/pi/tfg/django/tornejos/project/application/views.py' of this watch <Watch wd=1013 path=/home/pi/tfg/django/tornejos/project/application/views.py mask=4038 proc_fun=None auto_add=False exclude_filter=<function WatchManager.<lambda> at 0xb66756a8> dir=False > has probably changed and couldn't be updated, so it cannot be trusted anymore. To fix this error move directories/files only between watched parents directories, in this case e.g. put a watch on '/home/pi/tfg/django/tornejos/project/application'.
Performing system checks...

Unhandled exception in thread started by <function check_errors.<locals>.wrapper at 0xb5a53bb8>
Traceback (most recent call last):
  File "/home/pi/.local/lib/python3.5/site-packages/django/utils/autoreload.py", line 225, in wrapper
    fn(*args, **kwargs)
  File "/home/pi/.local/lib/python3.5/site-packages/django/core/management/commands/runserver.py", line 117, in inner_run
    self.check(display_num_errors=True)
  File "/home/pi/.local/lib/python3.5/site-packages/django/core/management/base.py", line 379, in check
    include_deployment_checks=include_deployment_checks,
  File "/home/pi/.local/lib/python3.5/site-packages/django/core/management/base.py", line 366, in _run_checks
    return checks.run_checks(**kwargs)
  File "/home/pi/.local/lib/python3.5/site-packages/django/core/checks/registry.py", line 71, in run_checks
    new_errors = check(app_configs=app_configs)
  File "/home/pi/.local/lib/python3.5/site-packages/django/core/checks/urls.py", line 40, in check_url_namespaces_unique
    all_namespaces = _load_all_namespaces(resolver)
  File "/home/pi/.local/lib/python3.5/site-packages/django/core/checks/urls.py", line 57, in _load_all_namespaces
    url_patterns = getattr(resolver, 'url_patterns', [])
  File "/home/pi/.local/lib/python3.5/site-packages/django/utils/functional.py", line 37, in __get__
    res = instance.__dict__[self.name] = self.func(instance)
  File "/home/pi/.local/lib/python3.5/site-packages/django/urls/resolvers.py", line 533, in url_patterns
    patterns = getattr(self.urlconf_module, "urlpatterns", self.urlconf_module)
  File "/home/pi/.local/lib/python3.5/site-packages/django/utils/functional.py", line 37, in __get__
    res = instance.__dict__[self.name] = self.func(instance)
  File "/home/pi/.local/lib/python3.5/site-packages/django/urls/resolvers.py", line 526, in urlconf_module
    return import_module(self.urlconf_name)
  File "/usr/lib/python3.5/importlib/__init__.py", line 126, in import_module
    return _bootstrap._gcd_import(name[level:], package, level)
  File "<frozen importlib._bootstrap>", line 986, in _gcd_import
  File "<frozen importlib._bootstrap>", line 969, in _find_and_load
  File "<frozen importlib._bootstrap>", line 958, in _find_and_load_unlocked
  File "<frozen importlib._bootstrap>", line 673, in _load_unlocked
  File "<frozen importlib._bootstrap_external>", line 673, in exec_module
  File "<frozen importlib._bootstrap>", line 222, in _call_with_frames_removed
  File "/home/pi/tfg/django/tornejos/project/urls.py", line 20, in <module>
    from project.application.views import test, create_tournament, display_tournament, list_tournaments
  File "/home/pi/tfg/django/tornejos/project/application/views.py", line 41
    result_data = client.recv()
    ^
IndentationError: unexpected indent
[2018-12-20 10:42:36,016 pyinotify ERROR] The pathname '/home/pi/tfg/django/tornejos/project/application/views.py' of this watch <Watch wd=1013 path=/home/pi/tfg/django/tornejos/project/application/views.py mask=4038 proc_fun=None auto_add=False exclude_filter=<function WatchManager.<lambda> at 0xb66006a8> dir=False > has probably changed and couldn't be updated, so it cannot be trusted anymore. To fix this error move directories/files only between watched parents directories, in this case e.g. put a watch on '/home/pi/tfg/django/tornejos/project/application'.
Performing system checks...

Unhandled exception in thread started by <function check_errors.<locals>.wrapper at 0xb5b12bb8>
Traceback (most recent call last):
  File "/home/pi/.local/lib/python3.5/site-packages/django/utils/autoreload.py", line 225, in wrapper
    fn(*args, **kwargs)
  File "/home/pi/.local/lib/python3.5/site-packages/django/core/management/commands/runserver.py", line 117, in inner_run
    self.check(display_num_errors=True)
  File "/home/pi/.local/lib/python3.5/site-packages/django/core/management/base.py", line 379, in check
    include_deployment_checks=include_deployment_checks,
  File "/home/pi/.local/lib/python3.5/site-packages/django/core/management/base.py", line 366, in _run_checks
    return checks.run_checks(**kwargs)
  File "/home/pi/.local/lib/python3.5/site-packages/django/core/checks/registry.py", line 71, in run_checks
    new_errors = check(app_configs=app_configs)
  File "/home/pi/.local/lib/python3.5/site-packages/django/core/checks/urls.py", line 40, in check_url_namespaces_unique
    all_namespaces = _load_all_namespaces(resolver)
  File "/home/pi/.local/lib/python3.5/site-packages/django/core/checks/urls.py", line 57, in _load_all_namespaces
    url_patterns = getattr(resolver, 'url_patterns', [])
  File "/home/pi/.local/lib/python3.5/site-packages/django/utils/functional.py", line 37, in __get__
    res = instance.__dict__[self.name] = self.func(instance)
  File "/home/pi/.local/lib/python3.5/site-packages/django/urls/resolvers.py", line 533, in url_patterns
    patterns = getattr(self.urlconf_module, "urlpatterns", self.urlconf_module)
  File "/home/pi/.local/lib/python3.5/site-packages/django/utils/functional.py", line 37, in __get__
    res = instance.__dict__[self.name] = self.func(instance)
  File "/home/pi/.local/lib/python3.5/site-packages/django/urls/resolvers.py", line 526, in urlconf_module
    return import_module(self.urlconf_name)
  File "/usr/lib/python3.5/importlib/__init__.py", line 126, in import_module
    return _bootstrap._gcd_import(name[level:], package, level)
  File "<frozen importlib._bootstrap>", line 986, in _gcd_import
  File "<frozen importlib._bootstrap>", line 969, in _find_and_load
  File "<frozen importlib._bootstrap>", line 958, in _find_and_load_unlocked
  File "<frozen importlib._bootstrap>", line 673, in _load_unlocked
  File "<frozen importlib._bootstrap_external>", line 673, in exec_module
  File "<frozen importlib._bootstrap>", line 222, in _call_with_frames_removed
  File "/home/pi/tfg/django/tornejos/project/urls.py", line 20, in <module>
    from project.application.views import test, create_tournament, display_tournament, list_tournaments
  File "/home/pi/tfg/django/tornejos/project/application/views.py", line 41
    result_data = client.recv()
    ^
IndentationError: unexpected indent
[2018-12-20 10:43:28,358 pyinotify ERROR] The pathname '/home/pi/tfg/django/tornejos/project/application/views.py' of this watch <Watch wd=1013 path=/home/pi/tfg/django/tornejos/project/application/views.py mask=4038 proc_fun=None auto_add=False exclude_filter=<function WatchManager.<lambda> at 0xb66bf6a8> dir=False > has probably changed and couldn't be updated, so it cannot be trusted anymore. To fix this error move directories/files only between watched parents directories, in this case e.g. put a watch on '/home/pi/tfg/django/tornejos/project/application'.
Performing system checks...

Unhandled exception in thread started by <function check_errors.<locals>.wrapper at 0xb5a4dbb8>
Traceback (most recent call last):
  File "/home/pi/.local/lib/python3.5/site-packages/django/utils/autoreload.py", line 225, in wrapper
    fn(*args, **kwargs)
  File "/home/pi/.local/lib/python3.5/site-packages/django/core/management/commands/runserver.py", line 117, in inner_run
    self.check(display_num_errors=True)
  File "/home/pi/.local/lib/python3.5/site-packages/django/core/management/base.py", line 379, in check
    include_deployment_checks=include_deployment_checks,
  File "/home/pi/.local/lib/python3.5/site-packages/django/core/management/base.py", line 366, in _run_checks
    return checks.run_checks(**kwargs)
  File "/home/pi/.local/lib/python3.5/site-packages/django/core/checks/registry.py", line 71, in run_checks
    new_errors = check(app_configs=app_configs)
  File "/home/pi/.local/lib/python3.5/site-packages/django/core/checks/urls.py", line 40, in check_url_namespaces_unique
    all_namespaces = _load_all_namespaces(resolver)
  File "/home/pi/.local/lib/python3.5/site-packages/django/core/checks/urls.py", line 57, in _load_all_namespaces
    url_patterns = getattr(resolver, 'url_patterns', [])
  File "/home/pi/.local/lib/python3.5/site-packages/django/utils/functional.py", line 37, in __get__
    res = instance.__dict__[self.name] = self.func(instance)
  File "/home/pi/.local/lib/python3.5/site-packages/django/urls/resolvers.py", line 533, in url_patterns
    patterns = getattr(self.urlconf_module, "urlpatterns", self.urlconf_module)
  File "/home/pi/.local/lib/python3.5/site-packages/django/utils/functional.py", line 37, in __get__
    res = instance.__dict__[self.name] = self.func(instance)
  File "/home/pi/.local/lib/python3.5/site-packages/django/urls/resolvers.py", line 526, in urlconf_module
    return import_module(self.urlconf_name)
  File "/usr/lib/python3.5/importlib/__init__.py", line 126, in import_module
    return _bootstrap._gcd_import(name[level:], package, level)
  File "<frozen importlib._bootstrap>", line 986, in _gcd_import
  File "<frozen importlib._bootstrap>", line 969, in _find_and_load
  File "<frozen importlib._bootstrap>", line 958, in _find_and_load_unlocked
  File "<frozen importlib._bootstrap>", line 673, in _load_unlocked
  File "<frozen importlib._bootstrap_external>", line 673, in exec_module
  File "<frozen importlib._bootstrap>", line 222, in _call_with_frames_removed
  File "/home/pi/tfg/django/tornejos/project/urls.py", line 20, in <module>
    from project.application.views import test, create_tournament, display_tournament, list_tournaments
  File "/home/pi/tfg/django/tornejos/project/application/views.py", line 44
    result_data = client.recv()
    ^
IndentationError: unexpected indent
[2018-12-20 12:10:05,506 pyinotify ERROR] The pathname '/home/pi/tfg/django/tornejos/project/application/views.py' of this watch <Watch wd=1013 path=/home/pi/tfg/django/tornejos/project/application/views.py mask=4038 proc_fun=None auto_add=False exclude_filter=<function WatchManager.<lambda> at 0xb65fa6a8> dir=False > has probably changed and couldn't be updated, so it cannot be trusted anymore. To fix this error move directories/files only between watched parents directories, in this case e.g. put a watch on '/home/pi/tfg/django/tornejos/project/application'.
Performing system checks...

Unhandled exception in thread started by <function check_errors.<locals>.wrapper at 0xb5a26bb8>
Traceback (most recent call last):
  File "/home/pi/.local/lib/python3.5/site-packages/django/utils/autoreload.py", line 225, in wrapper
    fn(*args, **kwargs)
  File "/home/pi/.local/lib/python3.5/site-packages/django/core/management/commands/runserver.py", line 117, in inner_run
    self.check(display_num_errors=True)
  File "/home/pi/.local/lib/python3.5/site-packages/django/core/management/base.py", line 379, in check
    include_deployment_checks=include_deployment_checks,
  File "/home/pi/.local/lib/python3.5/site-packages/django/core/management/base.py", line 366, in _run_checks
    return checks.run_checks(**kwargs)
  File "/home/pi/.local/lib/python3.5/site-packages/django/core/checks/registry.py", line 71, in run_checks
    new_errors = check(app_configs=app_configs)
  File "/home/pi/.local/lib/python3.5/site-packages/django/core/checks/urls.py", line 40, in check_url_namespaces_unique
    all_namespaces = _load_all_namespaces(resolver)
  File "/home/pi/.local/lib/python3.5/site-packages/django/core/checks/urls.py", line 57, in _load_all_namespaces
    url_patterns = getattr(resolver, 'url_patterns', [])
  File "/home/pi/.local/lib/python3.5/site-packages/django/utils/functional.py", line 37, in __get__
    res = instance.__dict__[self.name] = self.func(instance)
  File "/home/pi/.local/lib/python3.5/site-packages/django/urls/resolvers.py", line 533, in url_patterns
    patterns = getattr(self.urlconf_module, "urlpatterns", self.urlconf_module)
  File "/home/pi/.local/lib/python3.5/site-packages/django/utils/functional.py", line 37, in __get__
    res = instance.__dict__[self.name] = self.func(instance)
  File "/home/pi/.local/lib/python3.5/site-packages/django/urls/resolvers.py", line 526, in urlconf_module
    return import_module(self.urlconf_name)
  File "/usr/lib/python3.5/importlib/__init__.py", line 126, in import_module
    return _bootstrap._gcd_import(name[level:], package, level)
  File "<frozen importlib._bootstrap>", line 986, in _gcd_import
  File "<frozen importlib._bootstrap>", line 969, in _find_and_load
  File "<frozen importlib._bootstrap>", line 958, in _find_and_load_unlocked
  File "<frozen importlib._bootstrap>", line 673, in _load_unlocked
  File "<frozen importlib._bootstrap_external>", line 673, in exec_module
  File "<frozen importlib._bootstrap>", line 222, in _call_with_frames_removed
  File "/home/pi/tfg/django/tornejos/project/urls.py", line 20, in <module>
    from project.application.views import test, create_tournament, display_tournament, list_tournaments
  File "/home/pi/tfg/django/tornejos/project/application/views.py", line 46
    result_data = client.recv()
    ^
IndentationError: unexpected indent
[2018-12-20 12:24:10,052 pyinotify ERROR] The pathname '/home/pi/tfg/django/tornejos/project/application/views.py' of this watch <Watch wd=1013 path=/home/pi/tfg/django/tornejos/project/application/views.py mask=4038 proc_fun=None auto_add=False exclude_filter=<function WatchManager.<lambda> at 0xb65d36a8> dir=False > has probably changed and couldn't be updated, so it cannot be trusted anymore. To fix this error move directories/files only between watched parents directories, in this case e.g. put a watch on '/home/pi/tfg/django/tornejos/project/application'.
Performing system checks...

Unhandled exception in thread started by <function check_errors.<locals>.wrapper at 0xb5a93bb8>
Traceback (most recent call last):
  File "/home/pi/.local/lib/python3.5/site-packages/django/utils/autoreload.py", line 225, in wrapper
    fn(*args, **kwargs)
  File "/home/pi/.local/lib/python3.5/site-packages/django/core/management/commands/runserver.py", line 117, in inner_run
    self.check(display_num_errors=True)
  File "/home/pi/.local/lib/python3.5/site-packages/django/core/management/base.py", line 379, in check
    include_deployment_checks=include_deployment_checks,
  File "/home/pi/.local/lib/python3.5/site-packages/django/core/management/base.py", line 366, in _run_checks
    return checks.run_checks(**kwargs)
  File "/home/pi/.local/lib/python3.5/site-packages/django/core/checks/registry.py", line 71, in run_checks
    new_errors = check(app_configs=app_configs)
  File "/home/pi/.local/lib/python3.5/site-packages/django/core/checks/urls.py", line 40, in check_url_namespaces_unique
    all_namespaces = _load_all_namespaces(resolver)
  File "/home/pi/.local/lib/python3.5/site-packages/django/core/checks/urls.py", line 57, in _load_all_namespaces
    url_patterns = getattr(resolver, 'url_patterns', [])
  File "/home/pi/.local/lib/python3.5/site-packages/django/utils/functional.py", line 37, in __get__
    res = instance.__dict__[self.name] = self.func(instance)
  File "/home/pi/.local/lib/python3.5/site-packages/django/urls/resolvers.py", line 533, in url_patterns
    patterns = getattr(self.urlconf_module, "urlpatterns", self.urlconf_module)
  File "/home/pi/.local/lib/python3.5/site-packages/django/utils/functional.py", line 37, in __get__
    res = instance.__dict__[self.name] = self.func(instance)
  File "/home/pi/.local/lib/python3.5/site-packages/django/urls/resolvers.py", line 526, in urlconf_module
    return import_module(self.urlconf_name)
  File "/usr/lib/python3.5/importlib/__init__.py", line 126, in import_module
    return _bootstrap._gcd_import(name[level:], package, level)
  File "<frozen importlib._bootstrap>", line 986, in _gcd_import
  File "<frozen importlib._bootstrap>", line 969, in _find_and_load
  File "<frozen importlib._bootstrap>", line 958, in _find_and_load_unlocked
  File "<frozen importlib._bootstrap>", line 673, in _load_unlocked
  File "<frozen importlib._bootstrap_external>", line 673, in exec_module
  File "<frozen importlib._bootstrap>", line 222, in _call_with_frames_removed
  File "/home/pi/tfg/django/tornejos/project/urls.py", line 20, in <module>
    from project.application.views import test, create_tournament, display_tournament, list_tournaments
  File "/home/pi/tfg/django/tornejos/project/application/views.py", line 6, in <module>
    from multiprocessing.connections import Client
ImportError: No module named 'multiprocessing.connections'
[2018-12-20 12:24:37,177 pyinotify ERROR] The pathname '/home/pi/tfg/django/tornejos/project/application/views.py' of this watch <Watch wd=1013 path=/home/pi/tfg/django/tornejos/project/application/views.py mask=4038 proc_fun=None auto_add=False exclude_filter=<function WatchManager.<lambda> at 0xb66406a8> dir=False > has probably changed and couldn't be updated, so it cannot be trusted anymore. To fix this error move directories/files only between watched parents directories, in this case e.g. put a watch on '/home/pi/tfg/django/tornejos/project/application'.
Performing system checks...

Unhandled exception in thread started by <function check_errors.<locals>.wrapper at 0xb5a73bb8>
Traceback (most recent call last):
  File "/home/pi/.local/lib/python3.5/site-packages/django/utils/autoreload.py", line 225, in wrapper
    fn(*args, **kwargs)
  File "/home/pi/.local/lib/python3.5/site-packages/django/core/management/commands/runserver.py", line 117, in inner_run
    self.check(display_num_errors=True)
  File "/home/pi/.local/lib/python3.5/site-packages/django/core/management/base.py", line 379, in check
    include_deployment_checks=include_deployment_checks,
  File "/home/pi/.local/lib/python3.5/site-packages/django/core/management/base.py", line 366, in _run_checks
    return checks.run_checks(**kwargs)
  File "/home/pi/.local/lib/python3.5/site-packages/django/core/checks/registry.py", line 71, in run_checks
    new_errors = check(app_configs=app_configs)
  File "/home/pi/.local/lib/python3.5/site-packages/django/core/checks/urls.py", line 40, in check_url_namespaces_unique
    all_namespaces = _load_all_namespaces(resolver)
  File "/home/pi/.local/lib/python3.5/site-packages/django/core/checks/urls.py", line 57, in _load_all_namespaces
    url_patterns = getattr(resolver, 'url_patterns', [])
  File "/home/pi/.local/lib/python3.5/site-packages/django/utils/functional.py", line 37, in __get__
    res = instance.__dict__[self.name] = self.func(instance)
  File "/home/pi/.local/lib/python3.5/site-packages/django/urls/resolvers.py", line 533, in url_patterns
    patterns = getattr(self.urlconf_module, "urlpatterns", self.urlconf_module)
  File "/home/pi/.local/lib/python3.5/site-packages/django/utils/functional.py", line 37, in __get__
    res = instance.__dict__[self.name] = self.func(instance)
  File "/home/pi/.local/lib/python3.5/site-packages/django/urls/resolvers.py", line 526, in urlconf_module
    return import_module(self.urlconf_name)
  File "/usr/lib/python3.5/importlib/__init__.py", line 126, in import_module
    return _bootstrap._gcd_import(name[level:], package, level)
  File "<frozen importlib._bootstrap>", line 986, in _gcd_import
  File "<frozen importlib._bootstrap>", line 969, in _find_and_load
  File "<frozen importlib._bootstrap>", line 958, in _find_and_load_unlocked
  File "<frozen importlib._bootstrap>", line 673, in _load_unlocked
  File "<frozen importlib._bootstrap_external>", line 673, in exec_module
  File "<frozen importlib._bootstrap>", line 222, in _call_with_frames_removed
  File "/home/pi/tfg/django/tornejos/project/urls.py", line 20, in <module>
    from project.application.views import test, create_tournament, display_tournament, list_tournaments
  File "/home/pi/tfg/django/tornejos/project/application/views.py", line 6, in <module>
    from multiprocessing.connections import Client
ImportError: No module named 'multiprocessing.connections'
[2018-12-20 12:25:01,359 pyinotify ERROR] The pathname '/home/pi/tfg/django/tornejos/project/application/views.py' of this watch <Watch wd=1013 path=/home/pi/tfg/django/tornejos/project/application/views.py mask=4038 proc_fun=None auto_add=False exclude_filter=<function WatchManager.<lambda> at 0xb66206a8> dir=False > has probably changed and couldn't be updated, so it cannot be trusted anymore. To fix this error move directories/files only between watched parents directories, in this case e.g. put a watch on '/home/pi/tfg/django/tornejos/project/application'.
Performing system checks...

Unhandled exception in thread started by <function check_errors.<locals>.wrapper at 0xb5ab9bb8>
Traceback (most recent call last):
  File "/home/pi/.local/lib/python3.5/site-packages/django/utils/autoreload.py", line 225, in wrapper
    fn(*args, **kwargs)
  File "/home/pi/.local/lib/python3.5/site-packages/django/core/management/commands/runserver.py", line 117, in inner_run
    self.check(display_num_errors=True)
  File "/home/pi/.local/lib/python3.5/site-packages/django/core/management/base.py", line 379, in check
    include_deployment_checks=include_deployment_checks,
  File "/home/pi/.local/lib/python3.5/site-packages/django/core/management/base.py", line 366, in _run_checks
    return checks.run_checks(**kwargs)
  File "/home/pi/.local/lib/python3.5/site-packages/django/core/checks/registry.py", line 71, in run_checks
    new_errors = check(app_configs=app_configs)
  File "/home/pi/.local/lib/python3.5/site-packages/django/core/checks/urls.py", line 40, in check_url_namespaces_unique
    all_namespaces = _load_all_namespaces(resolver)
  File "/home/pi/.local/lib/python3.5/site-packages/django/core/checks/urls.py", line 57, in _load_all_namespaces
    url_patterns = getattr(resolver, 'url_patterns', [])
  File "/home/pi/.local/lib/python3.5/site-packages/django/utils/functional.py", line 37, in __get__
    res = instance.__dict__[self.name] = self.func(instance)
  File "/home/pi/.local/lib/python3.5/site-packages/django/urls/resolvers.py", line 533, in url_patterns
    patterns = getattr(self.urlconf_module, "urlpatterns", self.urlconf_module)
  File "/home/pi/.local/lib/python3.5/site-packages/django/utils/functional.py", line 37, in __get__
    res = instance.__dict__[self.name] = self.func(instance)
  File "/home/pi/.local/lib/python3.5/site-packages/django/urls/resolvers.py", line 526, in urlconf_module
    return import_module(self.urlconf_name)
  File "/usr/lib/python3.5/importlib/__init__.py", line 126, in import_module
    return _bootstrap._gcd_import(name[level:], package, level)
  File "<frozen importlib._bootstrap>", line 986, in _gcd_import
  File "<frozen importlib._bootstrap>", line 969, in _find_and_load
  File "<frozen importlib._bootstrap>", line 958, in _find_and_load_unlocked
  File "<frozen importlib._bootstrap>", line 673, in _load_unlocked
  File "<frozen importlib._bootstrap_external>", line 673, in exec_module
  File "<frozen importlib._bootstrap>", line 222, in _call_with_frames_removed
  File "/home/pi/tfg/django/tornejos/project/urls.py", line 20, in <module>
    from project.application.views import test, create_tournament, display_tournament, list_tournaments
  File "/home/pi/tfg/django/tornejos/project/application/views.py", line 6, in <module>
    from multiprocessing.connections import Client
ImportError: No module named 'multiprocessing.connections'
[2018-12-20 14:46:57,732 pyinotify ERROR] The pathname '/home/pi/tfg/django/tornejos/project/application/views.py' of this watch <Watch wd=1013 path=/home/pi/tfg/django/tornejos/project/application/views.py mask=4038 proc_fun=None auto_add=False exclude_filter=<function WatchManager.<lambda> at 0xb66726a8> dir=False > has probably changed and couldn't be updated, so it cannot be trusted anymore. To fix this error move directories/files only between watched parents directories, in this case e.g. put a watch on '/home/pi/tfg/django/tornejos/project/application'.
Performing system checks...

Unhandled exception in thread started by <function check_errors.<locals>.wrapper at 0xb5aebbb8>
Traceback (most recent call last):
  File "/home/pi/.local/lib/python3.5/site-packages/django/utils/autoreload.py", line 225, in wrapper
    fn(*args, **kwargs)
  File "/home/pi/.local/lib/python3.5/site-packages/django/core/management/commands/runserver.py", line 117, in inner_run
    self.check(display_num_errors=True)
  File "/home/pi/.local/lib/python3.5/site-packages/django/core/management/base.py", line 379, in check
    include_deployment_checks=include_deployment_checks,
  File "/home/pi/.local/lib/python3.5/site-packages/django/core/management/base.py", line 366, in _run_checks
    return checks.run_checks(**kwargs)
  File "/home/pi/.local/lib/python3.5/site-packages/django/core/checks/registry.py", line 71, in run_checks
    new_errors = check(app_configs=app_configs)
  File "/home/pi/.local/lib/python3.5/site-packages/django/core/checks/urls.py", line 40, in check_url_namespaces_unique
    all_namespaces = _load_all_namespaces(resolver)
  File "/home/pi/.local/lib/python3.5/site-packages/django/core/checks/urls.py", line 57, in _load_all_namespaces
    url_patterns = getattr(resolver, 'url_patterns', [])
  File "/home/pi/.local/lib/python3.5/site-packages/django/utils/functional.py", line 37, in __get__
    res = instance.__dict__[self.name] = self.func(instance)
  File "/home/pi/.local/lib/python3.5/site-packages/django/urls/resolvers.py", line 533, in url_patterns
    patterns = getattr(self.urlconf_module, "urlpatterns", self.urlconf_module)
  File "/home/pi/.local/lib/python3.5/site-packages/django/utils/functional.py", line 37, in __get__
    res = instance.__dict__[self.name] = self.func(instance)
  File "/home/pi/.local/lib/python3.5/site-packages/django/urls/resolvers.py", line 526, in urlconf_module
    return import_module(self.urlconf_name)
  File "/usr/lib/python3.5/importlib/__init__.py", line 126, in import_module
    return _bootstrap._gcd_import(name[level:], package, level)
  File "<frozen importlib._bootstrap>", line 986, in _gcd_import
  File "<frozen importlib._bootstrap>", line 969, in _find_and_load
  File "<frozen importlib._bootstrap>", line 958, in _find_and_load_unlocked
  File "<frozen importlib._bootstrap>", line 673, in _load_unlocked
  File "<frozen importlib._bootstrap_external>", line 673, in exec_module
  File "<frozen importlib._bootstrap>", line 222, in _call_with_frames_removed
  File "/home/pi/tfg/django/tornejos/project/urls.py", line 20, in <module>
    from project.application.views import test, create_tournament, display_tournament, list_tournaments
  File "/home/pi/tfg/django/tornejos/project/application/views.py", line 6, in <module>
    from multiprocessing.connections import Client
ImportError: No module named 'multiprocessing.connections'
[2018-12-20 15:57:58,594 pyinotify ERROR] The pathname '/home/pi/tfg/django/tornejos/project/application/views.py' of this watch <Watch wd=1013 path=/home/pi/tfg/django/tornejos/project/application/views.py mask=4038 proc_fun=None auto_add=False exclude_filter=<function WatchManager.<lambda> at 0xb66986a8> dir=False > has probably changed and couldn't be updated, so it cannot be trusted anymore. To fix this error move directories/files only between watched parents directories, in this case e.g. put a watch on '/home/pi/tfg/django/tornejos/project/application'.
Performing system checks...

Unhandled exception in thread started by <function check_errors.<locals>.wrapper at 0xb5a1cbb8>
Traceback (most recent call last):
  File "/home/pi/.local/lib/python3.5/site-packages/django/utils/autoreload.py", line 225, in wrapper
    fn(*args, **kwargs)
  File "/home/pi/.local/lib/python3.5/site-packages/django/core/management/commands/runserver.py", line 117, in inner_run
    self.check(display_num_errors=True)
  File "/home/pi/.local/lib/python3.5/site-packages/django/core/management/base.py", line 379, in check
    include_deployment_checks=include_deployment_checks,
  File "/home/pi/.local/lib/python3.5/site-packages/django/core/management/base.py", line 366, in _run_checks
    return checks.run_checks(**kwargs)
  File "/home/pi/.local/lib/python3.5/site-packages/django/core/checks/registry.py", line 71, in run_checks
    new_errors = check(app_configs=app_configs)
  File "/home/pi/.local/lib/python3.5/site-packages/django/core/checks/urls.py", line 40, in check_url_namespaces_unique
    all_namespaces = _load_all_namespaces(resolver)
  File "/home/pi/.local/lib/python3.5/site-packages/django/core/checks/urls.py", line 57, in _load_all_namespaces
    url_patterns = getattr(resolver, 'url_patterns', [])
  File "/home/pi/.local/lib/python3.5/site-packages/django/utils/functional.py", line 37, in __get__
    res = instance.__dict__[self.name] = self.func(instance)
  File "/home/pi/.local/lib/python3.5/site-packages/django/urls/resolvers.py", line 533, in url_patterns
    patterns = getattr(self.urlconf_module, "urlpatterns", self.urlconf_module)
  File "/home/pi/.local/lib/python3.5/site-packages/django/utils/functional.py", line 37, in __get__
    res = instance.__dict__[self.name] = self.func(instance)
  File "/home/pi/.local/lib/python3.5/site-packages/django/urls/resolvers.py", line 526, in urlconf_module
    return import_module(self.urlconf_name)
  File "/usr/lib/python3.5/importlib/__init__.py", line 126, in import_module
    return _bootstrap._gcd_import(name[level:], package, level)
  File "<frozen importlib._bootstrap>", line 986, in _gcd_import
  File "<frozen importlib._bootstrap>", line 969, in _find_and_load
  File "<frozen importlib._bootstrap>", line 958, in _find_and_load_unlocked
  File "<frozen importlib._bootstrap>", line 673, in _load_unlocked
  File "<frozen importlib._bootstrap_external>", line 673, in exec_module
  File "<frozen importlib._bootstrap>", line 222, in _call_with_frames_removed
  File "/home/pi/tfg/django/tornejos/project/urls.py", line 20, in <module>
    from project.application.views import test, create_tournament, display_tournament, list_tournaments
  File "/home/pi/tfg/django/tornejos/project/application/views.py", line 6, in <module>
    from multiprocessing.connections import Client
ImportError: No module named 'multiprocessing.connections'
[2018-12-20 16:05:15,461 pyinotify ERROR] The pathname '/home/pi/tfg/django/tornejos/project/application/views.py' of this watch <Watch wd=1013 path=/home/pi/tfg/django/tornejos/project/application/views.py mask=4038 proc_fun=None auto_add=False exclude_filter=<function WatchManager.<lambda> at 0xb65c96a8> dir=False > has probably changed and couldn't be updated, so it cannot be trusted anymore. To fix this error move directories/files only between watched parents directories, in this case e.g. put a watch on '/home/pi/tfg/django/tornejos/project/application'.
Performing system checks...

Unhandled exception in thread started by <function check_errors.<locals>.wrapper at 0xb5a78bb8>
Traceback (most recent call last):
  File "/home/pi/.local/lib/python3.5/site-packages/django/utils/autoreload.py", line 225, in wrapper
    fn(*args, **kwargs)
  File "/home/pi/.local/lib/python3.5/site-packages/django/core/management/commands/runserver.py", line 117, in inner_run
    self.check(display_num_errors=True)
  File "/home/pi/.local/lib/python3.5/site-packages/django/core/management/base.py", line 379, in check
    include_deployment_checks=include_deployment_checks,
  File "/home/pi/.local/lib/python3.5/site-packages/django/core/management/base.py", line 366, in _run_checks
    return checks.run_checks(**kwargs)
  File "/home/pi/.local/lib/python3.5/site-packages/django/core/checks/registry.py", line 71, in run_checks
    new_errors = check(app_configs=app_configs)
  File "/home/pi/.local/lib/python3.5/site-packages/django/core/checks/urls.py", line 40, in check_url_namespaces_unique
    all_namespaces = _load_all_namespaces(resolver)
  File "/home/pi/.local/lib/python3.5/site-packages/django/core/checks/urls.py", line 57, in _load_all_namespaces
    url_patterns = getattr(resolver, 'url_patterns', [])
  File "/home/pi/.local/lib/python3.5/site-packages/django/utils/functional.py", line 37, in __get__
    res = instance.__dict__[self.name] = self.func(instance)
  File "/home/pi/.local/lib/python3.5/site-packages/django/urls/resolvers.py", line 533, in url_patterns
    patterns = getattr(self.urlconf_module, "urlpatterns", self.urlconf_module)
  File "/home/pi/.local/lib/python3.5/site-packages/django/utils/functional.py", line 37, in __get__
    res = instance.__dict__[self.name] = self.func(instance)
  File "/home/pi/.local/lib/python3.5/site-packages/django/urls/resolvers.py", line 526, in urlconf_module
    return import_module(self.urlconf_name)
  File "/usr/lib/python3.5/importlib/__init__.py", line 126, in import_module
    return _bootstrap._gcd_import(name[level:], package, level)
  File "<frozen importlib._bootstrap>", line 986, in _gcd_import
  File "<frozen importlib._bootstrap>", line 969, in _find_and_load
  File "<frozen importlib._bootstrap>", line 958, in _find_and_load_unlocked
  File "<frozen importlib._bootstrap>", line 673, in _load_unlocked
  File "<frozen importlib._bootstrap_external>", line 673, in exec_module
  File "<frozen importlib._bootstrap>", line 222, in _call_with_frames_removed
  File "/home/pi/tfg/django/tornejos/project/urls.py", line 20, in <module>
    from project.application.views import test, create_tournament, display_tournament, list_tournaments
  File "/home/pi/tfg/django/tornejos/project/application/views.py", line 6, in <module>
    from multiprocessing.connections import Client
ImportError: No module named 'multiprocessing.connections'
[2018-12-20 16:30:31,081 pyinotify ERROR] The pathname '/home/pi/tfg/django/tornejos/project/application/views.py' of this watch <Watch wd=1013 path=/home/pi/tfg/django/tornejos/project/application/views.py mask=4038 proc_fun=None auto_add=False exclude_filter=<function WatchManager.<lambda> at 0xb66256a8> dir=False > has probably changed and couldn't be updated, so it cannot be trusted anymore. To fix this error move directories/files only between watched parents directories, in this case e.g. put a watch on '/home/pi/tfg/django/tornejos/project/application'.
Performing system checks...

Unhandled exception in thread started by <function check_errors.<locals>.wrapper at 0xb5b05bb8>
Traceback (most recent call last):
  File "/home/pi/.local/lib/python3.5/site-packages/django/utils/autoreload.py", line 225, in wrapper
    fn(*args, **kwargs)
  File "/home/pi/.local/lib/python3.5/site-packages/django/core/management/commands/runserver.py", line 117, in inner_run
    self.check(display_num_errors=True)
  File "/home/pi/.local/lib/python3.5/site-packages/django/core/management/base.py", line 379, in check
    include_deployment_checks=include_deployment_checks,
  File "/home/pi/.local/lib/python3.5/site-packages/django/core/management/base.py", line 366, in _run_checks
    return checks.run_checks(**kwargs)
  File "/home/pi/.local/lib/python3.5/site-packages/django/core/checks/registry.py", line 71, in run_checks
    new_errors = check(app_configs=app_configs)
  File "/home/pi/.local/lib/python3.5/site-packages/django/core/checks/urls.py", line 40, in check_url_namespaces_unique
    all_namespaces = _load_all_namespaces(resolver)
  File "/home/pi/.local/lib/python3.5/site-packages/django/core/checks/urls.py", line 57, in _load_all_namespaces
    url_patterns = getattr(resolver, 'url_patterns', [])
  File "/home/pi/.local/lib/python3.5/site-packages/django/utils/functional.py", line 37, in __get__
    res = instance.__dict__[self.name] = self.func(instance)
  File "/home/pi/.local/lib/python3.5/site-packages/django/urls/resolvers.py", line 533, in url_patterns
    patterns = getattr(self.urlconf_module, "urlpatterns", self.urlconf_module)
  File "/home/pi/.local/lib/python3.5/site-packages/django/utils/functional.py", line 37, in __get__
    res = instance.__dict__[self.name] = self.func(instance)
  File "/home/pi/.local/lib/python3.5/site-packages/django/urls/resolvers.py", line 526, in urlconf_module
    return import_module(self.urlconf_name)
  File "/usr/lib/python3.5/importlib/__init__.py", line 126, in import_module
    return _bootstrap._gcd_import(name[level:], package, level)
  File "<frozen importlib._bootstrap>", line 986, in _gcd_import
  File "<frozen importlib._bootstrap>", line 969, in _find_and_load
  File "<frozen importlib._bootstrap>", line 958, in _find_and_load_unlocked
  File "<frozen importlib._bootstrap>", line 673, in _load_unlocked
  File "<frozen importlib._bootstrap_external>", line 673, in exec_module
  File "<frozen importlib._bootstrap>", line 222, in _call_with_frames_removed
  File "/home/pi/tfg/django/tornejos/project/urls.py", line 20, in <module>
    from project.application.views import test, create_tournament, display_tournament, list_tournaments
  File "/home/pi/tfg/django/tornejos/project/application/views.py", line 6, in <module>
    from multiprocessing.connections import Client
ImportError: No module named 'multiprocessing.connections'
[2018-12-20 16:31:00,746 pyinotify ERROR] The pathname '/home/pi/tfg/django/tornejos/project/application/views.py' of this watch <Watch wd=1013 path=/home/pi/tfg/django/tornejos/project/application/views.py mask=4038 proc_fun=None auto_add=False exclude_filter=<function WatchManager.<lambda> at 0xb66b26a8> dir=False > has probably changed and couldn't be updated, so it cannot be trusted anymore. To fix this error move directories/files only between watched parents directories, in this case e.g. put a watch on '/home/pi/tfg/django/tornejos/project/application'.
Performing system checks...

Unhandled exception in thread started by <function check_errors.<locals>.wrapper at 0xb5adcbb8>
Traceback (most recent call last):
  File "/home/pi/.local/lib/python3.5/site-packages/django/utils/autoreload.py", line 225, in wrapper
    fn(*args, **kwargs)
  File "/home/pi/.local/lib/python3.5/site-packages/django/core/management/commands/runserver.py", line 117, in inner_run
    self.check(display_num_errors=True)
  File "/home/pi/.local/lib/python3.5/site-packages/django/core/management/base.py", line 379, in check
    include_deployment_checks=include_deployment_checks,
  File "/home/pi/.local/lib/python3.5/site-packages/django/core/management/base.py", line 366, in _run_checks
    return checks.run_checks(**kwargs)
  File "/home/pi/.local/lib/python3.5/site-packages/django/core/checks/registry.py", line 71, in run_checks
    new_errors = check(app_configs=app_configs)
  File "/home/pi/.local/lib/python3.5/site-packages/django/core/checks/urls.py", line 40, in check_url_namespaces_unique
    all_namespaces = _load_all_namespaces(resolver)
  File "/home/pi/.local/lib/python3.5/site-packages/django/core/checks/urls.py", line 57, in _load_all_namespaces
    url_patterns = getattr(resolver, 'url_patterns', [])
  File "/home/pi/.local/lib/python3.5/site-packages/django/utils/functional.py", line 37, in __get__
    res = instance.__dict__[self.name] = self.func(instance)
  File "/home/pi/.local/lib/python3.5/site-packages/django/urls/resolvers.py", line 533, in url_patterns
    patterns = getattr(self.urlconf_module, "urlpatterns", self.urlconf_module)
  File "/home/pi/.local/lib/python3.5/site-packages/django/utils/functional.py", line 37, in __get__
    res = instance.__dict__[self.name] = self.func(instance)
  File "/home/pi/.local/lib/python3.5/site-packages/django/urls/resolvers.py", line 526, in urlconf_module
    return import_module(self.urlconf_name)
  File "/usr/lib/python3.5/importlib/__init__.py", line 126, in import_module
    return _bootstrap._gcd_import(name[level:], package, level)
  File "<frozen importlib._bootstrap>", line 986, in _gcd_import
  File "<frozen importlib._bootstrap>", line 969, in _find_and_load
  File "<frozen importlib._bootstrap>", line 958, in _find_and_load_unlocked
  File "<frozen importlib._bootstrap>", line 673, in _load_unlocked
  File "<frozen importlib._bootstrap_external>", line 673, in exec_module
  File "<frozen importlib._bootstrap>", line 222, in _call_with_frames_removed
  File "/home/pi/tfg/django/tornejos/project/urls.py", line 20, in <module>
    from project.application.views import test, create_tournament, display_tournament, list_tournaments
  File "/home/pi/tfg/django/tornejos/project/application/views.py", line 6, in <module>
    from multiprocessing.connections import Client
ImportError: No module named 'multiprocessing.connections'
[2018-12-20 16:31:48,817 pyinotify ERROR] The pathname '/home/pi/tfg/django/tornejos/project/application/views.py' of this watch <Watch wd=1013 path=/home/pi/tfg/django/tornejos/project/application/views.py mask=4038 proc_fun=None auto_add=False exclude_filter=<function WatchManager.<lambda> at 0xb66956a8> dir=False > has probably changed and couldn't be updated, so it cannot be trusted anymore. To fix this error move directories/files only between watched parents directories, in this case e.g. put a watch on '/home/pi/tfg/django/tornejos/project/application'.
Performing system checks...

Unhandled exception in thread started by <function check_errors.<locals>.wrapper at 0xb5a78bb8>
Traceback (most recent call last):
  File "/home/pi/.local/lib/python3.5/site-packages/django/utils/autoreload.py", line 225, in wrapper
    fn(*args, **kwargs)
  File "/home/pi/.local/lib/python3.5/site-packages/django/core/management/commands/runserver.py", line 117, in inner_run
    self.check(display_num_errors=True)
  File "/home/pi/.local/lib/python3.5/site-packages/django/core/management/base.py", line 379, in check
    include_deployment_checks=include_deployment_checks,
  File "/home/pi/.local/lib/python3.5/site-packages/django/core/management/base.py", line 366, in _run_checks
    return checks.run_checks(**kwargs)
  File "/home/pi/.local/lib/python3.5/site-packages/django/core/checks/registry.py", line 71, in run_checks
    new_errors = check(app_configs=app_configs)
  File "/home/pi/.local/lib/python3.5/site-packages/django/core/checks/urls.py", line 40, in check_url_namespaces_unique
    all_namespaces = _load_all_namespaces(resolver)
  File "/home/pi/.local/lib/python3.5/site-packages/django/core/checks/urls.py", line 57, in _load_all_namespaces
    url_patterns = getattr(resolver, 'url_patterns', [])
  File "/home/pi/.local/lib/python3.5/site-packages/django/utils/functional.py", line 37, in __get__
    res = instance.__dict__[self.name] = self.func(instance)
  File "/home/pi/.local/lib/python3.5/site-packages/django/urls/resolvers.py", line 533, in url_patterns
    patterns = getattr(self.urlconf_module, "urlpatterns", self.urlconf_module)
  File "/home/pi/.local/lib/python3.5/site-packages/django/utils/functional.py", line 37, in __get__
    res = instance.__dict__[self.name] = self.func(instance)
  File "/home/pi/.local/lib/python3.5/site-packages/django/urls/resolvers.py", line 526, in urlconf_module
    return import_module(self.urlconf_name)
  File "/usr/lib/python3.5/importlib/__init__.py", line 126, in import_module
    return _bootstrap._gcd_import(name[level:], package, level)
  File "<frozen importlib._bootstrap>", line 986, in _gcd_import
  File "<frozen importlib._bootstrap>", line 969, in _find_and_load
  File "<frozen importlib._bootstrap>", line 958, in _find_and_load_unlocked
  File "<frozen importlib._bootstrap>", line 673, in _load_unlocked
  File "<frozen importlib._bootstrap_external>", line 673, in exec_module
  File "<frozen importlib._bootstrap>", line 222, in _call_with_frames_removed
  File "/home/pi/tfg/django/tornejos/project/urls.py", line 20, in <module>
    from project.application.views import test, create_tournament, display_tournament, list_tournaments
  File "/home/pi/tfg/django/tornejos/project/application/views.py", line 6, in <module>
    from multiprocessing.connections import Client
ImportError: No module named 'multiprocessing.connections'
[2018-12-20 16:33:24,271 pyinotify ERROR] The pathname '/home/pi/tfg/django/tornejos/project/application/views.py' of this watch <Watch wd=1013 path=/home/pi/tfg/django/tornejos/project/application/views.py mask=4038 proc_fun=None auto_add=False exclude_filter=<function WatchManager.<lambda> at 0xb66256a8> dir=False > has probably changed and couldn't be updated, so it cannot be trusted anymore. To fix this error move directories/files only between watched parents directories, in this case e.g. put a watch on '/home/pi/tfg/django/tornejos/project/application'.
Performing system checks...

Unhandled exception in thread started by <function check_errors.<locals>.wrapper at 0xb5aa3bb8>
Traceback (most recent call last):
  File "/home/pi/.local/lib/python3.5/site-packages/django/utils/autoreload.py", line 225, in wrapper
    fn(*args, **kwargs)
  File "/home/pi/.local/lib/python3.5/site-packages/django/core/management/commands/runserver.py", line 117, in inner_run
    self.check(display_num_errors=True)
  File "/home/pi/.local/lib/python3.5/site-packages/django/core/management/base.py", line 379, in check
    include_deployment_checks=include_deployment_checks,
  File "/home/pi/.local/lib/python3.5/site-packages/django/core/management/base.py", line 366, in _run_checks
    return checks.run_checks(**kwargs)
  File "/home/pi/.local/lib/python3.5/site-packages/django/core/checks/registry.py", line 71, in run_checks
    new_errors = check(app_configs=app_configs)
  File "/home/pi/.local/lib/python3.5/site-packages/django/core/checks/urls.py", line 40, in check_url_namespaces_unique
    all_namespaces = _load_all_namespaces(resolver)
  File "/home/pi/.local/lib/python3.5/site-packages/django/core/checks/urls.py", line 57, in _load_all_namespaces
    url_patterns = getattr(resolver, 'url_patterns', [])
  File "/home/pi/.local/lib/python3.5/site-packages/django/utils/functional.py", line 37, in __get__
    res = instance.__dict__[self.name] = self.func(instance)
  File "/home/pi/.local/lib/python3.5/site-packages/django/urls/resolvers.py", line 533, in url_patterns
    patterns = getattr(self.urlconf_module, "urlpatterns", self.urlconf_module)
  File "/home/pi/.local/lib/python3.5/site-packages/django/utils/functional.py", line 37, in __get__
    res = instance.__dict__[self.name] = self.func(instance)
  File "/home/pi/.local/lib/python3.5/site-packages/django/urls/resolvers.py", line 526, in urlconf_module
    return import_module(self.urlconf_name)
  File "/usr/lib/python3.5/importlib/__init__.py", line 126, in import_module
    return _bootstrap._gcd_import(name[level:], package, level)
  File "<frozen importlib._bootstrap>", line 986, in _gcd_import
  File "<frozen importlib._bootstrap>", line 969, in _find_and_load
  File "<frozen importlib._bootstrap>", line 958, in _find_and_load_unlocked
  File "<frozen importlib._bootstrap>", line 673, in _load_unlocked
  File "<frozen importlib._bootstrap_external>", line 673, in exec_module
  File "<frozen importlib._bootstrap>", line 222, in _call_with_frames_removed
  File "/home/pi/tfg/django/tornejos/project/urls.py", line 20, in <module>
    from project.application.views import test, create_tournament, display_tournament, list_tournaments
  File "/home/pi/tfg/django/tornejos/project/application/views.py", line 6, in <module>
    from multiprocessing.connections import Client
ImportError: No module named 'multiprocessing.connections'
[2018-12-20 16:37:52,799 pyinotify ERROR] The pathname '/home/pi/tfg/django/tornejos/project/application/views.py' of this watch <Watch wd=1013 path=/home/pi/tfg/django/tornejos/project/application/views.py mask=4038 proc_fun=None auto_add=False exclude_filter=<function WatchManager.<lambda> at 0xb66506a8> dir=False > has probably changed and couldn't be updated, so it cannot be trusted anymore. To fix this error move directories/files only between watched parents directories, in this case e.g. put a watch on '/home/pi/tfg/django/tornejos/project/application'.
Performing system checks...

Unhandled exception in thread started by <function check_errors.<locals>.wrapper at 0xb5a5bbb8>
Traceback (most recent call last):
  File "/home/pi/.local/lib/python3.5/site-packages/django/utils/autoreload.py", line 225, in wrapper
    fn(*args, **kwargs)
  File "/home/pi/.local/lib/python3.5/site-packages/django/core/management/commands/runserver.py", line 117, in inner_run
    self.check(display_num_errors=True)
  File "/home/pi/.local/lib/python3.5/site-packages/django/core/management/base.py", line 379, in check
    include_deployment_checks=include_deployment_checks,
  File "/home/pi/.local/lib/python3.5/site-packages/django/core/management/base.py", line 366, in _run_checks
    return checks.run_checks(**kwargs)
  File "/home/pi/.local/lib/python3.5/site-packages/django/core/checks/registry.py", line 71, in run_checks
    new_errors = check(app_configs=app_configs)
  File "/home/pi/.local/lib/python3.5/site-packages/django/core/checks/urls.py", line 40, in check_url_namespaces_unique
    all_namespaces = _load_all_namespaces(resolver)
  File "/home/pi/.local/lib/python3.5/site-packages/django/core/checks/urls.py", line 57, in _load_all_namespaces
    url_patterns = getattr(resolver, 'url_patterns', [])
  File "/home/pi/.local/lib/python3.5/site-packages/django/utils/functional.py", line 37, in __get__
    res = instance.__dict__[self.name] = self.func(instance)
  File "/home/pi/.local/lib/python3.5/site-packages/django/urls/resolvers.py", line 533, in url_patterns
    patterns = getattr(self.urlconf_module, "urlpatterns", self.urlconf_module)
  File "/home/pi/.local/lib/python3.5/site-packages/django/utils/functional.py", line 37, in __get__
    res = instance.__dict__[self.name] = self.func(instance)
  File "/home/pi/.local/lib/python3.5/site-packages/django/urls/resolvers.py", line 526, in urlconf_module
    return import_module(self.urlconf_name)
  File "/usr/lib/python3.5/importlib/__init__.py", line 126, in import_module
    return _bootstrap._gcd_import(name[level:], package, level)
  File "<frozen importlib._bootstrap>", line 986, in _gcd_import
  File "<frozen importlib._bootstrap>", line 969, in _find_and_load
  File "<frozen importlib._bootstrap>", line 958, in _find_and_load_unlocked
  File "<frozen importlib._bootstrap>", line 673, in _load_unlocked
  File "<frozen importlib._bootstrap_external>", line 673, in exec_module
  File "<frozen importlib._bootstrap>", line 222, in _call_with_frames_removed
  File "/home/pi/tfg/django/tornejos/project/urls.py", line 20, in <module>
    from project.application.views import test, create_tournament, display_tournament, list_tournaments
  File "/home/pi/tfg/django/tornejos/project/application/views.py", line 6, in <module>
    from multiprocessing.connections import Client
ImportError: No module named 'multiprocessing.connections'
[2018-12-20 16:40:51,443 pyinotify ERROR] The pathname '/home/pi/tfg/django/tornejos/project/application/views.py' of this watch <Watch wd=1013 path=/home/pi/tfg/django/tornejos/project/application/views.py mask=4038 proc_fun=None auto_add=False exclude_filter=<function WatchManager.<lambda> at 0xb66086a8> dir=False > has probably changed and couldn't be updated, so it cannot be trusted anymore. To fix this error move directories/files only between watched parents directories, in this case e.g. put a watch on '/home/pi/tfg/django/tornejos/project/application'.
Performing system checks...

Unhandled exception in thread started by <function check_errors.<locals>.wrapper at 0xb5a70bb8>
Traceback (most recent call last):
  File "/home/pi/.local/lib/python3.5/site-packages/django/utils/autoreload.py", line 225, in wrapper
    fn(*args, **kwargs)
  File "/home/pi/.local/lib/python3.5/site-packages/django/core/management/commands/runserver.py", line 117, in inner_run
    self.check(display_num_errors=True)
  File "/home/pi/.local/lib/python3.5/site-packages/django/core/management/base.py", line 379, in check
    include_deployment_checks=include_deployment_checks,
  File "/home/pi/.local/lib/python3.5/site-packages/django/core/management/base.py", line 366, in _run_checks
    return checks.run_checks(**kwargs)
  File "/home/pi/.local/lib/python3.5/site-packages/django/core/checks/registry.py", line 71, in run_checks
    new_errors = check(app_configs=app_configs)
  File "/home/pi/.local/lib/python3.5/site-packages/django/core/checks/urls.py", line 40, in check_url_namespaces_unique
    all_namespaces = _load_all_namespaces(resolver)
  File "/home/pi/.local/lib/python3.5/site-packages/django/core/checks/urls.py", line 57, in _load_all_namespaces
    url_patterns = getattr(resolver, 'url_patterns', [])
  File "/home/pi/.local/lib/python3.5/site-packages/django/utils/functional.py", line 37, in __get__
    res = instance.__dict__[self.name] = self.func(instance)
  File "/home/pi/.local/lib/python3.5/site-packages/django/urls/resolvers.py", line 533, in url_patterns
    patterns = getattr(self.urlconf_module, "urlpatterns", self.urlconf_module)
  File "/home/pi/.local/lib/python3.5/site-packages/django/utils/functional.py", line 37, in __get__
    res = instance.__dict__[self.name] = self.func(instance)
  File "/home/pi/.local/lib/python3.5/site-packages/django/urls/resolvers.py", line 526, in urlconf_module
    return import_module(self.urlconf_name)
  File "/usr/lib/python3.5/importlib/__init__.py", line 126, in import_module
    return _bootstrap._gcd_import(name[level:], package, level)
  File "<frozen importlib._bootstrap>", line 986, in _gcd_import
  File "<frozen importlib._bootstrap>", line 969, in _find_and_load
  File "<frozen importlib._bootstrap>", line 958, in _find_and_load_unlocked
  File "<frozen importlib._bootstrap>", line 673, in _load_unlocked
  File "<frozen importlib._bootstrap_external>", line 673, in exec_module
  File "<frozen importlib._bootstrap>", line 222, in _call_with_frames_removed
  File "/home/pi/tfg/django/tornejos/project/urls.py", line 20, in <module>
    from project.application.views import test, create_tournament, display_tournament, list_tournaments
  File "/home/pi/tfg/django/tornejos/project/application/views.py", line 6, in <module>
    from multiprocessing.connections import Client
ImportError: No module named 'multiprocessing.connections'
[2018-12-20 16:44:22,125 pyinotify ERROR] The pathname '/home/pi/tfg/django/tornejos/project/application/views.py' of this watch <Watch wd=1013 path=/home/pi/tfg/django/tornejos/project/application/views.py mask=4038 proc_fun=None auto_add=False exclude_filter=<function WatchManager.<lambda> at 0xb661d6a8> dir=False > has probably changed and couldn't be updated, so it cannot be trusted anymore. To fix this error move directories/files only between watched parents directories, in this case e.g. put a watch on '/home/pi/tfg/django/tornejos/project/application'.
Performing system checks...

Unhandled exception in thread started by <function check_errors.<locals>.wrapper at 0xb5aafbb8>
Traceback (most recent call last):
  File "/home/pi/.local/lib/python3.5/site-packages/django/utils/autoreload.py", line 225, in wrapper
    fn(*args, **kwargs)
  File "/home/pi/.local/lib/python3.5/site-packages/django/core/management/commands/runserver.py", line 117, in inner_run
    self.check(display_num_errors=True)
  File "/home/pi/.local/lib/python3.5/site-packages/django/core/management/base.py", line 379, in check
    include_deployment_checks=include_deployment_checks,
  File "/home/pi/.local/lib/python3.5/site-packages/django/core/management/base.py", line 366, in _run_checks
    return checks.run_checks(**kwargs)
  File "/home/pi/.local/lib/python3.5/site-packages/django/core/checks/registry.py", line 71, in run_checks
    new_errors = check(app_configs=app_configs)
  File "/home/pi/.local/lib/python3.5/site-packages/django/core/checks/urls.py", line 40, in check_url_namespaces_unique
    all_namespaces = _load_all_namespaces(resolver)
  File "/home/pi/.local/lib/python3.5/site-packages/django/core/checks/urls.py", line 57, in _load_all_namespaces
    url_patterns = getattr(resolver, 'url_patterns', [])
  File "/home/pi/.local/lib/python3.5/site-packages/django/utils/functional.py", line 37, in __get__
    res = instance.__dict__[self.name] = self.func(instance)
  File "/home/pi/.local/lib/python3.5/site-packages/django/urls/resolvers.py", line 533, in url_patterns
    patterns = getattr(self.urlconf_module, "urlpatterns", self.urlconf_module)
  File "/home/pi/.local/lib/python3.5/site-packages/django/utils/functional.py", line 37, in __get__
    res = instance.__dict__[self.name] = self.func(instance)
  File "/home/pi/.local/lib/python3.5/site-packages/django/urls/resolvers.py", line 526, in urlconf_module
    return import_module(self.urlconf_name)
  File "/usr/lib/python3.5/importlib/__init__.py", line 126, in import_module
    return _bootstrap._gcd_import(name[level:], package, level)
  File "<frozen importlib._bootstrap>", line 986, in _gcd_import
  File "<frozen importlib._bootstrap>", line 969, in _find_and_load
  File "<frozen importlib._bootstrap>", line 958, in _find_and_load_unlocked
  File "<frozen importlib._bootstrap>", line 673, in _load_unlocked
  File "<frozen importlib._bootstrap_external>", line 673, in exec_module
  File "<frozen importlib._bootstrap>", line 222, in _call_with_frames_removed
  File "/home/pi/tfg/django/tornejos/project/urls.py", line 20, in <module>
    from project.application.views import test, create_tournament, display_tournament, list_tournaments
  File "/home/pi/tfg/django/tornejos/project/application/views.py", line 6, in <module>
    from multiprocessing.connections import Client
ImportError: No module named 'multiprocessing.connections'
[2018-12-20 16:44:42,968 pyinotify ERROR] The pathname '/home/pi/tfg/django/tornejos/project/application/views.py' of this watch <Watch wd=1013 path=/home/pi/tfg/django/tornejos/project/application/views.py mask=4038 proc_fun=None auto_add=False exclude_filter=<function WatchManager.<lambda> at 0xb665c6a8> dir=False > has probably changed and couldn't be updated, so it cannot be trusted anymore. To fix this error move directories/files only between watched parents directories, in this case e.g. put a watch on '/home/pi/tfg/django/tornejos/project/application'.
Performing system checks...

Unhandled exception in thread started by <function check_errors.<locals>.wrapper at 0xb5a69bb8>
Traceback (most recent call last):
  File "/home/pi/.local/lib/python3.5/site-packages/django/utils/autoreload.py", line 225, in wrapper
    fn(*args, **kwargs)
  File "/home/pi/.local/lib/python3.5/site-packages/django/core/management/commands/runserver.py", line 117, in inner_run
    self.check(display_num_errors=True)
  File "/home/pi/.local/lib/python3.5/site-packages/django/core/management/base.py", line 379, in check
    include_deployment_checks=include_deployment_checks,
  File "/home/pi/.local/lib/python3.5/site-packages/django/core/management/base.py", line 366, in _run_checks
    return checks.run_checks(**kwargs)
  File "/home/pi/.local/lib/python3.5/site-packages/django/core/checks/registry.py", line 71, in run_checks
    new_errors = check(app_configs=app_configs)
  File "/home/pi/.local/lib/python3.5/site-packages/django/core/checks/urls.py", line 40, in check_url_namespaces_unique
    all_namespaces = _load_all_namespaces(resolver)
  File "/home/pi/.local/lib/python3.5/site-packages/django/core/checks/urls.py", line 57, in _load_all_namespaces
    url_patterns = getattr(resolver, 'url_patterns', [])
  File "/home/pi/.local/lib/python3.5/site-packages/django/utils/functional.py", line 37, in __get__
    res = instance.__dict__[self.name] = self.func(instance)
  File "/home/pi/.local/lib/python3.5/site-packages/django/urls/resolvers.py", line 533, in url_patterns
    patterns = getattr(self.urlconf_module, "urlpatterns", self.urlconf_module)
  File "/home/pi/.local/lib/python3.5/site-packages/django/utils/functional.py", line 37, in __get__
    res = instance.__dict__[self.name] = self.func(instance)
  File "/home/pi/.local/lib/python3.5/site-packages/django/urls/resolvers.py", line 526, in urlconf_module
    return import_module(self.urlconf_name)
  File "/usr/lib/python3.5/importlib/__init__.py", line 126, in import_module
    return _bootstrap._gcd_import(name[level:], package, level)
  File "<frozen importlib._bootstrap>", line 986, in _gcd_import
  File "<frozen importlib._bootstrap>", line 969, in _find_and_load
  File "<frozen importlib._bootstrap>", line 958, in _find_and_load_unlocked
  File "<frozen importlib._bootstrap>", line 673, in _load_unlocked
  File "<frozen importlib._bootstrap_external>", line 673, in exec_module
  File "<frozen importlib._bootstrap>", line 222, in _call_with_frames_removed
  File "/home/pi/tfg/django/tornejos/project/urls.py", line 20, in <module>
    from project.application.views import test, create_tournament, display_tournament, list_tournaments
  File "/home/pi/tfg/django/tornejos/project/application/views.py", line 6, in <module>
    from multiprocessing.connections import Client
ImportError: No module named 'multiprocessing.connections'
[2018-12-20 16:47:55,287 pyinotify ERROR] The pathname '/home/pi/tfg/django/tornejos/project/application/views.py' of this watch <Watch wd=1013 path=/home/pi/tfg/django/tornejos/project/application/views.py mask=4038 proc_fun=None auto_add=False exclude_filter=<function WatchManager.<lambda> at 0xb66166a8> dir=False > has probably changed and couldn't be updated, so it cannot be trusted anymore. To fix this error move directories/files only between watched parents directories, in this case e.g. put a watch on '/home/pi/tfg/django/tornejos/project/application'.
Performing system checks...

Unhandled exception in thread started by <function check_errors.<locals>.wrapper at 0xb5a63bb8>
Traceback (most recent call last):
  File "/home/pi/.local/lib/python3.5/site-packages/django/utils/autoreload.py", line 225, in wrapper
    fn(*args, **kwargs)
  File "/home/pi/.local/lib/python3.5/site-packages/django/core/management/commands/runserver.py", line 117, in inner_run
    self.check(display_num_errors=True)
  File "/home/pi/.local/lib/python3.5/site-packages/django/core/management/base.py", line 379, in check
    include_deployment_checks=include_deployment_checks,
  File "/home/pi/.local/lib/python3.5/site-packages/django/core/management/base.py", line 366, in _run_checks
    return checks.run_checks(**kwargs)
  File "/home/pi/.local/lib/python3.5/site-packages/django/core/checks/registry.py", line 71, in run_checks
    new_errors = check(app_configs=app_configs)
  File "/home/pi/.local/lib/python3.5/site-packages/django/core/checks/urls.py", line 40, in check_url_namespaces_unique
    all_namespaces = _load_all_namespaces(resolver)
  File "/home/pi/.local/lib/python3.5/site-packages/django/core/checks/urls.py", line 57, in _load_all_namespaces
    url_patterns = getattr(resolver, 'url_patterns', [])
  File "/home/pi/.local/lib/python3.5/site-packages/django/utils/functional.py", line 37, in __get__
    res = instance.__dict__[self.name] = self.func(instance)
  File "/home/pi/.local/lib/python3.5/site-packages/django/urls/resolvers.py", line 533, in url_patterns
    patterns = getattr(self.urlconf_module, "urlpatterns", self.urlconf_module)
  File "/home/pi/.local/lib/python3.5/site-packages/django/utils/functional.py", line 37, in __get__
    res = instance.__dict__[self.name] = self.func(instance)
  File "/home/pi/.local/lib/python3.5/site-packages/django/urls/resolvers.py", line 526, in urlconf_module
    return import_module(self.urlconf_name)
  File "/usr/lib/python3.5/importlib/__init__.py", line 126, in import_module
    return _bootstrap._gcd_import(name[level:], package, level)
  File "<frozen importlib._bootstrap>", line 986, in _gcd_import
  File "<frozen importlib._bootstrap>", line 969, in _find_and_load
  File "<frozen importlib._bootstrap>", line 958, in _find_and_load_unlocked
  File "<frozen importlib._bootstrap>", line 673, in _load_unlocked
  File "<frozen importlib._bootstrap_external>", line 673, in exec_module
  File "<frozen importlib._bootstrap>", line 222, in _call_with_frames_removed
  File "/home/pi/tfg/django/tornejos/project/urls.py", line 20, in <module>
    from project.application.views import test, create_tournament, display_tournament, list_tournaments
  File "/home/pi/tfg/django/tornejos/project/application/views.py", line 6, in <module>
    from multiprocessing.connections import Client
ImportError: No module named 'multiprocessing.connections'
[2018-12-20 16:49:17,680 pyinotify ERROR] The pathname '/home/pi/tfg/django/tornejos/project/application/views.py' of this watch <Watch wd=382 path=/home/pi/tfg/django/tornejos/project/application/views.py mask=4038 proc_fun=None auto_add=False exclude_filter=<function WatchManager.<lambda> at 0xb66106a8> dir=False > has probably changed and couldn't be updated, so it cannot be trusted anymore. To fix this error move directories/files only between watched parents directories, in this case e.g. put a watch on '/home/pi/tfg/django/tornejos/project/application'.
Performing system checks...

Unhandled exception in thread started by <function check_errors.<locals>.wrapper at 0xb5a96bb8>
Traceback (most recent call last):
  File "/home/pi/.local/lib/python3.5/site-packages/django/utils/autoreload.py", line 225, in wrapper
    fn(*args, **kwargs)
  File "/home/pi/.local/lib/python3.5/site-packages/django/core/management/commands/runserver.py", line 117, in inner_run
    self.check(display_num_errors=True)
  File "/home/pi/.local/lib/python3.5/site-packages/django/core/management/base.py", line 379, in check
    include_deployment_checks=include_deployment_checks,
  File "/home/pi/.local/lib/python3.5/site-packages/django/core/management/base.py", line 366, in _run_checks
    return checks.run_checks(**kwargs)
  File "/home/pi/.local/lib/python3.5/site-packages/django/core/checks/registry.py", line 71, in run_checks
    new_errors = check(app_configs=app_configs)
  File "/home/pi/.local/lib/python3.5/site-packages/django/core/checks/urls.py", line 40, in check_url_namespaces_unique
    all_namespaces = _load_all_namespaces(resolver)
  File "/home/pi/.local/lib/python3.5/site-packages/django/core/checks/urls.py", line 57, in _load_all_namespaces
    url_patterns = getattr(resolver, 'url_patterns', [])
  File "/home/pi/.local/lib/python3.5/site-packages/django/utils/functional.py", line 37, in __get__
    res = instance.__dict__[self.name] = self.func(instance)
  File "/home/pi/.local/lib/python3.5/site-packages/django/urls/resolvers.py", line 533, in url_patterns
    patterns = getattr(self.urlconf_module, "urlpatterns", self.urlconf_module)
  File "/home/pi/.local/lib/python3.5/site-packages/django/utils/functional.py", line 37, in __get__
    res = instance.__dict__[self.name] = self.func(instance)
  File "/home/pi/.local/lib/python3.5/site-packages/django/urls/resolvers.py", line 526, in urlconf_module
    return import_module(self.urlconf_name)
  File "/usr/lib/python3.5/importlib/__init__.py", line 126, in import_module
    return _bootstrap._gcd_import(name[level:], package, level)
  File "<frozen importlib._bootstrap>", line 986, in _gcd_import
  File "<frozen importlib._bootstrap>", line 969, in _find_and_load
  File "<frozen importlib._bootstrap>", line 958, in _find_and_load_unlocked
  File "<frozen importlib._bootstrap>", line 673, in _load_unlocked
  File "<frozen importlib._bootstrap_external>", line 673, in exec_module
  File "<frozen importlib._bootstrap>", line 222, in _call_with_frames_removed
  File "/home/pi/tfg/django/tornejos/project/urls.py", line 20, in <module>
    from project.application.views import test, create_tournament, display_tournament, list_tournaments
  File "/home/pi/tfg/django/tornejos/project/application/views.py", line 6, in <module>
    from multiprocessing.connections import Client
ImportError: No module named 'multiprocessing.connections'
[2018-12-20 16:54:33,154 pyinotify ERROR] The pathname '/home/pi/tfg/django/tornejos/project/application/views.py' of this watch <Watch wd=1013 path=/home/pi/tfg/django/tornejos/project/application/views.py mask=4038 proc_fun=None auto_add=False exclude_filter=<function WatchManager.<lambda> at 0xb66436a8> dir=False > has probably changed and couldn't be updated, so it cannot be trusted anymore. To fix this error move directories/files only between watched parents directories, in this case e.g. put a watch on '/home/pi/tfg/django/tornejos/project/application'.
Performing system checks...

Unhandled exception in thread started by <function check_errors.<locals>.wrapper at 0xb5a68bb8>
Traceback (most recent call last):
  File "/home/pi/.local/lib/python3.5/site-packages/django/utils/autoreload.py", line 225, in wrapper
    fn(*args, **kwargs)
  File "/home/pi/.local/lib/python3.5/site-packages/django/core/management/commands/runserver.py", line 117, in inner_run
    self.check(display_num_errors=True)
  File "/home/pi/.local/lib/python3.5/site-packages/django/core/management/base.py", line 379, in check
    include_deployment_checks=include_deployment_checks,
  File "/home/pi/.local/lib/python3.5/site-packages/django/core/management/base.py", line 366, in _run_checks
    return checks.run_checks(**kwargs)
  File "/home/pi/.local/lib/python3.5/site-packages/django/core/checks/registry.py", line 71, in run_checks
    new_errors = check(app_configs=app_configs)
  File "/home/pi/.local/lib/python3.5/site-packages/django/core/checks/urls.py", line 40, in check_url_namespaces_unique
    all_namespaces = _load_all_namespaces(resolver)
  File "/home/pi/.local/lib/python3.5/site-packages/django/core/checks/urls.py", line 57, in _load_all_namespaces
    url_patterns = getattr(resolver, 'url_patterns', [])
  File "/home/pi/.local/lib/python3.5/site-packages/django/utils/functional.py", line 37, in __get__
    res = instance.__dict__[self.name] = self.func(instance)
  File "/home/pi/.local/lib/python3.5/site-packages/django/urls/resolvers.py", line 533, in url_patterns
    patterns = getattr(self.urlconf_module, "urlpatterns", self.urlconf_module)
  File "/home/pi/.local/lib/python3.5/site-packages/django/utils/functional.py", line 37, in __get__
    res = instance.__dict__[self.name] = self.func(instance)
  File "/home/pi/.local/lib/python3.5/site-packages/django/urls/resolvers.py", line 526, in urlconf_module
    return import_module(self.urlconf_name)
  File "/usr/lib/python3.5/importlib/__init__.py", line 126, in import_module
    return _bootstrap._gcd_import(name[level:], package, level)
  File "<frozen importlib._bootstrap>", line 986, in _gcd_import
  File "<frozen importlib._bootstrap>", line 969, in _find_and_load
  File "<frozen importlib._bootstrap>", line 958, in _find_and_load_unlocked
  File "<frozen importlib._bootstrap>", line 673, in _load_unlocked
  File "<frozen importlib._bootstrap_external>", line 673, in exec_module
  File "<frozen importlib._bootstrap>", line 222, in _call_with_frames_removed
  File "/home/pi/tfg/django/tornejos/project/urls.py", line 20, in <module>
    from project.application.views import test, create_tournament, display_tournament, list_tournaments
  File "/home/pi/tfg/django/tornejos/project/application/views.py", line 6, in <module>
    from multiprocessing.connections import Client
ImportError: No module named 'multiprocessing.connections'
[2018-12-20 16:54:48,468 pyinotify ERROR] The pathname '/home/pi/tfg/django/tornejos/project/application/views.py' of this watch <Watch wd=1013 path=/home/pi/tfg/django/tornejos/project/application/views.py mask=4038 proc_fun=None auto_add=False exclude_filter=<function WatchManager.<lambda> at 0xb66156a8> dir=False > has probably changed and couldn't be updated, so it cannot be trusted anymore. To fix this error move directories/files only between watched parents directories, in this case e.g. put a watch on '/home/pi/tfg/django/tornejos/project/application'.
Performing system checks...

Unhandled exception in thread started by <function check_errors.<locals>.wrapper at 0xb5a61bb8>
Traceback (most recent call last):
  File "/home/pi/.local/lib/python3.5/site-packages/django/utils/autoreload.py", line 225, in wrapper
    fn(*args, **kwargs)
  File "/home/pi/.local/lib/python3.5/site-packages/django/core/management/commands/runserver.py", line 117, in inner_run
    self.check(display_num_errors=True)
  File "/home/pi/.local/lib/python3.5/site-packages/django/core/management/base.py", line 379, in check
    include_deployment_checks=include_deployment_checks,
  File "/home/pi/.local/lib/python3.5/site-packages/django/core/management/base.py", line 366, in _run_checks
    return checks.run_checks(**kwargs)
  File "/home/pi/.local/lib/python3.5/site-packages/django/core/checks/registry.py", line 71, in run_checks
    new_errors = check(app_configs=app_configs)
  File "/home/pi/.local/lib/python3.5/site-packages/django/core/checks/urls.py", line 40, in check_url_namespaces_unique
    all_namespaces = _load_all_namespaces(resolver)
  File "/home/pi/.local/lib/python3.5/site-packages/django/core/checks/urls.py", line 57, in _load_all_namespaces
    url_patterns = getattr(resolver, 'url_patterns', [])
  File "/home/pi/.local/lib/python3.5/site-packages/django/utils/functional.py", line 37, in __get__
    res = instance.__dict__[self.name] = self.func(instance)
  File "/home/pi/.local/lib/python3.5/site-packages/django/urls/resolvers.py", line 533, in url_patterns
    patterns = getattr(self.urlconf_module, "urlpatterns", self.urlconf_module)
  File "/home/pi/.local/lib/python3.5/site-packages/django/utils/functional.py", line 37, in __get__
    res = instance.__dict__[self.name] = self.func(instance)
  File "/home/pi/.local/lib/python3.5/site-packages/django/urls/resolvers.py", line 526, in urlconf_module
    return import_module(self.urlconf_name)
  File "/usr/lib/python3.5/importlib/__init__.py", line 126, in import_module
    return _bootstrap._gcd_import(name[level:], package, level)
  File "<frozen importlib._bootstrap>", line 986, in _gcd_import
  File "<frozen importlib._bootstrap>", line 969, in _find_and_load
  File "<frozen importlib._bootstrap>", line 958, in _find_and_load_unlocked
  File "<frozen importlib._bootstrap>", line 673, in _load_unlocked
  File "<frozen importlib._bootstrap_external>", line 673, in exec_module
  File "<frozen importlib._bootstrap>", line 222, in _call_with_frames_removed
  File "/home/pi/tfg/django/tornejos/project/urls.py", line 20, in <module>
    from project.application.views import test, create_tournament, display_tournament, list_tournaments
  File "/home/pi/tfg/django/tornejos/project/application/views.py", line 6, in <module>
    from multiprocessing.connections import Client
ImportError: No module named 'multiprocessing.connections'
[2018-12-20 16:55:34,567 pyinotify ERROR] The pathname '/home/pi/tfg/django/tornejos/project/application/views.py' of this watch <Watch wd=1013 path=/home/pi/tfg/django/tornejos/project/application/views.py mask=4038 proc_fun=None auto_add=False exclude_filter=<function WatchManager.<lambda> at 0xb660e6a8> dir=False > has probably changed and couldn't be updated, so it cannot be trusted anymore. To fix this error move directories/files only between watched parents directories, in this case e.g. put a watch on '/home/pi/tfg/django/tornejos/project/application'.
Performing system checks...

[20/Dec/2018 16:58:47] "GET / HTTP/1.1" 200 1838
[20/Dec/2018 16:58:47] "GET /static/css/index.css HTTP/1.1" 200 1223
Not Found: /favicon.ico
[20/Dec/2018 16:58:48] "GET /favicon.ico HTTP/1.1" 404 2718
Internal Server Error: /list
Traceback (most recent call last):
  File "/home/pi/.local/lib/python3.5/site-packages/django/core/handlers/exception.py", line 34, in inner
    response = get_response(request)
  File "/home/pi/.local/lib/python3.5/site-packages/django/core/handlers/base.py", line 126, in _get_response
    response = self.process_exception_by_middleware(e, request)
  File "/home/pi/.local/lib/python3.5/site-packages/django/core/handlers/base.py", line 124, in _get_response
    response = wrapped_callback(request, *callback_args, **callback_kwargs)
  File "/home/pi/tfg/django/tornejos/project/application/views.py", line 106, in list_tournaments
    context = __send_req_to_api(req_data)
  File "/home/pi/tfg/django/tornejos/project/application/views.py", line 51, in __send_req_to_api
    client = Client(address)
  File "/usr/lib/python3.5/multiprocessing/connection.py", line 487, in Client
    c = SocketClient(address)
  File "/usr/lib/python3.5/multiprocessing/connection.py", line 614, in SocketClient
    s.connect(address)
TypeError: an integer is required (got type str)
[20/Dec/2018 16:58:52] "GET /list HTTP/1.1" 500 77720
[2018-12-20 16:59:33,061 pyinotify ERROR] The pathname '/home/pi/tfg/django/tornejos/project/application/views.py' of this watch <Watch wd=1103 path=/home/pi/tfg/django/tornejos/project/application/views.py mask=4038 proc_fun=None auto_add=False exclude_filter=<function WatchManager.<lambda> at 0xb65d36a8> dir=False > has probably changed and couldn't be updated, so it cannot be trusted anymore. To fix this error move directories/files only between watched parents directories, in this case e.g. put a watch on '/home/pi/tfg/django/tornejos/project/application'.
Performing system checks...

System check identified no issues (0 silenced).
December 20, 2018 - 16:55:51
Django version 2.1.3, using settings 'project.settings'
Starting development server at http://127.0.0.1:8000/
Quit the server with CONTROL-C.
Trying port 6000
Internal Server Error: /list
Traceback (most recent call last):
  File "/home/pi/.local/lib/python3.5/site-packages/django/core/handlers/exception.py", line 34, in inner
    response = get_response(request)
  File "/home/pi/.local/lib/python3.5/site-packages/django/core/handlers/base.py", line 126, in _get_response
    response = self.process_exception_by_middleware(e, request)
  File "/home/pi/.local/lib/python3.5/site-packages/django/core/handlers/base.py", line 124, in _get_response
    response = wrapped_callback(request, *callback_args, **callback_kwargs)
  File "/home/pi/tfg/django/tornejos/project/application/views.py", line 106, in list_tournaments
    context = __send_req_to_api(req_data)
  File "/home/pi/tfg/django/tornejos/project/application/views.py", line 47, in __send_req_to_api
    print("Trying port " + port)
TypeError: Can't convert 'int' object to str implicitly
[20/Dec/2018 17:00:08] "GET /list HTTP/1.1" 500 70103
[2018-12-20 17:00:42,348 pyinotify ERROR] The pathname '/home/pi/tfg/django/tornejos/project/application/views.py' of this watch <Watch wd=1085 path=/home/pi/tfg/django/tornejos/project/application/views.py mask=4038 proc_fun=None auto_add=False exclude_filter=<function WatchManager.<lambda> at 0xb665d6a8> dir=False > has probably changed and couldn't be updated, so it cannot be trusted anymore. To fix this error move directories/files only between watched parents directories, in this case e.g. put a watch on '/home/pi/tfg/django/tornejos/project/application'.
Performing system checks...

System check identified no issues (0 silenced).
December 20, 2018 - 16:59:50
Django version 2.1.3, using settings 'project.settings'
Starting development server at http://127.0.0.1:8000/
Quit the server with CONTROL-C.
Internal Server Error: /list
Traceback (most recent call last):
  File "/home/pi/.local/lib/python3.5/site-packages/django/core/handlers/exception.py", line 34, in inner
    response = get_response(request)
  File "/home/pi/.local/lib/python3.5/site-packages/django/core/handlers/base.py", line 126, in _get_response
    response = self.process_exception_by_middleware(e, request)
  File "/home/pi/.local/lib/python3.5/site-packages/django/core/handlers/base.py", line 124, in _get_response
    response = wrapped_callback(request, *callback_args, **callback_kwargs)
  File "/home/pi/tfg/django/tornejos/project/application/views.py", line 106, in list_tournaments
    context = __send_req_to_api(req_data)
  File "/home/pi/tfg/django/tornejos/project/application/views.py", line 51, in __send_req_to_api
    client = Client(address)
  File "/usr/lib/python3.5/multiprocessing/connection.py", line 487, in Client
    c = SocketClient(address)
  File "/usr/lib/python3.5/multiprocessing/connection.py", line 614, in SocketClient
    s.connect(address)
ConnectionRefusedError: [Errno 111] Connection refused
[20/Dec/2018 17:01:08] "GET /list HTTP/1.1" 500 77872
[2018-12-20 17:02:25,627 pyinotify ERROR] The pathname '/home/pi/tfg/django/tornejos/project/application/views.py' of this watch <Watch wd=1032 path=/home/pi/tfg/django/tornejos/project/application/views.py mask=4038 proc_fun=None auto_add=False exclude_filter=<function WatchManager.<lambda> at 0xb65f46a8> dir=False > has probably changed and couldn't be updated, so it cannot be trusted anymore. To fix this error move directories/files only between watched parents directories, in this case e.g. put a watch on '/home/pi/tfg/django/tornejos/project/application'.
Performing system checks...

System check identified no issues (0 silenced).
December 20, 2018 - 17:00:59
Django version 2.1.3, using settings 'project.settings'
Starting development server at http://127.0.0.1:8000/
Quit the server with CONTROL-C.
Trying port 6000
[20/Dec/2018 17:07:23] "GET /list HTTP/1.1" 200 6184
[20/Dec/2018 17:07:23] "GET /static/css/list.css HTTP/1.1" 200 1289
[20/Dec/2018 17:07:23] "GET /static/js/list.js HTTP/1.1" 200 619
[20/Dec/2018 17:07:23] "GET /static/css/general.css HTTP/1.1" 200 1637
Not Found: /t/
[20/Dec/2018 17:07:45] "GET /t/ HTTP/1.1" 404 2691
Internal Server Error: /list
Traceback (most recent call last):
  File "/home/pi/.local/lib/python3.5/site-packages/django/core/handlers/exception.py", line 34, in inner
    response = get_response(request)
  File "/home/pi/.local/lib/python3.5/site-packages/django/core/handlers/base.py", line 126, in _get_response
    response = self.process_exception_by_middleware(e, request)
  File "/home/pi/.local/lib/python3.5/site-packages/django/core/handlers/base.py", line 124, in _get_response
    response = wrapped_callback(request, *callback_args, **callback_kwargs)
  File "/home/pi/tfg/django/tornejos/project/application/views.py", line 117, in list_tournaments
    return render(request, "pages/list.html", context)
  File "/home/pi/.local/lib/python3.5/site-packages/django/shortcuts.py", line 36, in render
    content = loader.render_to_string(template_name, context, request, using=using)
  File "/home/pi/.local/lib/python3.5/site-packages/django/template/loader.py", line 61, in render_to_string
    template = get_template(template_name, using=using)
  File "/home/pi/.local/lib/python3.5/site-packages/django/template/loader.py", line 15, in get_template
    return engine.get_template(template_name)
  File "/home/pi/.local/lib/python3.5/site-packages/django/template/backends/django.py", line 34, in get_template
    return Template(self.engine.get_template(template_name), self)
  File "/home/pi/.local/lib/python3.5/site-packages/django/template/engine.py", line 144, in get_template
    template, origin = self.find_template(template_name)
  File "/home/pi/.local/lib/python3.5/site-packages/django/template/engine.py", line 126, in find_template
    template = loader.get_template(name, skip=skip)
  File "/home/pi/.local/lib/python3.5/site-packages/django/template/loaders/base.py", line 30, in get_template
    contents, origin, origin.template_name, self.engine,
  File "/home/pi/.local/lib/python3.5/site-packages/django/template/base.py", line 156, in __init__
    self.nodelist = self.compile_nodelist()
  File "/home/pi/.local/lib/python3.5/site-packages/django/template/base.py", line 194, in compile_nodelist
    return parser.parse()
  File "/home/pi/.local/lib/python3.5/site-packages/django/template/base.py", line 478, in parse
    raise self.error(token, e)
  File "/home/pi/.local/lib/python3.5/site-packages/django/template/base.py", line 476, in parse
    compiled_result = compile_func(self, token)
  File "/home/pi/.local/lib/python3.5/site-packages/django/template/loader_tags.py", line 266, in do_extends
    nodelist = parser.parse()
  File "/home/pi/.local/lib/python3.5/site-packages/django/template/base.py", line 478, in parse
    raise self.error(token, e)
  File "/home/pi/.local/lib/python3.5/site-packages/django/template/base.py", line 476, in parse
    compiled_result = compile_func(self, token)
  File "/home/pi/.local/lib/python3.5/site-packages/django/template/loader_tags.py", line 209, in do_block
    nodelist = parser.parse(('endblock',))
  File "/home/pi/.local/lib/python3.5/site-packages/django/template/base.py", line 478, in parse
    raise self.error(token, e)
  File "/home/pi/.local/lib/python3.5/site-packages/django/template/base.py", line 476, in parse
    compiled_result = compile_func(self, token)
  File "/home/pi/.local/lib/python3.5/site-packages/django/template/defaulttags.py", line 971, in do_if
    raise TemplateSyntaxError('Malformed template tag at line {0}: "{1}"'.format(token.lineno, token.contents))
django.template.exceptions.TemplateSyntaxError: Malformed template tag at line 26: "else if data"
[20/Dec/2018 17:13:59] "GET /list HTTP/1.1" 500 156674
[20/Dec/2018 17:14:28] "GET /list HTTP/1.1" 200 1077
[20/Dec/2018 17:14:32] "GET /list HTTP/1.1" 200 1077
[20/Dec/2018 17:14:32] "GET /static/css/list.css HTTP/1.1" 200 1289
[20/Dec/2018 17:14:32] "GET /static/js/list.js HTTP/1.1" 200 619
[20/Dec/2018 17:14:33] "GET /static/css/general.css HTTP/1.1" 200 1637
Not Found: /favicon.ico
[20/Dec/2018 17:14:33] "GET /favicon.ico HTTP/1.1" 404 2718
[20/Dec/2018 17:14:36] "GET /create HTTP/1.1" 200 1749
[20/Dec/2018 17:14:36] "GET /static/js/create.js HTTP/1.1" 200 1422
[20/Dec/2018 17:14:37] "GET /list HTTP/1.1" 200 1077
[20/Dec/2018 17:23:02] "GET /list HTTP/1.1" 200 1133
[20/Dec/2018 17:23:11] "GET /create HTTP/1.1" 200 1749
[20/Dec/2018 17:23:12] "GET /list HTTP/1.1" 200 1133
[20/Dec/2018 17:23:16] "GET /list HTTP/1.1" 200 1133
[20/Dec/2018 17:23:16] "GET /static/css/list.css HTTP/1.1" 200 1289
[20/Dec/2018 17:23:16] "GET /static/js/list.js HTTP/1.1" 200 619
[20/Dec/2018 17:23:16] "GET /static/css/general.css HTTP/1.1" 200 1637
Not Found: /favicon.ico
[20/Dec/2018 17:23:16] "GET /favicon.ico HTTP/1.1" 404 2718
[20/Dec/2018 17:35:13] "GET /create HTTP/1.1" 200 1876
[20/Dec/2018 17:35:22] "POST /create HTTP/1.1" 200 1876
Not Found: /favicon.ico
[20/Dec/2018 17:38:04] "GET /favicon.ico HTTP/1.1" 404 2718
[20/Dec/2018 17:38:04] "GET /test HTTP/1.1" 200 1190
Not Found: /favicon.ico
[20/Dec/2018 17:38:04] "GET /favicon.ico HTTP/1.1" 404 2718
[2018-12-20 17:40:41,886 pyinotify ERROR] The pathname '/home/pi/tfg/django/tornejos/project/application/views.py' of this watch <Watch wd=1103 path=/home/pi/tfg/django/tornejos/project/application/views.py mask=4038 proc_fun=None auto_add=False exclude_filter=<function WatchManager.<lambda> at 0xb661f6a8> dir=False > has probably changed and couldn't be updated, so it cannot be trusted anymore. To fix this error move directories/files only between watched parents directories, in this case e.g. put a watch on '/home/pi/tfg/django/tornejos/project/application'.
Performing system checks...

System check identified no issues (0 silenced).
December 20, 2018 - 17:02:42
Django version 2.1.3, using settings 'project.settings'
Starting development server at http://127.0.0.1:8000/
Quit the server with CONTROL-C.
Trying port 6000
{'data': 'No nodes available', 'code': -1}
Trying port 6000
{'data': 'No nodes available', 'code': -1}
Trying port 6000
{'data': 'No nodes available', 'code': -1}
Trying port 6000
{'data': 'No nodes available', 'code': -1}
Trying port 6000
{'data': 'No nodes available', 'code': -1}
Trying port 6000
{'data': 'No nodes available', 'code': -1}
Trying port 6000
{'data': 'No nodes available', 'code': -1}
Trying port 6000
{'data': 'No nodes available', 'code': -1}
[20/Dec/2018 19:06:01] "GET /create HTTP/1.1" 200 940
[2018-12-20 19:06:57,756 pyinotify ERROR] The pathname '/home/pi/tfg/django/tornejos/project/application/views.py' of this watch <Watch wd=1051 path=/home/pi/tfg/django/tornejos/project/application/views.py mask=4038 proc_fun=None auto_add=False exclude_filter=<function WatchManager.<lambda> at 0xb664a6a8> dir=False > has probably changed and couldn't be updated, so it cannot be trusted anymore. To fix this error move directories/files only between watched parents directories, in this case e.g. put a watch on '/home/pi/tfg/django/tornejos/project/application'.
Performing system checks...

System check identified no issues (0 silenced).
December 20, 2018 - 17:40:59
Django version 2.1.3, using settings 'project.settings'
Starting development server at http://127.0.0.1:8000/
Quit the server with CONTROL-C.
